Workbook

Sheet ECT_EfficiencyCostMaxAnnualUF
A1: Source
A2: Variable | H2: a | I2: b | J2: c | K2: d | L2: e | M2: f | N2: g | O2: h | P2: j | Q2: k | R2: m | S2: n | Y2: aa | Z2: bb | AA2: cc | AB2: dd | AC2: ee
A3: Equation | H3: given | I3: given | J3: given | K3: given | L3: given | M3: given | N3: given | O3: given | P3: given *1000 | Q3: given *1000 | R3: given | Y3: = 1/a
A4: EnergyConvTech | B4: ModelGeography | C4: CapacityUnit | D4: InputEC | E4: OutputDEC | F4: AnnualOutputPerUnitCapacity | G4: SubGeography1 | H4: ConvEff | I4: Lifetime | J4: SelfCons | K4: MaxRampUpRate | L4: MaxRampDownRate | M4: MaxAnnualUF | N4: MW 2023 | O4: MW 2024 | P4: Legacy Fixed Cost (annualized per MW) | Q4: New Fixed Cost (anualized per MW) | R4: VarCost (million Rs / tonne!) | S4: VarCost Rs/MWh | U4: PhysicalUnit | V4: EnergyUnit | W4: DomEnergyDensity | X4: DomEmissionFactor | Y4: Fuel Use per MWh | Z4: tCO2/MT | AA4: MWh/MT | AB4: tCO2/MWh
A5: Unit | H5: % | I5: years | J5: MWh
A6: EG_COAL | B6: INDIA | C6: GW | D6: THERMAL_COAL | E6: ELECTRICITY | F6: 8760 | G6: NR | H6: 0.3809682 | I6: 40 | J6: 0.066 | K6: 0.3 | L6: 0.3 | M6: 0.85 | P6: =11751.5992748699*1000 -> 11751599 | Q6: 13721031 | R6: 133.52302 | S6: =R6/Y6 -> 50.868024 | U6: MT | V6: PJ | W6: 17.207188 | X6: 1871.8737 | Y6: =1/H6 -> 2.624891 | Z6: =Carriers!H3*1000 -> 1871873.7 | AA6: =Carriers!G3*277800 -> 4780156.7 | AB6: =Z6/AA6 -> 0.39159253 | AC6: =AB6 -> 0.39159253
A7: EG_COAL | B7: INDIA | C7: GW | D7: THERMAL_COAL | E7: ELECTRICITY | F7: 8760 | G7: NER | H7: 0.3809682 | I7: 40 | J7: 0.066 | K7: 0.3 | L7: 0.3 | M7: 0.85 | P7: =26148.8463751508*1000 -> 26148846 | Q7: 13721031 | R7: 133.52302 | S7: =R7/Y7 -> 50.868024 | U7: MT | V7: PJ | W7: 17.207188 | X7: 1871.8737 | Y7: =1/H7 -> 2.624891 | Z7: =Carriers!H11*1000 -> 3080754.9 | AA7: =Carriers!G4*277800 -> 10467837 | AB7: =Z7/AA7 -> 0.29430672 | AC7: =AB7 -> 0.29430672
A8: EG_COAL | B8: INDIA | C8: GW | D8: THERMAL_COAL | E8: ELECTRICITY | F8: 8760 | G8: ER | H8: 0.3809682 | I8: 40 | J8: 0.066 | K8: 0.3 | L8: 0.3 | M8: 0.85 | P8: =6514.90571684157*1000 -> 6514905.7 | Q8: 13721031 | R8: 133.52302 | S8: =R8/Y8 -> 50.868024 | W8: 17.207188 | X8: 1871.8737 | Y8: =1/H8 -> 2.624891 | Z8: =Carriers!H12*1000 -> 2464603.9 | AA8: =Carriers!G5*277800 -> 6333840 | AB8: =Z8/AA8 -> 0.38911686 | AC8: =AB8 -> 0.38911686
A9: EG_COAL | B9: INDIA | C9: GW | D9: THERMAL_COAL | E9: ELECTRICITY | F9: 8760 | G9: WR | H9: 0.3809682 | I9: 40 | J9: 0.066 | K9: 0.3 | L9: 0.3 | M9: 0.85 | P9: =5794.65159561365*1000 -> 5794651.6 | Q9: 13721031 | R9: 133.52302 | S9: =R9/Y9 -> 50.868024 | W9: 17.207188 | X9: 1871.8737 | Y9: =1/H9 -> 2.624891 | Z9: =Carriers!H13*1000 -> 3196749 | AA9: =Carriers!G6*277800 -> 4322568 | AB9: =Z9/AA9 -> 0.73954857 | AC9: =AB9 -> 0.73954857
A10: EG_COAL | B10: INDIA | C10: GW | D10: THERMAL_COAL | E10: ELECTRICITY | F10: 8760 | G10: SR | H10: 0.3809682 | I10: 40 | J10: 0.066 | K10: 0.3 | L10: 0.3 | M10: 0.85 | P10: =5822.44460147077*1000 -> 5822444.6 | Q10: 13721031 | R10: 133.52302 | S10: =R10/Y10 -> 50.868024 | W10: 17.207188 | X10: 1871.8737 | Y10: =1/H10 -> 2.624891 | Z10: =Carriers!H14*1000 -> 3080754.9 | AA10: =Carriers!G7*277800 -> 11979858 | AB10: =Z10/AA10 -> 0.25716121 | AC10: =AB10 -> 0.25716121
A11: EG_CCGT | B11: INDIA | C11: GW | D11: NATGAS | E11: ELECTRICITY | F11: 8760 | G11: ALL | H11: 0.40444272 | I11: 25 | J11: 0.02 | K11: 0.9 | L11: 0.9 | M11: 0.85 | P11: =8512.22780274884*1000 -> 8512227.8 | Q11: 8512227.8 | R11: 0 | S11: 0 | Y11: =1/H11 -> 2.472538 | Z11: =Carriers!H4*1000 -> 3025024.5 | AA11: =Carriers!G4*277800/0.829 -> 12627066 | AB11: =Z11/AA11 -> 0.23956671 | AC11: =AB11 -> 0.23956671
A12: EG_OCGT | B12: INDIA | C12: GW | D12: NATGAS | E12: ELECTRICITY | F12: 8760 | G12: ALL | H12: 0.28070163 | I12: 25 | J12: 0.01 | K12: 1 | L12: 1 | M12: 0.85 | P12: =6679.75064927145*1000 -> 6679750.6 | Q12: 6679750.6 | R12: 0 | S12: 0 | Y12: =1/H12 -> 3.5625016 | Z12: =Carriers!H4*1000 -> 3025024.5 | AA12: =Carriers!G4*277800/0.829 -> 12627066 | AB12: =Z12/AA12 -> 0.23956671 | AC12: =AB12 -> 0.23956671
A13: EG_PHWR | B13: INDIA | C13: GW | D13: ATOMIC | E13: ELECTRICITY | F13: 8760 | G13: ALL | H13: 1 | I13: 40 | J13: 0.1078 | K13: 0.01 | L13: 0.01 | M13: 0.70916667 | P13: =20833.2103478327*1000 -> 20833210 | Q13: 20833210 | R13: 0 | S13: 0 | Y13: =1/H13 -> 1
A14: EG_SMR | B14: INDIA | C14: GW | D14: ATOMIC | E14: ELECTRICITY | F14: 8760 | G14: ALL | H14: 1 | I14: 30 | J14: 0.05 | K14: 0.01 | L14: 0.01 | M14: 0.70916667 | Q14: 35289429 | R14: 0 | S14: 0 | Y14: =1/H14 -> 1
A15: EG_LH | B15: INDIA | C15: GW | D15: HYDEL | E15: ELECTRICITY | F15: 8760 | G15: ALL | H15: 1 | I15: 40 | J15: 0.006 | K15: 1 | L15: 1 | M15: 1 | P15: =19631.8145207228*1000 -> 19631815 | Q15: 19631815 | R15: 0 | S15: 0 | Y15: =1/H15 -> 1
A16: EG_SH | B16: INDIA | C16: GW | D16: HYDEL | E16: ELECTRICITY | F16: 8760 | G16: ALL | H16: 1 | I16: 35 | J16: 0.01 | K16: 1 | L16: 1 | M16: 1 | P16: =11825.3487554956*1000 -> 11825349 | Q16: 11825349 | R16: 0 | S16: 0 | Y16: =1/H16 -> 1
A17: EG_BIOMASS | B17: INDIA | C17: GW | D17: BIOMASS_WASTE | E17: ELECTRICITY | F17: 8760 | G17: ALL | H17: 0.2388459 | I17: 20 | J17: 0.1 | K17: 0.06 | L17: 0.06 | M17: 1 | P17: =7713.45723965334*1000 -> 7713457.2 | Q17: 7713457.2 | R17: 0 | S17: 0 | Y17: =1/H17 -> 4.1868 | Z17: =Carriers!H6*1000 -> 1656436.7 | AA17: =Carriers!G8*277800 -> 3791683.3 | AB17: =Z17/AA17 -> 0.43686051 | AC17: =AB17 -> 0.43686051
A18: EG_SOLARGM | B18: INDIA | C18: GW | D18: SUNLIGHT | E18: ELECTRICITY | F18: 8760 | G18: ALL | H18: 1 | I18: 25 | J18: 0.01 | K18: 1 | L18: 1 | M18: 1 | P18: =5630.98419436319*1000 -> 5630984.2 | Q18: 5439705.9 | R18: 0 | S18: 0 | Y18: =1/H18 -> 1
A19: EG_SOLARRF | B19: INDIA | C19: GW | D19: SUNLIGHT | E19: ELECTRICITY | F19: 8760 | G19: ALL | H19: 1 | I19: 25 | J19: 0.006 | K19: 1 | L19: 1 | M19: 1 | P19: =5542.18769541597*1000 -> 5542187.7 | Q19: 5362133.8 | R19: 0 | S19: 0 | Y19: =1/H19 -> 1
A20: EG_WINDON | B20: INDIA | C20: GW | D20: WIND | E20: ELECTRICITY | F20: 8760 | G20: ALL | H20: 1 | I20: 25 | J20: 0.005 | K20: 1 | L20: 1 | M20: 1 | P20: =10659.4302732183*1000 -> 10659430 | Q20: 10586964 | R20: 0 | S20: 0 | Y20: =1/H20 -> 1
A21: EG_WINDOFF | B21: INDIA | C21: GW | D21: WIND | E21: ELECTRICITY | F21: 8760 | G21: ALL | H21: 1 | I21: 25 | J21: 0.005 | K21: 1 | L21: 1 | M21: 1 | Q21: 34540362 | R21: 0 | S21: 0 | Y21: =1/H21 -> 1
B24: EnergyConvTech | D24: InstYear | E24: EmissionType | F24: DomEmissionFactor | G24: ImpEmissionFactor
B25: EG_COAL | D25: 2023 | E25: GHG | F25: 1942.0976 | G25: 2057.8978
F26: =F25/Y10/1000 -> 0.73987744

Sheet Carriers
A1: Year | B1: EnergyCarrier | C1: BalancingArea | D1: BalancingTime | E1: PhysicalUnit | F1: EnergyUnit | G1: DomEnergyDensity | H1: DomEmissionFactor | I1: EmissionType | J1: ImpEnergyDensity | K1: ImpEmissionFactor | L1: Remarks
A2: 2024 | B2: COKING_COAL | C2: SUBGEOGRAPHY1 | D2: YEAR | E2: MT | F2: PJ | G2: 20.555669 | H2: 2257.6805 | I2: GHG | J2: 24.179251 | K2: 2760.9
A3: 2024 | B3: THERMAL_COAL | C3: SUBGEOGRAPHY1 | D3: YEAR | E3: MT | F3: PJ | G3: 17.207188 | H3: 1871.8737 | I3: GHG | J3: 22.60872 | K3: 1982.186
A4: 2024 | B4: NATGAS | C4: MODELGEOGRAPHY | D4: YEAR | E4: BCM | F4: PJ | G4: 37.6812 | H4: 3025.0245 | I4: GHG | J4: 37.6812 | K4: 2048.5162
A5: 2024 | B5: BIOGAS | C5: MODELGEOGRAPHY | D5: YEAR | E5: BCM | F5: PJ | G5: 22.8 | H5: 2001.5626 | I5: GHG | J5: 22.8 | K5: 1246.1226 | L5: Density of biogas is assumed to be same as natural gas
A6: 2024 | B6: BIOMASS | C6: MODELGEOGRAPHY | D6: YEAR | E6: MT | F6: PJ | G6: 15.56 | H6: 1656.4367 | I6: GHG | J6: 15.56 | K6: 1656.4367
A7: 2024 | B7: CRUDE | C7: MODELGEOGRAPHY | D7: YEAR | E7: MT | F7: PJ | G7: 43.12404 | H7: 54.232192 | I7: GHG | J7: 43.12404 | K7: 0 | L7: As only fugitive emissions are applicable to crude, emissions for imported crude is assumed as 0 for the ModelGeography
A8: 2024 | B8: BIOMASS_WASTE | C8: MODELGEOGRAPHY | D8: YEAR | E8: MT | F8: PJ | G8: 13.648968 | H8: 1292.3067 | I8: GHG | J8: 13.648968 | K8: 1292.3067
A9: 2024 | B9: PETCOKE | H9: 3176.6475 | I9: GHG | K9: 3176.6475
A10: 2024 | B10: PP_OTHER | H10: 3141.2838 | I10: GHG | K10: 3141.2838
A11: 2024 | B11: MS | H11: 3080.7549 | I11: GHG | K11: 3080.7549
A12: 2025 | B12: MS | H12: 2464.6039 | I12: GHG | K12: 2464.6039 | L12: 20% reduction due to ethanol blending, assuming E20 is fully deployed beginning FY25
A13: 2024 | B13: HSD | H13: 3196.749 | I13: GHG | K13: 3196.749
A14: 2024 | B14: ATF | H14: 3080.7549 | I14: GHG | K14: 3080.7549
A15: 2035 | B15: ATF | H15: 3058.2628 | I15: GHG | K15: 3058.2628
A16: 2036 | B16: ATF | H16: 3035.935 | I16: GHG | K16: 3035.935
A17: 2037 | B17: ATF | H17: 3013.7701 | I17: GHG | K17: 3013.7701
A18: 2038 | B18: ATF | H18: 2991.7671 | I18: GHG | K18: 2991.7671
A19: 2039 | B19: ATF | H19: 2969.9247 | I19: GHG | K19: 2969.9247
A20: 2040 | B20: ATF | H20: 2948.2418 | I20: GHG | K20: 2948.2418
A21: 2041 | B21: ATF | H21: 2926.7172 | I21: GHG | K21: 2926.7172 | L21: 5% reduction by FY41 from FY24-34 levels
A22: 2024 | B22: LPG | H22: 2987.2078 | I22: GHG | K22: 2987.2078

Sheet Transmission
A1: EnergyCarrier | B1: ModelGeographySrc | C1: SubGeography1Src | D1: ModelGeographyDest | E1: SubGeography1Dest | F1: Year | G1: TransitCost | H1: TransitLoss | I1: MaxTransit
A2: ELECTRICITY | B2: INDIA | C2: NR | D2: INDIA | E2: NR | F2: 2024 | G2: 2.6248298 | H2: 0.14930632 | I2: -1
A3: ELECTRICITY | B3: INDIA | C3: WR | D3: INDIA | E3: WR | F3: 2024 | G3: 1.8783628 | H3: 0.12258156 | I3: -1
A4: ELECTRICITY | B4: INDIA | C4: SR | D4: INDIA | E4: SR | F4: 2024 | G4: 2.8361183 | H4: 0.10645771 | I4: -1
A5: ELECTRICITY | B5: INDIA | C5: ER | D5: INDIA | E5: ER | F5: 2024 | G5: 1.8272949 | H5: 0.17367141 | I5: -1
A6: ELECTRICITY | B6: INDIA | C6: NER | D6: INDIA | E6: NER | F6: 2024 | G6: 4.6461251 | H6: 0.15154467 | I6: -1
A7: ELECTRICITY | B7: INDIA | C7: NR | D7: INDIA | E7: WR | F7: 2024 | G7: 0.50994571 | H7: 0.035 | I7: 36.72
A8: ELECTRICITY | B8: INDIA | C8: WR | D8: INDIA | E8: SR | F8: 2024 | G8: 0.50994571 | H8: 0.035 | I8: 22.32
A9: ELECTRICITY | B9: INDIA | C9: SR | D9: INDIA | E9: ER | F9: 2024 | G9: 0.50994571 | H9: 0.035 | I9: 5.83
A10: ELECTRICITY | B10: INDIA | C10: ER | D10: INDIA | E10: NER | F10: 2024 | G10: 0.50994571 | H10: 0.035 | I10: 2.95
A11: ELECTRICITY | B11: INDIA | C11: NER | D11: INDIA | E11: NR | F11: 2024 | G11: 0.50994571 | H11: 0.035 | I11: 3
A12: ELECTRICITY | B12: INDIA | C12: NR | D12: INDIA | E12: SR | F12: 2024 | G12: 0.50994571 | H12: 0.035 | I12: 0
A13: ELECTRICITY | B13: INDIA | C13: WR | D13: INDIA | E13: ER | F13: 2024 | G13: 0.50994571 | H13: 0.035 | I13: 21.19
... A26: ELECTRICITY | B26: INDIA | C26: NER | D26: INDIA | E26: ER | F26: 2024 | G26: 0.50994571 | H26: 0.035 | I26: 2.95

Sheet ECT_MaxAdd2024
A3: Year | B3: 2024 | C3: 2023 | D3: Total in 2024
A5: Row Labels | B5: Sum of MaxCapacity
A6: NR | B6: 5.7302851
A7: EG_BIOMASS | B7: 0.143 | C7: 3355.17 | D7: =B7*1000+C7 -> 3498.17
A8: EG_CCGT | B8: 0 | C8: 7330.5 | D8: =B8*1000+C8 -> 7330.5
A9: EG_COAL | B9: 0 | C9: 0
A10: EG_LH | B10: 0 | C10: 20500 | D10: =B10*1000+C10 -> 20500
A11: EG_OCGT | B11: 0 | C11: 0 | D11: =B11*1000+C11 -> 0
A12: EG_PHWR | B12: 0 | C12: 1603.5 | D12: =B12*1000+C12 -> 1603.5
A13: EG_SH | B13: 0.028 | C13: 1700 | D13: =B13*1000+C13 -> 1728
A14: EG_SMR | B14: 0 | C14: 0 | D14: =B14*1000+C14 -> 0
A15: EG_SOLARGM | B15: 4.791 | C15: 19996.72 | D15: =B15*1000+C15 -> 24787.72
A16: EG_SOLARRF | B16: 0.766 | C16: 2666.3 | D16: =B16*1000+C16 -> 3432.3
A17: EG_WINDOFF | B17: 0 | C17: 0 | D17: =B17*1000+C17 -> 0
A18: EG_WINDON | B18: 0.002 | C18: 5301.4 | D18: =B18*1000+C18 -> 5303.4
A19: GH_ELECTROLYSIS | B19: 0.0002850662 | C19: 0 | D19: =B19*1000+C19 -> 0.2850662
A20: NER | B20: 0.026021154
A21: EG_BIOMASS | B21: 0.001 | C21: 15.8 | D21: =B21*1000+C21 -> 16.8
A22: EG_CCGT | B22: 0 | C22: 2002.4 | D22: =B22*1000+C22 -> 2002.4
A23: EG_COAL | B23: 0 | C23: 0 | D23: =B23*1000+C23 -> 0
A24: EG_LH | B24: 0 | C24: 1850 | D24: =B24*1000+C24 -> 1850
A25: EG_OCGT | B25: 0 | C25: 0 | D25: =B25*1000+C25 -> 0
A26: EG_PHWR | B26: 0 | C26: 0 | D26: =B26*1000+C26 -> 0
A27: EG_SH | B27: 0.01 | C27: 300 | D27: =B27*1000+C27 -> 310
A28: EG_SMR | B28: 0 | C28: 0 | D28: =B28*1000+C28 -> 0
A29: EG_SOLARGM | B29: 0.007 | C29: 171.48 | D29: =B29*1000+C29 -> 178.48
A30: EG_SOLARRF | B30: 0.008 | C30: 67.6 | D30: =B30*1000+C30 -> 75.6
A31: EG_WINDOFF | B31: 0 | C31: 0 | D31: =B31*1000+C31 -> 0
A32: EG_WINDON | B32: 0 | C32: 0 | D32: =B32*1000+C32 -> 0
A33: GH_ELECTROLYSIS | B33: 2.1154e-05 | C33: 0 | D33: =B33*1000+C33 -> 0.021154
A34: ER | B34: 0.2071059
A35: EG_BIOMASS | B35: 0.023 | D35: =B35*1000+560.64 -> 583.64
A36: EG_CCGT | B36: 0 | D36: =B36*1000+770.8 -> 770.8
A37: EG_COAL | B37: 0 | D37: =B37*1000+C37 -> 0
A38: EG_LH | B38: 0 | C38: 4200 | D38: =B38*1000+C38 -> 4200
A39: EG_OCGT | B39: 0 | C39: 0 | D39: =B39*1000+C39 -> 0
A40: EG_PHWR | B40: 0 | C40: 0 | D40: =B40*1000+C40 -> 0
A41: EG_SH | B41: 0.006 | C41: 350 | D41: =B41*1000+C41 -> 356
A42: EG_SMR | B42: 0 | C42: 0 | D42: =B42*1000+C42 -> 0
A43: EG_SOLARGM | B43: 0.04 | C43: 847.72 | D43: =B43*1000+C43 -> 887.72
...
