Workbook
Name Escalation_rate: [1]!COAL_TransitCost_Esc[#All]

Sheet PeriodMap
A1: Period | B1: Year (FY) | C1: Constraint (s) | D1: Notes
A2: 1 | B2: 2023 | C2: Capacity forced , no retirements, no new-builds | D2: This period is inserted only so that all existing capacity can be built. Using demand from 2024, as PIER2.0 does not provide a demand for 2023
A3: 2 | B3: 2024 | C3: Pipeline capacity forced, no retirements, no new-builds | D3: Demand = PIER2.0 2024, Calibration year for constrained model operation and comparison between Rumi+PIER2.0 & Macro case build on PIER2.0
A4: 3 | B4: 2025 | D4: Demand = PIER2.0 2025, Calibration year for less constraned model operaration
A5: 4 | B5: 2029 | D5: Using demand from 2029, as selected year for period , which spans 2026 to 2031, using constraints from PIER2.0 "8_REF_Unconstr" scenario
A6: 5 | B6: 2034 | D6: Using demand from 2034, as selected year for period, which spans 2032 to 2036, using constraints from PIER2.0 "8_REF_Unconstr" scenario
A7: 6 | B7: 2039 | D7: Using demand from 2039, as selected year for period, which spans 2037 to 2041, using constraints from PIER2.0 "8_REF_Unconstr" scenario
A8: 7 | B8: 2045
A9: 8 | B9: 2055
A10: 9 | B10: 2065
A11: 10 | B11: 2071

Sheet assets_gen_p1
A1: Source::File | G1: PIER::EnergyConvTechnologies.csv | H1: PIER::EnergyConvTechnologies.csv | I1: PIER::EnergyConvTechnologies.csv | J1: PIER::EnergyConvTechnologies.csv | K1: PIER2.0_ECT::EfficiencyCostMaxAnnual.csv | L1: PIER2.0_ECT::EfficiencyCostMaxAnnual.csv | M1: PIER2.0_ECT::EfficiencyCostMaxAnnual.csv | N1: PIER2.0_ECT::EfficiencyCostMaxAnnual.csv | O1: PIER2.0_ECT::EfficiencyCostMaxAnnual.csv | P1: PIER2.0::ECT_Lifetime.csv | Q1: PIER2.0::ECT_OperationalInfo.csv | R1: PIER2.0::ECT_OperationalInfo.csv | S1: PIER2.0::ECT_OperationalInfo.csv | T1: PIER2.0::ECT_LegacyCapacity.csv | V1: PIER2.0::ECT_CapAddBounds.csv | W1: PIER2.0::ECT_CapAddBounds.csv | X1: PIER2.0::PhysicalDerivedCarriers.csv | Y1: PIER2.0::PhysicalCarrierEmissions.csv or for coal, PIER2.0::ECT_EmissionDetails.csv | Z1: PIER2.0::ECT_EfficiencyCostMaxAnnualUF.xlsx | AA1: PIER2.0::ECT_EfficiencyCostMaxAnnualUF.xlsx
A2: PIER2.0 var name | B2: EnergyConvTech | C2: SubGeography1 | F2: ModelGeography | G2: CapacityUnit | H2: InputEC | I2: OutputDEC | J2: AnnualOutputPerUnitCapacity | K2: ConvEff | L2: MaxAnnualUF | M2: FixedCost | N2: FixedCost | O2: VarCost | P2: Lifetime | Q2: SelfCons | R2: MaxRampUpRate | S2: MaxRampDownRate | T2: LegacyCapacity | U2: RetCapacity | V2: MinCapacity | W2: MaxCapacity | X2: DomEnergyDensity | Y2: DomEmissionFactor
A3: Variable | K3: a | L3: b | M3: c | N3: d | O3: e | P3: f | Q3: g | R3: h | S3: i | T3: j | U3: k | V3: l | W3: m | X3: n | Y3: o | Z3: p | AA3: q | AC3: aa | AD3: bb | AE3: cc | AF3: dd | AG3: ee | AH3: ff | AI3: gg | AJ3: hh | AK3: ii | AL3: jj
A4: description | C4: model geography | G4: all units in macro are given in the selected value | H4: energy carrier | I4: energy carrier | J4: model granularity | K4: efficiency of conversion of energy input to output | L4: max utilization factor (over whole year) ** this must be considered alongside availability for technology provided in ECT_Max_CUF.csv to arrive at more granular availability profiles (see code) | M4: annuity on existiting capacity | N4: annuity on new capacity | O4: variable cost per Mt of input energy carrier | P4: lifetime of asset | Q4: % of energy input consumed by technology (not part of output) | T4: legacy/existing | U4: legacy capacity retired | V4: pipeline builds | W4: maximum additions | X4: given | Y4: given | Z4: given Fixed O&M (PIER or assumed), adjusted to 2024Rs from 2020Rs | AA4: given discount rate from PIER2.0 workbook, No adjustment made | AC4: self-consumption adjsuted fuel consumption of generating unit | AD4: self-consumption adjusted efficiency | AE4: doemstic only, need imported ! | AH4: This is without fixed O&M as expected by Macro | AI4: For existing infrastructure this is half operational lifetime, rounded to integer as Macro will fail if given decimal | AL4: legacy capacity
A5: Equation to Macro var | G5: given / 1000 | H5: given | M5: given/1000 | N5: given/1000 | P5: given | R5: given | S5: given | T5: = given*1000 | U5: = given*1000 | V5: = given*1000 | W5: = given*1000 | AA5: = given | AC5: = 1 / a / (1 -g) | AD5: = a - g | AE5: = ( n * conversion_if_not _MT) / (o * conversion_PJ_to_MWh) | AF5: = e / on/ conversion_PJ_to_MWh * aa | AG5: = p * 2020 to 2024 inflator | AH5: = d - ee | AI5: = round ( f / 2 , 0) | AJ5: = q / ( 1-(1+q)^(-gg)) | AK5: = ff / hh | AL5: = j - k
A6: Macro variable | C6: location | D6: type | E6: id | H6: fuel_commodity | M6: annualized_investment_cost | N6: annualized_investment_cost | P6: lifetime of asset | R6: ramp_up_fraction | S6: ramp_down_fraction | V6: min_capcity | W6: max_capacity | AA6: wacc | AC6: fuel_consumption | AD6: discharge_efficiency | AE6: emission_rate | AF6: variable_om_cost | AG6: fixed_om_cost | AH6: annualized_investment_cost | AI6: capital_recovery_period | AJ6: CRF | AK6: investment_cost | AL6: existing_capacity
A7: Unit | K7: % | L7: % | M7: million Rs2024/MW | N7: million Rs2024/MW | O7: million Rs / Mt | P7: years | Q7: % | R7: fraction of capacity | S7: fraction of capacity | T7: MW | U7: MW | V7: MW | W7: MW | X7: PJ/MT or PJ/BCM | Y7: tonnes CO2/MT (no BCM) | Z7: million 2020Rs/year | AA7: % | AC7: MWin per Mwout | AD7: % | AE7: tCO2/MWh input | AF7: millionRs/MWh-elec | AG7: million 2024Rs/year | AH7: million 2024Rs/year | AI7: years | AJ7: % total investment per capital recovery year | AK7: million 2024Rs | AL7: MW
B8: EG_COAL | C8: NR | D8: ThermalPower | E8: coal_legacy | F8: INDIA | G8: MW | H8: THERMAL_COAL | I8: ELECTRICITY | J8: 8760 | K8: 0.3809682 | L8: 0.85 | M8: =11751.5992748699/1000 -> 11.751599 | N8: =13721.03129/1000 -> 13.721031 | O8: 133.52302 | P8: 40 | Q8: 0.066 | R8: 0.3 | S8: 0.3 | T8: =Capacity!B5*1000 -> 67226.539 | U8: 0 | V8: 0 | W8: 0 | X8: =CarriersTech_characteristics!$G$2 -> 17.207188 | Y8: =CarriersTech_characteristics!$H$28*1000 -> 1942097.6 | Z8: 3 | AA8: 0.105 | AC8: =1/K8/(1-Q8) -> 2.8103758 | AE8: =Y8/(X8*Conversions!$D$2) -> 0.40631575 | AF8: =O8/X8/Conversions!$D$2*AC8 -> 7.850786e-05 | AG8: =Z8*Conversions!$D$4 -> 3.7167527 | AH8: =M8-AG8 -> 8.0348465 | AI8: =ROUND(P8/2,0) -> 20 | AJ8: =AA8/(1-(1+AA8)^-AI8) -> 0.12149327 | AK8: =AH8/AJ8 -> 66.13409 | AL8: =T8-U8 -> 67226.539
B9: EG_CCGT | C9: NR | D9: ThermalPower | E9: NG_CCGT_legacy | F9: INDIA | G9: MW | H9: NATGAS | I9: ELECTRICITY | J9: 8760 | K9: 0.40444272 | L9: 0.85 | M9: =8512.22780274884/1000 -> 8.5122278 | N9: =8512.227803/1000 -> 8.5122278 | O9: 0 | P9: 25 | Q9: 0.02 | R9: 0.9 | S9: 0.9 | T9: =Capacity!B6*1000 -> 7330.5467 | U9: 0 | V9: 0 | W9: 0 | X9: =CarriersTech_characteristics!$G$3 -> 37.6812 | Y9: =CarriersTech_characteristics!$H$3*1000 -> 3025024.5 | Z9: 2.9 | AA9: 0.105 | AC9: =1/K9/(1-Q9) -> 2.522998 | AE9: =(Y9*Conversions!$D$3)/(X9*Conversions!$D$2) -> 0.23958587 | AF9: 0 | AG9: =Z9*Conversions!$D$4 -> 3.592861 | AH9: =M9-AG9 -> 4.9193668 | AI9: =ROUND(P9/2,0) -> 13 | AJ9: =AA9/(1-(1+AA9)^-AI9) -> 0.14444512 | AK9: =AH9/AJ9 -> 34.056996 | AL9: =T9-U9 -> 7330.5467
B10: EG_OCGT | C10: NR | D10: ThermalPower | F10: INDIA | G10: MW | H10: NATGAS | I10: ELECTRICITY | J10: 8760 | K10: 0.28070163 | L10: 0.85 | M10: =6679.75064927145/1000 -> 6.6797506 | N10: =6679.750649/1000 -> 6.6797506 | O10: 0 | P10: 25 | Q10: 0.01 | R10: 1 | S10: 1 | T10: =Capacity!B7*1000 -> 0 | U10: 0 | V10: 0 | W10: 0 | X10: =CarriersTech_characteristics!$G$3 -> 37.6812 | Y10: =CarriersTech_characteristics!$H$3*1000 -> 3025024.5 | Z10: 0.7 | AA10: 0.105 | AC10: =1/K10/(1-Q10) -> 3.5984865 | AE10: =(Y10*Conversions!$D$3)/(X10*Conversions!$D$2) -> 0.23958587 | AF10: 0 | AG10: =Z10*Conversions!$D$4 -> 0.86724231 | AH10: =M10-AG10 -> 5.8125083 | AI10: =ROUND(P10/2,0) -> 13 | AJ10: =AA10/(1-(1+AA10)^-AI10) -> 0.14444512 | AK10: =AH10/AJ10 -> 40.240255 | AL10: =T10-U10 -> 0
B11: EG_PHWR | C11: NR | D11: ThermalPower | E11: nuclear_PHWR_legacy | F11: INDIA | G11: MW | H11: ATOMIC | I11: ELECTRICITY | J11: 8760 | K11: 1 | L11: 0.70916667 | M11: =20833.2103478327/1000 -> 20.83321 | N11: =20833.21035/1000 -> 20.83321 | O11: 0 | P11: 40 | Q11: 0.1078 | R11: 0.01 | S11: 0.01 | T11: =Capacity!B8*1000 -> 1603.5184 | U11: 0 | V11: 0 | W11: 0 | Z11: 4.3 | AA11: 0.105 | AC11: =1/K11/(1-Q11) -> 1.1208249 | AF11: 0 | AG11: =Z11*Conversions!$D$4 -> 5.3273456 | AH11: =M11-AG11 -> 15.505865 | AI11: =ROUND(P11/2,0) -> 20 | AJ11: =AA11/(1-(1+AA11)^-AI11) -> 0.12149327 | AK11: =AH11/AJ11 -> 127.62736 | AL11: =T11-U11 -> 1603.5184
B12: EG_SMR | C12: NR | D12: ThermalPower | F12: INDIA | G12: MW | H12: ATOMIC | I12: ELECTRICITY | J12: 8760 | K12: 1 | L12: 0.70916667 | M12: =N12 -> 35.289429 | N12: =35289.42939/1000 -> 35.289429 | O12: 0 | P12: 30 | Q12: 0.05 | R12: 0.01 | S12: 0.01 | T12: =Capacity!B9*1000 -> 0 | U12: 0 | V12: 0 | W12: 0 | Z12: 5 | AA12: 0.105 | AC12: =1/K12/(1-Q12) -> 1.0526316 | AF12: 0 | AG12: =Z12*Conversions!$D$4 -> 6.1945879 | AH12: =M12-AG12 -> 29.094841 | AI12: =ROUND(P12/2,0) -> 15 | AJ12: =AA12/(1-(1+AA12)^-AI12) -> 0.135248 | AK12: =AH12/AJ12 -> 215.12215 | AL12: =T12-U12 -> 0
B13: EG_LH | C13: NR | D13: HydroRes | E13: conventional_hydroelectric_legacy | F13: INDIA | G13: MW | H13: HYDEL | I13: ELECTRICITY | J13: 8760 | K13: 1 | L13: 1 | M13: =19631.8145207228/1000 -> 19.631815 | N13: =19631.81452/1000 -> 19.631815 | O13: 0 | P13: 40 | Q13: 0.006 | R13: 1 | S13: 1 | T13: =Capacity!B10*1000 -> 20527.317 | U13: 0 | V13: 0 | W13: 0 | Z13: 4.4 | AA13: 0.105 | AD13: =K13-Q13 -> 0.994 | AF13: 0 | AG13: =Z13*Conversions!$D$4 -> 5.4512374 | AH13: =M13-AG13 -> 14.180577 | AI13: =ROUND(P13/2,0) -> 20 | AJ13: =AA13/(1-(1+AA13)^-AI13) -> 0.12149327 | AK13: =AH13/AJ13 -> 116.71904 | AL13: =T13-U13 -> 20527.317
B14: EG_SH | C14: NR | D14: HydroRes | E14: conventional_hydroelectric_small_legacy | F14: INDIA | G14: MW | H14: HYDEL | I14: ELECTRICITY | J14: 8760 | K14: 1 | L14: 1 | M14: =11825.3487554956/1000 -> 11.825349 | N14: =11825.34876/1000 -> 11.825349 | O14: 0 | P14: 35 | Q14: 0.01 | R14: 1 | S14: 1 | T14: =Capacity!B11*1000 -> 1698.75 | U14: 0 | V14: 0 | W14: 0 | Z14: =2.4 -> 2.4 | AA14: 0.0835 | AD14: =K14-Q14 -> 0.99 | AF14: 0 | AG14: =Z14*Conversions!$D$4 -> 2.9734022 | AH14: =M14-AG14 -> 8.8519466 | AI14: =ROUND(P14/2,0) -> 18 | AJ14: =AA14/(1-(1+AA14)^-AI14) -> 0.10930622 | AK14: =AH14/AJ14 -> 80.983009 | AL14: =T14-U14 -> 1698.75
B15: EG_BIOMASS | C15: NR | D15: ThermalPower | E15: biomass_legacy | F15: INDIA | G15: MW | H15: BIOMASS_WASTE | I15: ELECTRICITY | J15: 8760 | K15: 0.2388459 | L15: 1 | M15: =7713.45723965334/1000 -> 7.7134572 | N15: =7713.45724/1000 -> 7.7134572 | O15: 0 | P15: 20 | Q15: 0.1 | R15: 0.06 | S15: 0.06 | T15: =Capacity!B12*1000 -> 3357.15 | U15: 0 | V15: 0 | W15: 0 | X15: =CarriersTech_characteristics!$G$7 -> 13.648968 | Y15: =CarriersTech_characteristics!$H$5*1000 -> 1656436.7 | Z15: 1 | AA15: 0.0835 | AC15: =1/K15/(1-Q15) -> 4.652 | AE15: =Y15/(X15*Conversions!$D$2) -> 0.43689545 | AF15: 0 | AG15: =Z15*Conversions!$D$4 -> 1.2389176 | AH15: =M15-AG15 -> 6.4745397 | AI15: =ROUND(P15/2,0) -> 10 | AJ15: =AA15/(1-(1+AA15)^-AI15) -> 0.15139063 | AK15: =AH15/AJ15 -> 42.767109 | AL15: =T15-U15 -> 3357.15
B16: EG_SOLARGM | C16: NR | D16: VRE | E16: solar_GM_legacy | F16: INDIA | G16: MW | H16: SUNLIGHT | I16: ELECTRICITY | J16: 8760 | K16: 1 | L16: 1 | M16: =5630.98419436319/1000 -> 5.6309842 | N16: =5439.705856/1000 -> 5.4397059 | O16: 0 | P16: 25 | Q16: 0.01 | R16: 1 | S16: 1 | T16: =Capacity!B13*1000 -> 19996.724 | U16: 0 | V16: 0 | W16: 0 | Z16: 0.35 | AA16: 0.105 | AC16: 1 | AF16: 0 | AG16: =Z16*Conversions!$D$4 -> 0.43362115 | AH16: =M16-AG16 -> 5.197363 | AI16: =ROUND(P16/2,0) -> 13 | AJ16: =AA16/(1-(1+AA16)^-AI16) -> 0.14444512 | AK16: =AH16/AJ16 -> 35.981577 | AL16: =T16-U16 -> 19996.724
B17: EG_SOLARRF | C17: NR | D17: VRE | E17: solar_RT_legacy | F17: INDIA | G17: MW | H17: SUNLIGHT | I17: ELECTRICITY | J17: 8760 | K17: 1 | L17: 1 | M17: =5542.18769541597/1000 -> 5.5421877 | N17: =5362.133837/1000 -> 5.3621338 | O17: 0 | P17: 25 | Q17: 0.006 | R17: 1 | S17: 1 | T17: =Capacity!B14*1000 -> 2666.3458 | U17: 0 | V17: 0 | W17: 0 | Z17: 0.51 | AA17: 0.104 | AC17: 1 | AF17: 0 | AG17: =Z17*Conversions!$D$4 -> 0.63184797 | AH17: =M17-AG17 -> 4.9103397 | AI17: =ROUND(P17/2,0) -> 13 | AJ17: =AA17/(1-(1+AA17)^-AI17) -> 0.14370863 | AK17: =AH17/AJ17 -> 34.168719 | AL17: =T17-U17 -> 2666.3458
B18: EG_WINDON | C18: NR | D18: VRE | E18: onshore_wind_legacy | F18: INDIA | G18: MW | H18: WIND | I18: ELECTRICITY | J18: 8760 | K18: 1 | L18: 1 | M18: =10659.4302732183/1000 -> 10.65943 | N18: =10586.96446/1000 -> 10.586964 | O18: 0 | P18: 25 | Q18: 0.005 | R18: 1 | S18: 1 | T18: =Capacity!B15*1000 -> 5301.42 | U18: 0 | V18: 0 | W18: 0 | Z18: 0.68 | AA18: 0.105 | AC18: 1 | AF18: 0 | AG18: =Z18*Conversions!$D$4 -> 0.84246396 | AH18: =M18-AG18 -> 9.8169663 | AI18: =ROUND(P18/2,0) -> 13 | AJ18: =AA18/(1-(1+AA18)^-AI18) -> 0.14444512 | AK18: =AH18/AJ18 -> 67.963296 | AL18: =T18-U18 -> 5301.42
B19: EG_WINDOFF | C19: NR | D19: VRE | F19: INDIA | G19: MW | H19: WIND | I19: ELECTRICITY | J19: 8760 | K19: 1 | L19: 1 | M19: =N19 -> 34.540362 | N19: =34540.36167/1000 -> 34.540362 | O19: 0 | P19: 25 | Q19: 0.005 | R19: 1 | S19: 1 | T19: =Capacity!B16*1000 -> 0 | U19: 0 | V19: 0 | W19: 0 | Z19: 6.7 | AA19: 0.112 | AC19: 1 | AF19: 0 | AG19: =Z19*Conversions!$D$4 -> 8.3007478 | AH19: =M19-AG19 -> 26.239614 | AI19: =ROUND(P19/2,0) -> 13 | AJ19: =AA19/(1-(1+AA19)^-AI19) -> 0.14964415 | AK19: =AH19/AJ19 -> 175.34674 | AL19: =T19-U19 -> 0
B20: EG_COAL | C20: NER | D20: ThermalPower | E20: coal_legacy | F20: INDIA | G20: MW | H20: THERMAL_COAL | I20: ELECTRICITY | J20: 8760 | K20: 0.3809682 | L20: 0.85 | M20: =26148.8463751508/1000 -> 26.148846 | N20: =13721.03129/1000 -> 13.721031 | O20: 133.52302 | P20: 40 | Q20: 0.066 | R20: 0.3 | S20: 0.3 | T20: =Capacity!B19*1000 -> 1010.9297 | U20: 0 | V20: 0 | W20: 0 | X20: =CarriersTech_characteristics!$G$2 -> 17.207188 | Y20: =CarriersTech_characteristics!$H$28*1000 -> 1942097.6 | Z20: 3 | AA20: 0.105 | AC20: =1/K20/(1-Q20) -> 2.8103758 | AE20: =Y20/(X20*Conversions!$D$2) -> 0.40631575 | AF20: =O20/CarriersTech_characteristics!$G$2/Conversions!$D$2*AC20 -> 7.850786e-05 | AG20: =Z20*Conversions!$D$4 -> 3.7167527 | AH20: =M20-AG20 -> 22.432094 | AI20: =ROUND(P20/2,0) -> 20 | AJ20: =AA20/(1-(1+AA20)^-AI20) -> 0.12149327 | AK20: =AH20/AJ20 -> 184.63652 | AL20: =T20-U20 -> 1010.9297
B21: EG_CCGT | C21: NER | D21: ThermalPower | E21: NG_CCGT_legacy | F21: INDIA | G21: MW | H21: NATGAS | I21: ELECTRICITY | J21: 8760 | K21: 0.40444272 | L21: 0.85 | M21: =8512.22780274884/1000 -> 8.5122278 | N21: =8512.227803/1000 -> 8.5122278 | O21: 0 | P21: 25 | Q21: 0.02 | R21: 0.9 | S21: 0.9 | T21: =Capacity!B20*1000 -> 2002.4569 | U21: 0 | V21: 0 | W21: 0 | X21: =CarriersTech_characteristics!$G$3 -> 37.6812 | Y21: =CarriersTech_characteristics!$H$3*1000 -> 3025024.5 | Z21: 2.9 | AA21: 0.105 | AC21: =1/K21/(1-Q21) -> 2.522998 | AE21: =(Y21*Conversions!$D$3)/(X21*Conversions!$D$2) -> 0.23958587 | AF21: 0 | AG21: =Z21*Conversions!$D$4 -> 3.592861 | AH21: =M21-AG21 -> 4.9193668 | AI21: =ROUND(P21/2,0) -> 13 | AJ21: =AA21/(1-(1+AA21)^-AI21) -> 0.14444512 | AK21: =AH21/AJ21 -> 34.056996 | AL21: =T21-U21 -> 2002.4569
B22: EG_OCGT | C22: NER | D22: ThermalPower | F22: INDIA | G22: MW | H22: NATGAS | I22: ELECTRICITY | J22: 8760 | K22: 0.28070163 | L22: 0.85 | M22: =6679.75064927145/1000 -> 6.6797506 | N22: =6679.750649/1000 -> 6.6797506 | O22: 0 | P22: 25 | Q22: 0.01 | R22: 1 | S22: 1 | T22: =Capacity!B21*1000 -> 0 | U22: 0 | V22: 0 | W22: 0 | X22: =CarriersTech_characteristics!$G$3 -> 37.6812 | Y22: =CarriersTech_characteristics!$H$3*1000 -> 3025024.5 | Z22: 0.7 | AA22: 0.105 | AC22: =1/K22/(1-Q22) -> 3.5984865 | AE22: =(Y22*Conversions!$D$3)/(X22*Conversions!$D$2) -> 0.23958587 | AF22: 0 | AG22: =Z22*Conversions!$D$4 -> 0.86724231 | AH22: =M22-AG22 -> 5.8125083 | AI22: =ROUND(P22/2,0) -> 13 | AJ22: =AA22/(1-(1+AA22)^-AI22) -> 0.14444512 | AK22: =AH22/AJ22 -> 40.240255 | AL22: =T22-U22 -> 0
B23: EG_PHWR | C23: NER | D23: ThermalPower | E23: nuclear_PHWR_legacy | F23: INDIA | G23: MW | H23: ATOMIC | I23: ELECTRICITY | J23: 8760 | K23: 1 | L23: 0.70916667 | M23: =20833.2103478327/1000 -> 20.83321 | N23: =20833.21035/1000 -> 20.83321 | O23: 0 | P23: 40 | Q23: 0.1078 | R23: 0.01 | S23: 0.01 | T23: =Capacity!B22*1000 -> 0 | U23: 0 | V23: 0 | W23: 0 | Z23: 4.3 | AA23: 0.105 | AC23: =1/K23/(1-Q23) -> 1.1208249 | AF23: 0 | AG23: =Z23*Conversions!$D$4 -> 5.3273456 | AH23: =M23-AG23 -> 15.505865 | AI23: =ROUND(P23/2,0) -> 20 | AJ23: =AA23/(1-(1+AA23)^-AI23) -> 0.12149327 | AK23: =AH23/AJ23 -> 127.62736 | AL23: =T23-U23 -> 0
B24: EG_SMR | C24: NER | D24: ThermalPower | F24: INDIA | G24: MW | H24: ATOMIC | I24: ELECTRICITY | J24: 8760 | K24: 1 | L24: 0.70916667 | M24: =N24 -> 35.289429 | N24: =35289.42939/1000 -> 35.289429 | O24: 0 | P24: 30 | Q24: 0.05 | R24: 0.01 | S24: 0.01 | T24: =Capacity!B23*1000 -> 0 | U24: 0 | V24: 0 | W24: 0 | Z24: 5 | AA24: 0.105 | AC24: =1/K24/(1-Q24) -> 1.0526316 | AF24: 0 | AG24: =Z24*Conversions!$D$4 -> 6.1945879 | AH24: =M24-AG24 -> 29.094841 | AI24: =ROUND(P24/2,0) -> 15 | AJ24: =AA24/(1-(1+AA24)^-AI24) -> 0.135248 | AK24: =AH24/AJ24 -> 215.12215 | AL24: =T24-U24 -> 0
B25: EG_LH | C25: NER | D25: HydroRes | E25: conventional_hydroelectric_legacy | F25: INDIA | G25: MW | H25: HYDEL | I25: ELECTRICITY | J25: 8760 | K25: 1 | L25: 1 | M25: =19631.8145207228/1000 -> 19.631815 | N25: =19631.81452/1000 -> 19.631815 | O25: 0 | P25: 40 | Q25: 0.006 | R25: 1 | S25: 1 | T25: =Capacity!B24*1000 -> 1842.8253 | U25: 0 | V25: 0 | W25: 0 | Z25: 4.4 | AA25: 0.105 | AD25: =K25-Q25 -> 0.994 | AF25: 0 | AG25: =Z25*Conversions!$D$4 -> 5.4512374 | AH25: =M25-AG25 -> 14.180577 | AI25: =ROUND(P25/2,0) -> 20 | AJ25: =AA25/(1-(1+AA25)^-AI25) -> 0.12149327 | AK25: =AH25/AJ25 -> 116.71904 | AL25: =T25-U25 -> 1842.8253
B26: EG_SH | C26: NER | D26: HydroRes | E26: conventional_hydroelectric_small_legacy | F26: INDIA | G26: MW | H26: HYDEL | I26: ELECTRICITY | J26: 8760 | K26: 1 | L26: 1 | M26: =11825.3487554956/1000 -> 11.825349 | N26: =11825.34876/1000 -> 11.825349 | O26: 0 | P26: 35 | Q26: 0.01 | R26: 1 | S26: 1 | T26: =Capacity!B25*1000 -> 299.35 | U26: 0 | V26: 0 | W26: 0 | Z26: =2.4 -> 2.4 | AA26: 0.0835 | AD26: =K26-Q26 -> 0.99 | AF26: 0 | AG26: =Z26*Conversions!$D$4 -> 2.9734022 | AH26: =M26-AG26 -> 8.8519466 | AI26: =ROUND(P26/2,0) -> 18 | AJ26: =AA26/(1-(1+AA26)^-AI26) -> 0.10930622 | AK26: =AH26/AJ26 -> 80.983009 | AL26: =T26-U26 -> 299.35
B27: EG_BIOMASS | C27: NER | D27: ThermalPower | E27: biomass_legacy | F27: INDIA | G27: MW | H27: BIOMASS_WASTE | I27: ELECTRICITY | J27: 8760 | K27: 0.2388459 | L27: 1 | M27: =7713.45723965334/1000 -> 7.7134572 | N27: =7713.45724/1000 -> 7.7134572 | O27: 0 | P27: 20 | Q27: 0.1 | R27: 0.06 | S27: 0.06 | T27: =Capacity!B26*1000 -> 15.8 | U27: 0 | V27: 0 | W27: 0 | X27: =CarriersTech_characteristics!$G$7 -> 13.648968 | Y27: =CarriersTech_characteristics!$H$5*1000 -> 1656436.7 | Z27: 1 | AA27: 0.0835 | AC27: =1/K27/(1-Q27) -> 4.652 | AE27: =Y27/(X27*Conversions!$D$2) -> 0.43689545 | AF27: 0 | AG27: =Z27*Conversions!$D$4 -> 1.2389176 | AH27: =M27-AG27 -> 6.4745397 | AI27: =ROUND(P27/2,0) -> 10 | AJ27: =AA27/(1-(1+AA27)^-AI27) -> 0.15139063 | AK27: =AH27/AJ27 -> 42.767109 | AL27: =T27-U27 -> 15.8
B28: EG_SOLARGM | C28: NER | D28: VRE | E28: solar_GM_legacy | F28: INDIA | G28: MW | H28: SUNLIGHT | I28: ELECTRICITY | J28: 8760 | K28: 1 | L28: 1 | M28: =5630.98419436319/1000 -> 5.6309842 | N28: =5439.705856/1000 -> 5.4397059 | O28: 0 | P28: 25 | Q28: 0.01 | R28: 1 | S28: 1 | T28: =Capacity!B27*1000 -> 171.48962 | U28: 0 | V28: 0 | W28: 0 | Z28: 0.35 | AA28: 0.105 | AC28: 1 | AF28: 0 | AG28: =Z28*Conversions!$D$4 -> 0.43362115 | AH28: =M28-AG28 -> 5.197363 | AI28: =ROUND(P28/2,0) -> 13 | AJ28: =AA28/(1-(1+AA28)^-AI28) -> 0.14444512 | AK28: =AH28/AJ28 -> 35.981577 | AL28: =T28-U28 -> 171.48962
B29: EG_SOLARRF | C29: NER | D29: VRE | E29: solar_RT_legacy | F29: INDIA | G29: MW | H29: SUNLIGHT | I29: ELECTRICITY | J29: 8760 | K29: 1 | L29: 1 | M29: =5542.18769541597/1000 -> 5.5421877 | N29: =5362.133837/1000 -> 5.3621338 | O29: 0 | P29: 25 | Q29: 0.006 | R29: 1 | S29: 1 | T29: =Capacity!B28*1000 -> 67.610378 | U29: 0 | V29: 0 | W29: 0 | Z29: 0.51 | AA29: 0.104 | AC29: 1 | AF29: 0 | AG29: =Z29*Conversions!$D$4 -> 0.63184797 | AH29: =M29-AG29 -> 4.9103397 | AI29: =ROUND(P29/2,0) -> 13 | AJ29: =AA29/(1-(1+AA29)^-AI29) -> 0.14370863 | AK29: =AH29/AJ29 -> 34.168719 | AL29: =T29-U29 -> 67.610378
B30: EG_WINDON | C30: NER | D30: VRE | E30: onshore_wind_legacy | F30: INDIA | G30: MW | H30: WIND | I30: ELECTRICITY | J30: 8760 | K30: 1 | L30: 1 | M30: =10659.4302732183/1000 -> 10.65943 | N30: =10586.96446/1000 -> 10.586964 | O30: 0 | P30: 25 | Q30: 0.005 | R30: 1 | S30: 1 | T30: =Capacity!B29*1000 -> 0 | U30: 0 | V30: 0 | W30: 0 | Z30: 0.68 | AA30: 0.105 | AC30: 1 | AF30: 0 | AG30: =Z30*Conversions!$D$4 -> 0.84246396 | AH30: =M30-AG30 -> 9.8169663 | AI30: =ROUND(P30/2,0) -> 13 | AJ30: =AA30/(1-(1+AA30)^-AI30) -> 0.14444512 | AK30: =AH30/AJ30 -> 67.963296 | AL30: =T30-U30 -> 0
B31: EG_WINDOFF | C31: NER | D31: VRE | F31: INDIA | G31: MW | H31: WIND | I31: ELECTRICITY | J31: 8760 | K31: 1 | L31: 1 | M31: =N31 -> 34.540362 | N31: =34540.36167/1000 -> 34.540362 | O31: 0 | P31: 25 | Q31: 0.005 | R31: 1 | S31: 1 | T31: =Capacity!B30*1000 -> 0 | U31: 0 | V31: 0 | W31: 0 | Z31: 6.7 | AA31: 0.112 | AC31: 1 | AF31: 0 | AG31: =Z31*Conversions!$D$4 -> 8.3007478 | AH31: =M31-AG31 -> 26.239614 | AI31: =ROUND(P31/2,0) -> 13 | AJ31: =AA31/(1-(1+AA31)^-AI31) -> 0.14964415 | AK31: =AH31/AJ31 -> 175.34674 | AL31: =T31-U31 -> 0
B32: EG_COAL | C32: ER | D32: ThermalPower | E32: coal_legacy | F32: INDIA | G32: MW | H32: THERMAL_COAL | I32: ELECTRICITY | J32: 8760 | K32: 0.3809682 | L32: 0.85 | M32: =6514.90571684157/1000 -> 6.5149057 | N32: =13721.03129/1000 -> 13.721031 | O32: 133.52302 | P32: 40 | Q32: 0.066 | R32: 0.3 | S32: 0.3 | T32: =Capacity!B33*1000 -> 41729.904 | U32: 0 | V32: 0 | W32: 0 | X32: =CarriersTech_characteristics!$G$2 -> 17.207188 | Y32: =CarriersTech_characteristics!$H$28*1000 -> 1942097.6 | Z32: 3 | AA32: 0.105 | AC32: =1/K32/(1-Q32) -> 2.8103758 | AE32: =Y32/(X32*Conversions!$D$2) -> 0.40631575 | AF32: =O32/CarriersTech_characteristics!$G$2/Conversions!$D$2*AC32 -> 7.850786e-05 | AG32: =Z32*Conversions!$D$4 -> 3.7167527 | AH32: =M32-AG32 -> 2.798153 | AI32: =ROUND(P32/2,0) -> 20 | AJ32: =AA32/(1-(1+AA32)^-AI32) -> 0.12149327 | AK32: =AH32/AJ32 -> 23.031342 | AL32: =T32-U32 -> 41729.904
B33: EG_CCGT | C33: ER | D33: ThermalPower | E33: NG_CCGT_legacy | F33: INDIA | G33: MW | H33: NATGAS | I33: ELECTRICITY | J33: 8760 | K33: 0.40444272 | L33: 0.85 | M33: =8512.22780274884/1000 -> 8.5122278 | N33: =8512.227803/1000 -> 8.5122278 | O33: 0 | P33: 25 | Q33: 0.02 | R33: 0.9 | S33: 0.9 | T33: =Capacity!B34*1000 -> 770.80433 | U33: 0 | V33: 0 | W33: 0 | X33: =CarriersTech_characteristics!$G$3 -> 37.6812 | Y33: =CarriersTech_characteristics!$H$3*1000 -> 3025024.5 | Z33: 2.9 | AA33: 0.105 | AC33: =1/K33/(1-Q33) -> 2.522998 | AE33: =(Y33*Conversions!$D$3)/(X33*Conversions!$D$2) -> 0.23958587 | AF33: 0 | AG33: =Z33*Conversions!$D$4 -> 3.592861 | AH33: =M33-AG33 -> 4.9193668 | AI33: =ROUND(P33/2,0) -> 13 | AJ33: =AA33/(1-(1+AA33)^-AI33) -> 0.14444512 | AK33: =AH33/AJ33 -> 34.056996 | AL33: =T33-U33 -> 770.80433
B34: EG_OCGT | C34: ER | D34: ThermalPower | F34: INDIA | G34: MW | H34: NATGAS | I34: ELECTRICITY | J34: 8760 | K34: 0.28070163 | L34: 0.85 | M34: =6679.75064927145/1000 -> 6.6797506 | N34: =6679.750649/1000 -> 6.6797506 | O34: 0 | P34: 25 | Q34: 0.01 | R34: 1 | S34: 1 | T34: =Capacity!B35*1000 -> 0 | U34: 0 | V34: 0 | W34: 0 | X34: =CarriersTech_characteristics!$G$3 -> 37.6812 | Y34: =CarriersTech_characteristics!$H$3*1000 -> 3025024.5 | Z34: 0.7 | AA34: 0.105 | AC34: =1/K34/(1-Q34) -> 3.5984865 | AE34: =(Y34*Conversions!$D$3)/(X34*Conversions!$D$2) -> 0.23958587 | AF34: 0 | AG34: =Z34*Conversions!$D$4 -> 0.86724231 | AH34: =M34-AG34 -> 5.8125083 | AI34: =ROUND(P34/2,0) -> 13 | AJ34: =AA34/(1-(1+AA34)^-AI34) -> 0.14444512 | AK34: =AH34/AJ34 -> 40.240255 | AL34: =T34-U34 -> 0
B35: EG_PHWR | C35: ER | D35: ThermalPower | E35: nuclear_PHWR_legacy | F35: INDIA | G35: MW | H35: ATOMIC | I35: ELECTRICITY | J35: 8760 | K35: 1 | L35: 0.70916667 | M35: =20833.2103478327/1000 -> 20.83321 | N35: =20833.21035/1000 -> 20.83321 | O35: 0 | P35: 40 | Q35: 0.1078 | R35: 0.01 | S35: 0.01 | T35: =Capacity!B36*1000 -> 0 | U35: 0 | V35: 0 | W35: 0 | Z35: 4.3 | AA35: 0.105 | AC35: =1/K35/(1-Q35) -> 1.1208249 | AF35: 0 | AG35: =Z35*Conversions!$D$4 -> 5.3273456 | AH35: =M35-AG35 -> 15.505865 | AI35: =ROUND(P35/2,0) -> 20 | AJ35: =AA35/(1-(1+AA35)^-AI35) -> 0.12149327 | AK35: =AH35/AJ35 -> 127.62736 | AL35: =T35-U35 -> 0
B36: EG_SMR | C36: ER | D36: ThermalPower | F36: INDIA | G36: MW | H36: ATOMIC | I36: ELECTRICITY | J36: 8760 | K36: 1 | L36: 0.70916667 | M36: =N36 -> 35.289429 | N36: =35289.42939/1000 -> 35.289429 | O36: 0 | P36: 30 | Q36: 0.05 | R36: 0.01 | S36: 0.01 | T36: =Capacity!B37*1000 -> 0 | U36: 0 | V36: 0 | W36: 0 | Z36: 5 | AA36: 0.105 | AC36: =1/K36/(1-Q36) -> 1.0526316 | AF36: 0 | AG36: =Z36*Conversions!$D$4 -> 6.1945879 | AH36: =M36-AG36 -> 29.094841 | AI36: =ROUND(P36/2,0) -> 15 | AJ36: =AA36/(1-(1+AA36)^-AI36) -> 0.135248 | AK36: =AH36/AJ36 -> 215.12215 | AL36: =T36-U36 -> 0
B37: EG_LH | C37: ER | D37: HydroRes | E37: conventional_hydroelectric_legacy | F37: INDIA | G37: MW | H37: HYDEL | I37: ELECTRICITY | J37: 8760 | K37: 1 | L37: 1 | M37: =19631.8145207228/1000 -> 19.631815 | N37: =19631.81452/1000 -> 19.631815 | O37: 0 | P37: 40 | Q37: 0.006 | R37: 1 | S37: 1 | T37: =Capacity!B38*1000 -> 4198.8603 | U37: 0 | V37: 0 | W37: 0 | Z37: 4.4 | AA37: 0.105 | AD37: =K37-Q37 -> 0.994 | AF37: 0 | AG37: =Z37*Conversions!$D$4 -> 5.4512374 | AH37: =M37-AG37 -> 14.180577 | AI37: =ROUND(P37/2,0) -> 20 | AJ37: =AA37/(1-(1+AA37)^-AI37) -> 0.12149327 | AK37: =AH37/AJ37 -> 116.71904 | AL37: =T37-U37 -> 4198.8603
B38: EG_SH | C38: ER | D38: HydroRes | E38: conventional_hydroelectric_small_legacy | F38: INDIA | G38: MW | H38: HYDEL | I38: ELECTRICITY | J38: 8760 | K38: 1 | L38: 1 | M38: =11825.3487554956/1000 -> 11.825349 | N38: =11825.34876/1000 -> 11.825349 | O38: 0 | P38: 35 | Q38: 0.01 | R38: 1 | S38: 1 | T38: =Capacity!B39*1000 -> 343.99 | U38: 0 | V38: 0 | W38: 0 | Z38: =2.4 -> 2.4 | AA38: 0.0835 | AD38: =K38-Q38 -> 0.99 | AF38: 0 | AG38: =Z38*Conversions!$D$4 -> 2.9734022 | AH38: =M38-AG38 -> 8.8519466 | AI38: =ROUND(P38/2,0) -> 18 | AJ38: =AA38/(1-(1+AA38)^-AI38) -> 0.10930622 | AK38: =AH38/AJ38 -> 80.983009 | AL38: =T38-U38 -> 343.99
B39: EG_BIOMASS | C39: ER | D39: ThermalPower | E39: biomass_legacy | F39: INDIA | G39: MW | H39: BIOMASS_WASTE | I39: ELECTRICITY | J39: 8760 | K39: 0.2388459 | L39: 1 | M39: =7713.45723965334/1000 -> 7.7134572 | N39: =7713.45724/1000 -> 7.7134572 | O39: 0 | P39: 20 | Q39: 0.1 | R39: 0.06 | S39: 0.06 | T39: =Capacity!B40*1000 -> 560.64 | U39: 0 | V39: 0 | W39: 0 | X39: =CarriersTech_characteristics!$G$7 -> 13.648968 | Y39: =CarriersTech_characteristics!$H$5*1000 -> 1656436.7 | Z39: 1 | AA39: 0.0835 | AC39: =1/K39/(1-Q39) -> 4.652 | AE39: =Y39/(X39*Conversions!$D$2) -> 0.43689545 | AF39: 0 | AG39: =Z39*Conversions!$D$4 -> 1.2389176 | AH39: =M39-AG39 -> 6.4745397 | AI39: =ROUND(P39/2,0) -> 10 | AJ39: =AA39/(1-(1+AA39)^-AI39) -> 0.15139063 | AK39: =AH39/AJ39 -> 42.767109 | AL39: =T39-U39 -> 560.64
B40: EG_SOLARGM | C40: ER | D40: VRE | E40: solar_GM_legacy | F40: INDIA | G40: MW | H40: SUNLIGHT | I40: ELECTRICITY | J40: 8760 | K40: 1 | L40: 1 | M40: =5630.98419436319/1000 -> 5.6309842 | N40: =5439.705856/1000 -> 5.4397059 | O40: 0 | P40: 25 | Q40: 0.01 | R40: 1 | S40: 1 | T40: =Capacity!B41*1000 -> 847.7259 | U40: 0 | V40: 0 | W40: 0 | Z40: 0.35 | AA40: 0.105 | AC40: 1 | AF40: 0 | AG40: =Z40*Conversions!$D$4 -> 0.43362115 | AH40: =M40-AG40 -> 5.197363 | AI40: =ROUND(P40/2,0) -> 13 | AJ40: =AA40/(1-(1+AA40)^-AI40) -> 0.14444512 | AK40: =AH40/AJ40 -> 35.981577 | AL40: =T40-U40 -> 847.7259
...

Sheet assets_gen_p2
A1: Source::File | G1: PIER::EnergyConvTechnologies.csv | H1: PIER::EnergyConvTechnologies.csv | I1: PIER::EnergyConvTechnologies.csv | J1: PIER::EnergyConvTechnologies.csv | K1: PIER2.0_ECT::EfficiencyCostMaxAnnual.csv | L1: PIER2.0_ECT::EfficiencyCostMaxAnnual.csv | M1: PIER2.0_ECT::EfficiencyCostMaxAnnual.csv | N1: PIER2.0_ECT::EfficiencyCostMaxAnnual.csv | O1: PIER2.0_ECT::EfficiencyCostMaxAnnual.csv | P1: PIER2.0::ECT_Lifetime.csv | Q1: PIER2.0::ECT_OperationalInfo.csv | R1: PIER2.0::ECT_OperationalInfo.csv | S1: PIER2.0::ECT_OperationalInfo.csv | T1: PIER2.0::ECT_LegacyCapacity.csv | V1: PIER2.0::ECT_CapAddBounds.csv | W1: PIER2.0::ECT_CapAddBounds.csv | X1: PIER2.0::PhysicalDerivedCarriers.csv | Y1: PIER2.0::PhysicalCarrierEmissions.csv | Z1: PIER2.0::ECT_EfficiencyCostMaxAnnualUF.xlsx | AA1: PIER2.0::ECT_EfficiencyCostMaxAnnualUF.xlsx
A2: PIER2.0 var name | B2: EnergyConvTech | C2: SubGeography1 | F2: ModelGeography | G2: CapacityUnit | H2: InputEC | I2: OutputDEC | J2: AnnualOutputPerUnitCapacity | K2: ConvEff | L2: MaxAnnualUF | M2: FixedCost | N2: FixedCost | O2: VarCost | P2: Lifetime | Q2: SelfCons | R2: MaxRampUpRate | S2: MaxRampDownRate | T2: LegacyCapacity | U2: RetCapacity | V2: MinCapacity | W2: MaxCapacity | X2: DomEnergyDensity | Y2: DomEmissionFactor
A3: Variable | K3: a | L3: b | M3: c | N3: d | O3: e | P3: f | Q3: g | R3: h | S3: i | T3: j | U3: k | V3: l | W3: m | X3: n | Y3: o | Z3: p | AA3: q | AC3: aa | AD3: bb | AE3: cc | AF3: dd | AG3: ee | AH3: ff | AI3: gg | AJ3: hh | AK3: ii | AL3: jj
A4: description | C4: model geography | G4: all units in macro are given in the selected value | H4: energy carrier | I4: energy carrier | J4: model granularity | K4: efficiency of conversion of energy input to output | L4: max utilization factor (over whole year) ** this must be considered alongside availability for technology provided in ECT_Max_CUF.csv to arrive at more granular availability profiles (see code) | M4: annuity on existiting capacity | N4: annuity on new capacity | O4: variable cost per Mt of input energy carrier | P4: lifetime of asset | Q4: % of energy input consumed by technology (not part of output) | T4: legacy/existing | U4: legacy capacity retired | V4: pipeline builds | W4: maximum additions | X4: given | Y4: given | Z4: given Fixed O&M (PIER or assumed), adjusted to 2024Rs from 2020Rs | AA4: given discount rate from PIER2.0 workbook, No adjustment made | AC4: self-consumption adjsuted fuel consumption of generating unit | AD4: self-consumption adjusted efficiency | AE4: doemstic only, need imported ! | AH4: This is without fixed O&M as expected by Macro | AI4: For existing infrastructure this is half operational lifetime, rounded to integer as Macro will fail if given decimal | AL4: legacy capacity
A5: Equation to Macro var | G5: given / 1000 | H5: given | M5: given/1000 | N5: given/1000 | P5: given | R5: given | S5: given | T5: = given*1000 | U5: = given*1000 | V5: = given*1000 | W5: = given*1000 | AA5: = given | AC5: = 1 / a / (1 -g) | AD5: = a - g | AE5: = ( n * conversion_if_not _MT) / (o * conversion_PJ_to_MWh) | AF5: = e / on/ conversion_PJ_to_MWh * aa | AG5: = p * 2020 to 2024 inflator | AH5: = d - ee | AI5: = round ( f / 2 , 0) | AJ5: = q / ( 1-(1+q)^(-gg)) | AK5: = ff / hh | AL5: = j - k
A6: Macro variable | C6: location | D6: type | E6: id | H6: fuel_commodity | M6: annualized_investment_cost | N6: annualized_investment_cost | P6: lifetime of asset | R6: ramp_up_fraction | S6: ramp_down_fraction | V6: min_capcity | W6: max_capacity | AA6: wacc | AC6: fuel_consumption | AD6: discharge_efficiency | AE6: emission_rate | AF6: variable_om_cost | AG6: fixed_om_cost | AH6: annualized_investment_cost | AI6: capital_recovery_period | AJ6: CRF | AK6: investment_cost | AL6: existing_capacity
A7: Unit | K7: % | L7: % | M7: million Rs2024/MW | N7: million Rs2024/MW | O7: million Rs / Mt | P7: years | Q7: % | R7: fraction of capacity | S7: fraction of capacity | T7: MW | U7: MW | V7: MW | W7: MW | X7: PJ/MT or PJ/BCM | Y7: tonnes CO2/MT (no BCM) | Z7: million 2020Rs/year | AA7: % | AC7: MWin per Mwout | AD7: % | AE7: tCO2/MWh input | AF7: millionRs/MWh-elec | AG7: million 2024Rs/year | AH7: million 2024Rs/year | AI7: years | AJ7: % total investment per capital recovery year | AK7: million 2024Rs | AL7: MW
B8: EG_COAL | C8: NR | D8: ThermalPower | E8: coal | F8: INDIA | G8: MW | H8: THERMAL_COAL | I8: ELECTRICITY | J8: 8760 | K8: 0.3809682 | L8: 0.85 | M8: =11751.5992748699/1000 -> 11.751599 | N8: =13721.03129/1000 -> 13.721031 | O8: 133.52302 | P8: 40 | Q8: 0.066 | R8: 0.3 | S8: 0.3 | T8: =Capacity!B5*1000 -> 67226.539 | U8: =Capacity!AR5*1000 -> 220 | V8: =Capacity!D5*1000 -> 0 | W8: =Capacity!X5*1000 -> 0 | X8: =CarriersTech_characteristics!$G$2 -> 17.207188 | Y8: =CarriersTech_characteristics!$H$28*1000 -> 1942097.6 | Z8: 3 | AA8: 0.105 | AC8: =1/K8/(1-Q8) -> 2.8103758 | AE8: =Y8/(X8*Conversions!$D$2) -> 0.40631575 | AF8: =O8/X8/Conversions!$D$2*AC8 -> 7.850786e-05 | AG8: =Z8*Conversions!$D$4 -> 3.7167527 | AH8: =M8-AG8 -> 8.0348465 | AI8: =P8 -> 40 | AJ8: =AA8/(1-(1+AA8)^-AI8) -> 0.10697141 | AK8: =AH8/AJ8 -> 75.112094 | AL8: =T8-U8 -> 67006.539
B9: EG_CCGT | C9: NR | D9: ThermalPower | E9: NG_CCGT | F9: INDIA | G9: MW | H9: NATGAS | I9: ELECTRICITY | J9: 8760 | K9: 0.40444272 | L9: 0.85 | M9: =8512.22780274884/1000 -> 8.5122278 | N9: =8512.227803/1000 -> 8.5122278 | O9: 0 | P9: 25 | Q9: 0.02 | R9: 0.9 | S9: 0.9 | T9: =Capacity!B6*1000 -> 7330.5467 | U9: =Capacity!AR6*1000 -> 0 | V9: =Capacity!D6*1000 -> 0 | W9: =Capacity!X6*1000 -> 0 | X9: =CarriersTech_characteristics!$G$3 -> 37.6812 | Y9: =CarriersTech_characteristics!$H$3*1000 -> 3025024.5 | Z9: 2.9 | AA9: 0.105 | AC9: =1/K9/(1-Q9) -> 2.522998 | AE9: =(Y9*Conversions!$D$3)/(X9*Conversions!$D$2) -> 0.23958587 | AF9: 0 | AG9: =Z9*Conversions!$D$4 -> 3.592861 | AH9: =M9-AG9 -> 4.9193668 | AI9: =P9 -> 25 | AJ9: =AA9/(1-(1+AA9)^-AI9) -> 0.11442932 | AK9: =AH9/AJ9 -> 42.99044 | AL9: =T9-U9 -> 7330.5467
B10: EG_OCGT | C10: NR | D10: ThermalPower | F10: INDIA | G10: MW | H10: NATGAS | I10: ELECTRICITY | J10: 8760 | K10: 0.28070163 | L10: 0.85 | M10: =6679.75064927145/1000 -> 6.6797506 | N10: =6679.750649/1000 -> 6.6797506 | O10: 0 | P10: 25 | Q10: 0.01 | R10: 1 | S10: 1 | T10: =Capacity!B7*1000 -> 0 | U10: =Capacity!AR7*1000 -> 0 | V10: =Capacity!D7*1000 -> 0 | W10: =Capacity!X7*1000 -> 0 | X10: =CarriersTech_characteristics!$G$3 -> 37.6812 | Y10: =CarriersTech_characteristics!$H$3*1000 -> 3025024.5 | Z10: 0.7 | AA10: 0.105 | AC10: =1/K10/(1-Q10) -> 3.5984865 | AE10: =(Y10*Conversions!$D$3)/(X10*Conversions!$D$2) -> 0.23958587 | AF10: 0 | AG10: =Z10*Conversions!$D$4 -> 0.86724231 | AH10: =M10-AG10 -> 5.8125083 | AI10: =P10 -> 25 | AJ10: =AA10/(1-(1+AA10)^-AI10) -> 0.11442932 | AK10: =AH10/AJ10 -> 50.795621 | AL10: =T10-U10 -> 0
B11: EG_PHWR | C11: NR | D11: ThermalPower | E11: nuclear_PHWR | F11: INDIA | G11: MW | H11: ATOMIC | I11: ELECTRICITY | J11: 8760 | K11: 1 | L11: 0.70916667 | M11: =20833.2103478327/1000 -> 20.83321 | N11: =20833.21035/1000 -> 20.83321 | O11: 0 | P11: 40 | Q11: 0.1078 | R11: 0.01 | S11: 0.01 | T11: =Capacity!B8*1000 -> 1603.5184 | U11: =Capacity!AR8*1000 -> 0 | V11: =Capacity!D8*1000 -> 0 | W11: =Capacity!X8*1000 -> 0 | Z11: 4.3 | AA11: 0.105 | AC11: =1/K11/(1-Q11) -> 1.1208249 | AF11: 0 | AG11: =Z11*Conversions!$D$4 -> 5.3273456 | AH11: =M11-AG11 -> 15.505865 | AI11: =P11 -> 40 | AJ11: =AA11/(1-(1+AA11)^-AI11) -> 0.10697141 | AK11: =AH11/AJ11 -> 144.95336 | AL11: =T11-U11 -> 1603.5184
B12: EG_SMR | C12: NR | D12: ThermalPower | F12: INDIA | G12: MW | H12: ATOMIC | I12: ELECTRICITY | J12: 8760 | K12: 1 | L12: 0.70916667 | M12: =N12 -> 35.289429 | N12: =35289.42939/1000 -> 35.289429 | O12: 0 | P12: 30 | Q12: 0.05 | R12: 0.01 | S12: 0.01 | T12: =Capacity!B9*1000 -> 0 | U12: =Capacity!AR9*1000 -> 0 | V12: =Capacity!D9*1000 -> 0 | W12: =Capacity!X9*1000 -> 0 | Z12: 5 | AA12: 0.105 | AC12: =1/K12/(1-Q12) -> 1.0526316 | AF12: 0 | AG12: =Z12*Conversions!$D$4 -> 6.1945879 | AH12: =M12-AG12 -> 29.094841 | AI12: =P12 -> 30 | AJ12: =AA12/(1-(1+AA12)^-AI12) -> 0.11052848 | AK12: =AH12/AJ12 -> 263.23388 | AL12: =T12-U12 -> 0
B13: EG_LH | C13: NR | D13: HydroRes | E13: conventional_hydroelectric | F13: INDIA | G13: MW | H13: HYDEL | I13: ELECTRICITY | J13: 8760 | K13: 1 | L13: 1 | M13: =19631.8145207228/1000 -> 19.631815 | N13: =19631.81452/1000 -> 19.631815 | O13: 0 | P13: 40 | Q13: 0.006 | R13: 1 | S13: 1 | T13: =Capacity!B10*1000 -> 20527.317 | U13: =Capacity!AR10*1000 -> 0 | V13: =Capacity!D10*1000 -> 0 | W13: =Capacity!X10*1000 -> 0 | Z13: 4.4 | AA13: 0.105 | AD13: =K13-Q13 -> 0.994 | AF13: 0 | AG13: =Z13*Conversions!$D$4 -> 5.4512374 | AH13: =M13-AG13 -> 14.180577 | AI13: =P13 -> 40 | AJ13: =AA13/(1-(1+AA13)^-AI13) -> 0.10697141 | AK13: =AH13/AJ13 -> 132.56418 | AL13: =T13-U13 -> 20527.317
B14: EG_SH | C14: NR | D14: HydroRes | E14: conventional_hydroelectric_small | F14: INDIA | G14: MW | H14: HYDEL | I14: ELECTRICITY | J14: 8760 | K14: 1 | L14: 1 | M14: =11825.3487554956/1000 -> 11.825349 | N14: =11825.34876/1000 -> 11.825349 | O14: 0 | P14: 35 | Q14: 0.01 | R14: 1 | S14: 1 | T14: =Capacity!B11*1000 -> 1698.75 | U14: =Capacity!AR11*1000 -> 0 | V14: =Capacity!D11*1000 -> 28 | W14: =Capacity!X11*1000 -> 28 | Z14: =2.4 -> 2.4 | AA14: 0.0835 | AD14: =K14-Q14 -> 0.99 | AF14: 0 | AG14: =Z14*Conversions!$D$4 -> 2.9734022 | AH14: =M14-AG14 -> 8.8519466 | AI14: =P14 -> 35 | AJ14: =AA14/(1-(1+AA14)^-AI14) -> 0.088866959 | AK14: =AH14/AJ14 -> 99.608974 | AL14: =T14-U14 -> 1698.75
B15: EG_BIOMASS | C15: NR | D15: ThermalPower | E15: biomass | F15: INDIA | G15: MW | H15: BIOMASS_WASTE | I15: ELECTRICITY | J15: 8760 | K15: 0.2388459 | L15: 1 | M15: =7713.45723965334/1000 -> 7.7134572 | N15: =7713.45724/1000 -> 7.7134572 | O15: 0 | P15: 20 | Q15: 0.1 | R15: 0.06 | S15: 0.06 | T15: =Capacity!B12*1000 -> 3357.15 | U15: =Capacity!AR12*1000 -> 0 | V15: =Capacity!D12*1000 -> 143 | W15: =Capacity!X12*1000 -> 143 | X15: =CarriersTech_characteristics!$G$7 -> 13.648968 | Y15: =CarriersTech_characteristics!$H$5*1000 -> 1656436.7 | Z15: 1 | AA15: 0.0835 | AC15: =1/K15/(1-Q15) -> 4.652 | AE15: =Y15/(X15*Conversions!$D$2) -> 0.43689545 | AF15: 0 | AG15: =Z15*Conversions!$D$4 -> 1.2389176 | AH15: =M15-AG15 -> 6.4745397 | AI15: =P15 -> 20 | AJ15: =AA15/(1-(1+AA15)^-AI15) -> 0.1045193 | AK15: =AH15/AJ15 -> 61.945879 | AL15: =T15-U15 -> 3357.15
B16: EG_SOLARGM | C16: NR | D16: VRE | E16: solar_GM | F16: INDIA | G16: MW | H16: SUNLIGHT | I16: ELECTRICITY | J16: 8760 | K16: 1 | L16: 1 | M16: =5630.98419436319/1000 -> 5.6309842 | N16: =5439.705856/1000 -> 5.4397059 | O16: 0 | P16: 25 | Q16: 0.01 | R16: 1 | S16: 1 | T16: =Capacity!B13*1000 -> 19996.724 | U16: =Capacity!AR13*1000 -> 0 | V16: =Capacity!D13*1000 -> 4791 | W16: =Capacity!X13*1000 -> 4791 | Z16: 0.35 | AA16: 0.105 | AC16: 1 | AF16: 0 | AG16: =Z16*Conversions!$D$4 -> 0.43362115 | AH16: =M16-AG16 -> 5.197363 | AI16: =P16 -> 25 | AJ16: =AA16/(1-(1+AA16)^-AI16) -> 0.11442932 | AK16: =AH16/AJ16 -> 45.419854 | AL16: =T16-U16 -> 19996.724
B17: EG_SOLARRF | C17: NR | D17: VRE | E17: solar_RT | F17: INDIA | G17: MW | H17: SUNLIGHT | I17: ELECTRICITY | J17: 8760 | K17: 1 | L17: 1 | M17: =5542.18769541597/1000 -> 5.5421877 | N17: =5362.133837/1000 -> 5.3621338 | O17: 0 | P17: 25 | Q17: 0.006 | R17: 1 | S17: 1 | T17: =Capacity!B14*1000 -> 2666.3458 | U17: =Capacity!AR14*1000 -> 0 | V17: =Capacity!D14*1000 -> 766 | W17: =Capacity!X14*1000 -> 766 | Z17: 0.51 | AA17: 0.104 | AC17: 1 | AF17: 0 | AG17: =Z17*Conversions!$D$4 -> 0.63184797 | AH17: =M17-AG17 -> 4.9103397 | AI17: =P17 -> 25 | AJ17: =AA17/(1-(1+AA17)^-AI17) -> 0.113573 | AK17: =AH17/AJ17 -> 43.235096 | AL17: =T17-U17 -> 2666.3458
B18: EG_WINDON | C18: NR | D18: VRE | E18: onshore_wind | F18: INDIA | G18: MW | H18: WIND | I18: ELECTRICITY | J18: 8760 | K18: 1 | L18: 1 | M18: =10659.4302732183/1000 -> 10.65943 | N18: =10586.96446/1000 -> 10.586964 | O18: 0 | P18: 25 | Q18: 0.005 | R18: 1 | S18: 1 | T18: =Capacity!B15*1000 -> 5301.42 | U18: =Capacity!AR15*1000 -> 0 | V18: =Capacity!D15*1000 -> 2 | W18: =Capacity!X15*1000 -> 2 | Z18: 0.68 | AA18: 0.105 | AC18: 1 | AF18: 0 | AG18: =Z18*Conversions!$D$4 -> 0.84246396 | AH18: =M18-AG18 -> 9.8169663 | AI18: =P18 -> 25 | AJ18: =AA18/(1-(1+AA18)^-AI18) -> 0.11442932 | AK18: =AH18/AJ18 -> 85.790655 | AL18: =T18-U18 -> 5301.42
B19: EG_WINDOFF | C19: NR | D19: VRE | F19: INDIA | G19: MW | H19: WIND | I19: ELECTRICITY | J19: 8760 | K19: 1 | L19: 1 | M19: =N19 -> 34.540362 | N19: =34540.36167/1000 -> 34.540362 | O19: 0 | P19: 25 | Q19: 0.005 | R19: 1 | S19: 1 | T19: =Capacity!B16*1000 -> 0 | U19: =Capacity!AR16*1000 -> 0 | V19: =Capacity!D16*1000 -> 0 | W19: =Capacity!X16*1000 -> 0 | Z19: 6.7 | AA19: 0.112 | AC19: 1 | AF19: 0 | AG19: =Z19*Conversions!$D$4 -> 8.3007478 | AH19: =M19-AG19 -> 26.239614 | AI19: =P19 -> 25 | AJ19: =AA19/(1-(1+AA19)^-AI19) -> 0.12047789 | AK19: =AH19/AJ19 -> 217.7961 | AL19: =T19-U19 -> 0
B20: EG_COAL | C20: NER | D20: ThermalPower | E20: coal | F20: INDIA | G20: MW | H20: THERMAL_COAL | I20: ELECTRICITY | J20: 8760 | K20: 0.3809682 | L20: 0.85 | M20: =26148.8463751508/1000 -> 26.148846 | N20: =13721.03129/1000 -> 13.721031 | O20: 133.52302 | P20: 40 | Q20: 0.066 | R20: 0.3 | S20: 0.3 | T20: =Capacity!B19*1000 -> 1010.9297 | U20: =Capacity!AR19*1000 -> 0 | V20: =Capacity!D19*1000 -> 0 | W20: =Capacity!X19*1000 -> 0 | X20: =CarriersTech_characteristics!$G$2 -> 17.207188 | Y20: =CarriersTech_characteristics!$H$28*1000 -> 1942097.6 | Z20: 3 | AA20: 0.105 | AC20: =1/K20/(1-Q20) -> 2.8103758 | AE20: =Y20/(X20*Conversions!$D$2) -> 0.40631575 | AF20: =O20/CarriersTech_characteristics!$G$2/Conversions!$D$2*AC20 -> 7.850786e-05 | AG20: =Z20*Conversions!$D$4 -> 3.7167527 | AH20: =M20-AG20 -> 22.432094 | AI20: =P20 -> 40 | AJ20: =AA20/(1-(1+AA20)^-AI20) -> 0.10697141 | AK20: =AH20/AJ20 -> 209.70177 | AL20: =T20-U20 -> 1010.9297
B21: EG_CCGT | C21: NER | D21: ThermalPower | E21: NG_CCGT | F21: INDIA | G21: MW | H21: NATGAS | I21: ELECTRICITY | J21: 8760 | K21: 0.40444272 | L21: 0.85 | M21: =8512.22780274884/1000 -> 8.5122278 | N21: =8512.227803/1000 -> 8.5122278 | O21: 0 | P21: 25 | Q21: 0.02 | R21: 0.9 | S21: 0.9 | T21: =Capacity!B20*1000 -> 2002.4569 | U21: =Capacity!AR20*1000 -> 0 | V21: =Capacity!D20*1000 -> 0 | W21: =Capacity!X20*1000 -> 0 | X21: =CarriersTech_characteristics!$G$3 -> 37.6812 | Y21: =CarriersTech_characteristics!$H$3*1000 -> 3025024.5 | Z21: 2.9 | AA21: 0.105 | AC21: =1/K21/(1-Q21) -> 2.522998 | AE21: =(Y21*Conversions!$D$3)/(X21*Conversions!$D$2) -> 0.23958587 | AF21: 0 | AG21: =Z21*Conversions!$D$4 -> 3.592861 | AH21: =M21-AG21 -> 4.9193668 | AI21: =P21 -> 25 | AJ21: =AA21/(1-(1+AA21)^-AI21) -> 0.11442932 | AK21: =AH21/AJ21 -> 42.99044 | AL21: =T21-U21 -> 2002.4569
B22: EG_OCGT | C22: NER | D22: ThermalPower | F22: INDIA | G22: MW | H22: NATGAS | I22: ELECTRICITY | J22: 8760 | K22: 0.28070163 | L22: 0.85 | M22: =6679.75064927145/1000 -> 6.6797506 | N22: =6679.750649/1000 -> 6.6797506 | O22: 0 | P22: 25 | Q22: 0.01 | R22: 1 | S22: 1 | T22: =Capacity!B21*1000 -> 0 | U22: =Capacity!AR21*1000 -> 0 | V22: =Capacity!D21*1000 -> 0 | W22: =Capacity!X21*1000 -> 0 | X22: =CarriersTech_characteristics!$G$3 -> 37.6812 | Y22: =CarriersTech_characteristics!$H$3*1000 -> 3025024.5 | Z22: 0.7 | AA22: 0.105 | AC22: =1/K22/(1-Q22) -> 3.5984865 | AE22: =(Y22*Conversions!$D$3)/(X22*Conversions!$D$2) -> 0.23958587 | AF22: 0 | AG22: =Z22*Conversions!$D$4 -> 0.86724231 | AH22: =M22-AG22 -> 5.8125083 | AI22: =P22 -> 25 | AJ22: =AA22/(1-(1+AA22)^-AI22) -> 0.11442932 | AK22: =AH22/AJ22 -> 50.795621 | AL22: =T22-U22 -> 0
B23: EG_PHWR | C23: NER | D23: ThermalPower | E23: nuclear_PHWR | F23: INDIA | G23: MW | H23: ATOMIC | I23: ELECTRICITY | J23: 8760 | K23: 1 | L23: 0.70916667 | M23: =20833.2103478327/1000 -> 20.83321 | N23: =20833.21035/1000 -> 20.83321 | O23: 0 | P23: 40 | Q23: 0.1078 | R23: 0.01 | S23: 0.01 | T23: =Capacity!B22*1000 -> 0 | U23: =Capacity!AR22*1000 -> 0 | V23: =Capacity!D22*1000 -> 0 | W23: =Capacity!X22*1000 -> 0 | Z23: 4.3 | AA23: 0.105 | AC23: =1/K23/(1-Q23) -> 1.1208249 | AF23: 0 | AG23: =Z23*Conversions!$D$4 -> 5.3273456 | AH23: =M23-AG23 -> 15.505865 | AI23: =P23 -> 40 | AJ23: =AA23/(1-(1+AA23)^-AI23) -> 0.10697141 | AK23: =AH23/AJ23 -> 144.95336 | AL23: =T23-U23 -> 0
B24: EG_SMR | C24: NER | D24: ThermalPower | F24: INDIA | G24: MW | H24: ATOMIC | I24: ELECTRICITY | J24: 8760 | K24: 1 | L24: 0.70916667 | M24: =N24 -> 35.289429 | N24: =35289.42939/1000 -> 35.289429 | O24: 0 | P24: 30 | Q24: 0.05 | R24: 0.01 | S24: 0.01 | T24: =Capacity!B23*1000 -> 0 | U24: =Capacity!AR23*1000 -> 0 | V24: =Capacity!D23*1000 -> 0 | W24: =Capacity!X23*1000 -> 0 | Z24: 5 | AA24: 0.105 | AC24: =1/K24/(1-Q24) -> 1.0526316 | AF24: 0 | AG24: =Z24*Conversions!$D$4 -> 6.1945879 | AH24: =M24-AG24 -> 29.094841 | AI24: =P24 -> 30 | AJ24: =AA24/(1-(1+AA24)^-AI24) -> 0.11052848 | AK24: =AH24/AJ24 -> 263.23388 | AL24: =T24-U24 -> 0
B25: EG_LH | C25: NER | D25: HydroRes | E25: conventional_hydroelectric | F25: INDIA | G25: MW | H25: HYDEL | I25: ELECTRICITY | J25: 8760 | K25: 1 | L25: 1 | M25: =19631.8145207228/1000 -> 19.631815 | N25: =19631.81452/1000 -> 19.631815 | O25: 0 | P25: 40 | Q25: 0.006 | R25: 1 | S25: 1 | T25: =Capacity!B24*1000 -> 1842.8253 | U25: =Capacity!AR24*1000 -> 0 | V25: =Capacity!D24*1000 -> 0 | W25: =Capacity!X24*1000 -> 0 | Z25: 4.4 | AA25: 0.105 | AD25: =K25-Q25 -> 0.994 | AF25: 0 | AG25: =Z25*Conversions!$D$4 -> 5.4512374 | AH25: =M25-AG25 -> 14.180577 | AI25: =P25 -> 40 | AJ25: =AA25/(1-(1+AA25)^-AI25) -> 0.10697141 | AK25: =AH25/AJ25 -> 132.56418 | AL25: =T25-U25 -> 1842.8253
B26: EG_SH | C26: NER | D26: HydroRes | E26: conventional_hydroelectric_small | F26: INDIA | G26: MW | H26: HYDEL | I26: ELECTRICITY | J26: 8760 | K26: 1 | L26: 1 | M26: =11825.3487554956/1000 -> 11.825349 | N26: =11825.34876/1000 -> 11.825349 | O26: 0 | P26: 35 | Q26: 0.01 | R26: 1 | S26: 1 | T26: =Capacity!B25*1000 -> 299.35 | U26: =Capacity!AR25*1000 -> 0 | V26: =Capacity!D25*1000 -> 10 | W26: =Capacity!X25*1000 -> 10 | Z26: =2.4 -> 2.4 | AA26: 0.0835 | AD26: =K26-Q26 -> 0.99 | AF26: 0 | AG26: =Z26*Conversions!$D$4 -> 2.9734022 | AH26: =M26-AG26 -> 8.8519466 | AI26: =P26 -> 35 | AJ26: =AA26/(1-(1+AA26)^-AI26) -> 0.088866959 | AK26: =AH26/AJ26 -> 99.608974 | AL26: =T26-U26 -> 299.35
B27: EG_BIOMASS | C27: NER | D27: ThermalPower | E27: biomass | F27: INDIA | G27: MW | H27: BIOMASS_WASTE | I27: ELECTRICITY | J27: 8760 | K27: 0.2388459 | L27: 1 | M27: =7713.45723965334/1000 -> 7.7134572 | N27: =7713.45724/1000 -> 7.7134572 | O27: 0 | P27: 20 | Q27: 0.1 | R27: 0.06 | S27: 0.06 | T27: =Capacity!B26*1000 -> 15.8 | U27: =Capacity!AR26*1000 -> 0 | V27: =Capacity!D26*1000 -> 1 | W27: =Capacity!X26*1000 -> 1 | X27: =CarriersTech_characteristics!$G$7 -> 13.648968 | Y27: =CarriersTech_characteristics!$H$5*1000 -> 1656436.7 | Z27: 1 | AA27: 0.0835 | AC27: =1/K27/(1-Q27) -> 4.652 | AE27: =Y27/(X27*Conversions!$D$2) -> 0.43689545 | AF27: 0 | AG27: =Z27*Conversions!$D$4 -> 1.2389176 | AH27: =M27-AG27 -> 6.4745397 | AI27: =P27 -> 20 | AJ27: =AA27/(1-(1+AA27)^-AI27) -> 0.1045193 | AK27: =AH27/AJ27 -> 61.945879 | AL27: =T27-U27 -> 15.8
B28: EG_SOLARGM | C28: NER | D28: VRE | E28: solar_GM | F28: INDIA | G28: MW | H28: SUNLIGHT | I28: ELECTRICITY | J28: 8760 | K28: 1 | L28: 1 | M28: =5630.98419436319/1000 -> 5.6309842 | N28: =5439.705856/1000 -> 5.4397059 | O28: 0 | P28: 25 | Q28: 0.01 | R28: 1 | S28: 1 | T28: =Capacity!B27*1000 -> 171.48962 | U28: =Capacity!AR27*1000 -> 0 | V28: =Capacity!D27*1000 -> 7 | W28: =Capacity!X27*1000 -> 7 | Z28: 0.35 | AA28: 0.105 | AC28: 1 | AF28: 0 | AG28: =Z28*Conversions!$D$4 -> 0.43362115 | AH28: =M28-AG28 -> 5.197363 | AI28: =P28 -> 25 | AJ28: =AA28/(1-(1+AA28)^-AI28) -> 0.11442932 | AK28: =AH28/AJ28 -> 45.419854 | AL28: =T28-U28 -> 171.48962
B29: EG_SOLARRF | C29: NER | D29: VRE | E29: solar_RT | F29: INDIA | G29: MW | H29: SUNLIGHT | I29: ELECTRICITY | J29: 8760 | K29: 1 | L29: 1 | M29: =5542.18769541597/1000 -> 5.5421877 | N29: =5362.133837/1000 -> 5.3621338 | O29: 0 | P29: 25 | Q29: 0.006 | R29: 1 | S29: 1 | T29: =Capacity!B28*1000 -> 67.610378 | U29: =Capacity!AR28*1000 -> 0 | V29: =Capacity!D28*1000 -> 8 | W29: =Capacity!X28*1000 -> 8 | Z29: 0.51 | AA29: 0.104 | AC29: 1 | AF29: 0 | AG29: =Z29*Conversions!$D$4 -> 0.63184797 | AH29: =M29-AG29 -> 4.9103397 | AI29: =P29 -> 25 | AJ29: =AA29/(1-(1+AA29)^-AI29) -> 0.113573 | AK29: =AH29/AJ29 -> 43.235096 | AL29: =T29-U29 -> 67.610378
B30: EG_WINDON | C30: NER | D30: VRE | E30: onshore_wind | F30: INDIA | G30: MW | H30: WIND | I30: ELECTRICITY | J30: 8760 | K30: 1 | L30: 1 | M30: =10659.4302732183/1000 -> 10.65943 | N30: =10586.96446/1000 -> 10.586964 | O30: 0 | P30: 25 | Q30: 0.005 | R30: 1 | S30: 1 | T30: =Capacity!B29*1000 -> 0 | U30: =Capacity!AR29*1000 -> 0 | V30: =Capacity!D29*1000 -> 0 | W30: =Capacity!X29*1000 -> 0 | Z30: 0.68 | AA30: 0.105 | AC30: 1 | AF30: 0 | AG30: =Z30*Conversions!$D$4 -> 0.84246396 | AH30: =M30-AG30 -> 9.8169663 | AI30: =P30 -> 25 | AJ30: =AA30/(1-(1+AA30)^-AI30) -> 0.11442932 | AK30: =AH30/AJ30 -> 85.790655 | AL30: =T30-U30 -> 0
B31: EG_WINDOFF | C31: NER | D31: VRE | F31: INDIA | G31: MW | H31: WIND | I31: ELECTRICITY | J31: 8760 | K31: 1 | L31: 1 | M31: =N31 -> 34.540362 | N31: =34540.36167/1000 -> 34.540362 | O31: 0 | P31: 25 | Q31: 0.005 | R31: 1 | S31: 1 | T31: =Capacity!B30*1000 -> 0 | U31: =Capacity!AR30*1000 -> 0 | V31: =Capacity!D30*1000 -> 0 | W31: =Capacity!X30*1000 -> 0 | Z31: 6.7 | AA31: 0.112 | AC31: 1 | AF31: 0 | AG31: =Z31*Conversions!$D$4 -> 8.3007478 | AH31: =M31-AG31 -> 26.239614 | AI31: =P31 -> 25 | AJ31: =AA31/(1-(1+AA31)^-AI31) -> 0.12047789 | AK31: =AH31/AJ31 -> 217.7961 | AL31: =T31-U31 -> 0
B32: EG_COAL | C32: ER | D32: ThermalPower | E32: coal | F32: INDIA | G32: MW | H32: THERMAL_COAL | I32: ELECTRICITY | J32: 8760 | K32: 0.3809682 | L32: 0.85 | M32: =6514.90571684157/1000 -> 6.5149057 | N32: =13721.03129/1000 -> 13.721031 | O32: 133.52302 | P32: 40 | Q32: 0.066 | R32: 0.3 | S32: 0.3 | T32: =Capacity!B33*1000 -> 41729.904 | U32: =Capacity!AR33*1000 -> 0 | V32: =Capacity!D33*1000 -> 0 | W32: =Capacity!X33*1000 -> 0 | X32: =CarriersTech_characteristics!$G$2 -> 17.207188 | Y32: =CarriersTech_characteristics!$H$28*1000 -> 1942097.6 | Z32: 3 | AA32: 0.105 | AC32: =1/K32/(1-Q32) -> 2.8103758 | AE32: =Y32/(X32*Conversions!$D$2) -> 0.40631575 | AF32: =O32/CarriersTech_characteristics!$G$2/Conversions!$D$2*AC32 -> 7.850786e-05 | AG32: =Z32*Conversions!$D$4 -> 3.7167527 | AH32: =M32-AG32 -> 2.798153 | AI32: =P32 -> 40 | AJ32: =AA32/(1-(1+AA32)^-AI32) -> 0.10697141 | AK32: =AH32/AJ32 -> 26.157952 | AL32: =T32-U32 -> 41729.904
B33: EG_CCGT | C33: ER | D33: ThermalPower | E33: NG_CCGT | F33: INDIA | G33: MW | H33: NATGAS | I33: ELECTRICITY | J33: 8760 | K33: 0.40444272 | L33: 0.85 | M33: =8512.22780274884/1000 -> 8.5122278 | N33: =8512.227803/1000 -> 8.5122278 | O33: 0 | P33: 25 | Q33: 0.02 | R33: 0.9 | S33: 0.9 | T33: =Capacity!B34*1000 -> 770.80433 | U33: =Capacity!AR34*1000 -> 0 | V33: =Capacity!D34*1000 -> 0 | W33: =Capacity!X34*1000 -> 0 | X33: =CarriersTech_characteristics!$G$3 -> 37.6812 | Y33: =CarriersTech_characteristics!$H$3*1000 -> 3025024.5 | Z33: 2.9 | AA33: 0.105 | AC33: =1/K33/(1-Q33) -> 2.522998 | AE33: =(Y33*Conversions!$D$3)/(X33*Conversions!$D$2) -> 0.23958587 | AF33: 0 | AG33: =Z33*Conversions!$D$4 -> 3.592861 | AH33: =M33-AG33 -> 4.9193668 | AI33: =P33 -> 25 | AJ33: =AA33/(1-(1+AA33)^-AI33) -> 0.11442932 | AK33: =AH33/AJ33 -> 42.99044 | AL33: =T33-U33 -> 770.80433
B34: EG_OCGT | C34: ER | D34: ThermalPower | F34: INDIA | G34: MW | H34: NATGAS | I34: ELECTRICITY | J34: 8760 | K34: 0.28070163 | L34: 0.85 | M34: =6679.75064927145/1000 -> 6.6797506 | N34: =6679.750649/1000 -> 6.6797506 | O34: 0 | P34: 25 | Q34: 0.01 | R34: 1 | S34: 1 | T34: =Capacity!B35*1000 -> 0 | U34: =Capacity!AR35*1000 -> 0 | V34: =Capacity!D35*1000 -> 0 | W34: =Capacity!X35*1000 -> 0 | X34: =CarriersTech_characteristics!$G$3 -> 37.6812 | Y34: =CarriersTech_characteristics!$H$3*1000 -> 3025024.5 | Z34: 0.7 | AA34: 0.105 | AC34: =1/K34/(1-Q34) -> 3.5984865 | AE34: =(Y34*Conversions!$D$3)/(X34*Conversions!$D$2) -> 0.23958587 | AF34: 0 | AG34: =Z34*Conversions!$D$4 -> 0.86724231 | AH34: =M34-AG34 -> 5.8125083 | AI34: =P34 -> 25 | AJ34: =AA34/(1-(1+AA34)^-AI34) -> 0.11442932 | AK34: =AH34/AJ34 -> 50.795621 | AL34: =T34-U34 -> 0
B35: EG_PHWR | C35: ER | D35: ThermalPower | E35: nuclear_PHWR | F35: INDIA | G35: MW | H35: ATOMIC | I35: ELECTRICITY | J35: 8760 | K35: 1 | L35: 0.70916667 | M35: =20833.2103478327/1000 -> 20.83321 | N35: =20833.21035/1000 -> 20.83321 | O35: 0 | P35: 40 | Q35: 0.1078 | R35: 0.01 | S35: 0.01 | T35: =Capacity!B36*1000 -> 0 | U35: =Capacity!AR36*1000 -> 0 | V35: =Capacity!D36*1000 -> 0 | W35: =Capacity!X36*1000 -> 0 | Z35: 4.3 | AA35: 0.105 | AC35: =1/K35/(1-Q35) -> 1.1208249 | AF35: 0 | AG35: =Z35*Conversions!$D$4 -> 5.3273456 | AH35: =M35-AG35 -> 15.505865 | AI35: =P35 -> 40 | AJ35: =AA35/(1-(1+AA35)^-AI35) -> 0.10697141 | AK35: =AH35/AJ35 -> 144.95336 | AL35: =T35-U35 -> 0
B36: EG_SMR | C36: ER | D36: ThermalPower | F36: INDIA | G36: MW | H36: ATOMIC | I36: ELECTRICITY | J36: 8760 | K36: 1 | L36: 0.70916667 | M36: =N36 -> 35.289429 | N36: =35289.42939/1000 -> 35.289429 | O36: 0 | P36: 30 | Q36: 0.05 | R36: 0.01 | S36: 0.01 | T36: =Capacity!B37*1000 -> 0 | U36: =Capacity!AR37*1000 -> 0 | V36: =Capacity!D37*1000 -> 0 | W36: =Capacity!X37*1000 -> 0 | Z36: 5 | AA36: 0.105 | AC36: =1/K36/(1-Q36) -> 1.0526316 | AF36: 0 | AG36: =Z36*Conversions!$D$4 -> 6.1945879 | AH36: =M36-AG36 -> 29.094841 | AI36: =P36 -> 30 | AJ36: =AA36/(1-(1+AA36)^-AI36) -> 0.11052848 | AK36: =AH36/AJ36 -> 263.23388 | AL36: =T36-U36 -> 0
B37: EG_LH | C37: ER | D37: HydroRes | E37: conventional_hydroelectric | F37: INDIA | G37: MW | H37: HYDEL | I37: ELECTRICITY | J37: 8760 | K37: 1 | L37: 1 | M37: =19631.8145207228/1000 -> 19.631815 | N37: =19631.81452/1000 -> 19.631815 | O37: 0 | P37: 40 | Q37: 0.006 | R37: 1 | S37: 1 | T37: =Capacity!B38*1000 -> 4198.8603 | U37: =Capacity!AR38*1000 -> 0 | V37: =Capacity!D38*1000 -> 0 | W37: =Capacity!X38*1000 -> 0 | Z37: 4.4 | AA37: 0.105 | AD37: =K37-Q37 -> 0.994 | AF37: 0 | AG37: =Z37*Conversions!$D$4 -> 5.4512374 | AH37: =M37-AG37 -> 14.180577 | AI37: =P37 -> 40 | AJ37: =AA37/(1-(1+AA37)^-AI37) -> 0.10697141 | AK37: =AH37/AJ37 -> 132.56418 | AL37: =T37-U37 -> 4198.8603
B38: EG_SH | C38: ER | D38: HydroRes | E38: conventional_hydroelectric_small | F38: INDIA | G38: MW | H38: HYDEL | I38: ELECTRICITY | J38: 8760 | K38: 1 | L38: 1 | M38: =11825.3487554956/1000 -> 11.825349 | N38: =11825.34876/1000 -> 11.825349 | O38: 0 | P38: 35 | Q38: 0.01 | R38: 1 | S38: 1 | T38: =Capacity!B39*1000 -> 343.99 | U38: =Capacity!AR39*1000 -> 0 | V38: =Capacity!D39*1000 -> 6 | W38: =Capacity!X39*1000 -> 6 | Z38: =2.4 -> 2.4 | AA38: 0.0835 | AD38: =K38-Q38 -> 0.99 | AF38: 0 | AG38: =Z38*Conversions!$D$4 -> 2.9734022 | AH38: =M38-AG38 -> 8.8519466 | AI38: =P38 -> 35 | AJ38: =AA38/(1-(1+AA38)^-AI38) -> 0.088866959 | AK38: =AH38/AJ38 -> 99.608974 | AL38: =T38-U38 -> 343.99
B39: EG_BIOMASS | C39: ER | D39: ThermalPower | E39: biomass | F39: INDIA | G39: MW | H39: BIOMASS_WASTE | I39: ELECTRICITY | J39: 8760 | K39: 0.2388459 | L39: 1 | M39: =7713.45723965334/1000 -> 7.7134572 | N39: =7713.45724/1000 -> 7.7134572 | O39: 0 | P39: 20 | Q39: 0.1 | R39: 0.06 | S39: 0.06 | T39: =Capacity!B40*1000 -> 560.64 | U39: =Capacity!AR40*1000 -> 0 | V39: =Capacity!D40*1000 -> 23 | W39: =Capacity!X40*1000 -> 23 | X39: =CarriersTech_characteristics!$G$7 -> 13.648968 | Y39: =CarriersTech_characteristics!$H$5*1000 -> 1656436.7 | Z39: 1 | AA39: 0.0835 | AC39: =1/K39/(1-Q39) -> 4.652 | AE39: =Y39/(X39*Conversions!$D$2) -> 0.43689545 | AF39: 0 | AG39: =Z39*Conversions!$D$4 -> 1.2389176 | AH39: =M39-AG39 -> 6.4745397 | AI39: =P39 -> 20 | AJ39: =AA39/(1-(1+AA39)^-AI39) -> 0.1045193 | AK39: =AH39/AJ39 -> 61.945879 | AL39: =T39-U39 -> 560.64
B40: EG_SOLARGM | C40: ER | D40: VRE | E40: solar_GM | F40: INDIA | G40: MW | H40: SUNLIGHT | I40: ELECTRICITY | J40: 8760 | K40: 1 | L40: 1 | M40: =5630.98419436319/1000 -> 5.6309842 | N40: =5439.705856/1000 -> 5.4397059 | O40: 0 | P40: 25 | Q40: 0.01 | R40: 1 | S40: 1 | T40: =Capacity!B41*1000 -> 847.7259 | U40: =Capacity!AR41*1000 -> 0 | V40: =Capacity!D41*1000 -> 40 | W40: =Capacity!X41*1000 -> 40 | Z40: 0.35 | AA40: 0.105 | AC40: 1 | AF40: 0 | AG40: =Z40*Conversions!$D$4 -> 0.43362115 | AH40: =M40-AG40 -> 5.197363 | AI40: =P40 -> 25 | AJ40: =AA40/(1-(1+AA40)^-AI40) -> 0.11442932 | AK40: =AH40/AJ40 -> 45.419854 | AL40: =T40-U40 -> 847.7259
...

Sheet assets_stor_p1
A1: Source::File | G1: PIER::EnergyConvTechnologies.csv | H1: PIER::EnergyStorTechnologies.csv | I1: PIER::EnergyStorTechnologies.csv | J1: PIER::EnergyStorTechnologies.csv | K1: PIER::EnergyStorTechnologies.csv | L1: PIER::EnergyStorTechnologies.csv | M1: PIER2.0::EST_DeratingDepthOfDischarge.csv | N1: PIER2.0::EST_DeratingDepthOfDischarge.csv | O1: PIER2.0::EST_EfficiencyCost.csv | P1: PIER2.0::EST_Lifetime.csv or EST_LegacyDetails.csv | Q1: PIER2.0::EST_Lifetime.csv or EST_LegacyDetails.csv | R1: PIER2.0::EST_EfficiencyCost.csv | S1: PIER2.0::ECT_LegacyDetails.csv | T1: PIER2.0::EST_CapAddBounds.csv | U1: PIER2.0::EST_CapAddBounds.csv | V1: PIER2.0::EST_Parameters.xlsx | W1: PIER2.0::EST_Parameters.xlsx
A2: PIER2.0 var name | B2: EnergyConvTech | C2: SubGeography1 | F2: ModelGeography | G2: CapacityUnit | H2: StoredEC | I2: DomOrImp | J2: MaxChargeRate | K2: MaxDischargeRate | L2: StorPeriodicity | M2: CapacityDerating | N2: DepthOfDischarge | O2: Efficiency | P2: LifetimeYears | Q2: LifetimeCycles | R2: FixedCost | S2: LegacyCapacity | T2: MinCapacity | U2: MaxCapacity
A3: Variable | J3: a | K3: b | M3: c | N3: d | O3: e | P3: f | Q3: g | R3: h | S3: i | T3: j | U3: k | V3: l | W3: m | Y3: aa | Z3: bb | AA3: dd | AB3: ee | AC3: ff
A4: description | C4: model geography | G4: all units in macro are given in the selected value | H4: energy carrier | O4: overall efficiency | P4: lifetime of asset in years | Q4: lifetime of asset in cycles | R4: annuity on new capacity | S4: legacy/existing | T4: pipeline builds | U4: maximum additions | V4: given Fixed O&M (PIER or assumed), adjusted to 2024Rs from 2020Rs | W4: given discount rate from PIER2.0 workbook, No adjustment made | AA4: For existing infrastructure this is half operational lifetime, rounded to integer as Macro will fail if given decimal | AB4: CRF
A5: Equation to Macro var | G5: given / 1000 | H5: given | J5: given | K5: given | M5: given | N5: given | O5: given | P5: given | Q5: given | R5: given/1000 | S5: = given*1000 | T5: = given*1000 | U5: = given*1000 | W5: = given | Y5: = sqrt ( e ) | Z5: = sqrt ( e ) | AA5: = round ( f / 2 , 0) | AB5: = q / ( 1-(1+q)^(-gg)) | AC5: = ff / hh
A6: Macro variable | C6: location | D6: type | E6: id | J6: discharge_max_flow_fraction | P6: lifetime of asset | R6: annualized_investment_cost | T6: min_capcity | U6: max_capacity | W6: wacc | Y6: discharge_efficienc | Z6: charge_efficiency | AA6: capital_recovery_period | AC6: investment_cost
A7: Unit | J7: % | K7: % | M7: % | N7: fraction of capacity | O7: % | P7: years | Q7: cycles | R7: million Rs2024/MW | S7: MW | T7: MW | U7: MW | V7: million 2020Rs/year | W7: % | Y7: % | Z7: % | AA7: years | AC7: million 2024Rs
