Workbook
Name Escalation_rate: [1]!COAL_TransitCost_Esc[#All]

Sheet PIER_CHK
B1: Macro | C1: Macro | E1: PIERumi | F1: PIERumi | G1: EF (MT/TWh) | I1: Emission Rate derived from PIER
B2: Generation_TWh | C2: Emissions_MT | D2: EF (MT/TWh) | E2: Generation_TWh | F2: Emissions_MT
A3: Coal | B3: 1176 | C3: 1848 | D3: =C3/B3 -> 1.5714286 | E3: 1362 | F3: 1597 | G3: =F3/E3 -> 1.1725404 | I3: =G3/ECT_EfficiencyCostMaxAnnualUF!Y6 -> 0.41721836 | J3: =I3*2.62 -> 1.0931121
A4: NG | B4: 15 | C4: 0.0009 | D4: =C4/B4 -> 6e-05 | E4: 33 | F4: 0.021 | G4: =F4/E4 -> 0.00063636364 | I4: =G4/ECT_EfficiencyCostMaxAnnualUF!Y12*1000 -> 0.25222519
D6: =D3/2.62 -> 0.5997819
N7: Differences in generation 2024 | O7: PIER | P7: Macro | Q7: %diff Macro2PIER | R7: Need
N8: Coal | O8: 1362 | P8: 1314 | Q8: =P8/O8 -> 0.96475771 | R8: None. will change if change other
N9: Nuclear | O9: 52 | P9: 59 | Q9: =P9/O9 -> 1.1346154 | R9: to reduce
N10: Hydro Large | O10: 147 | P10: 155 | Q10: =P10/O10 -> 1.0544218 | R10: to reduce
N11: Hydro Small | O11: 10 | P11: 11 | Q11: =P11/O11 -> 1.1 | R11: to reduce
N12: Natural Gas | O12: 33 | P12: 39 | Q12: =P12/O12 -> 1.1818182 | R12: None. will change if change other
N13: Wind | O13: 84 | P13: 117 | Q13: =P13/O13 -> 1.3928571 | R13: to reduce
N14: Solar Utility | O14: 109 | P14: 123 | Q14: =P14/O14 -> 1.1284404 | R14: to reduce
N15: Solar Rooftop | O15: 17 | P15: 23 | Q15: =P15/O15 -> 1.3529412 | R15: to reduce

Sheet ECT_EfficiencyCostMaxAnnualUF
A1: Source
A2: Variable | H2: a | I2: b | J2: c | K2: d | L2: e | M2: f | N2: g | O2: h | P2: j | Q2: k | R2: m | S2: n | Y2: aa | Z2: bb | AA2: cc | AB2: dd | AC2: ee
A3: Equation | H3: given | I3: given | J3: given | K3: given | L3: given | M3: given | N3: given | O3: given | P3: given *1000 | Q3: given *1000 | R3: given | Y3: = 1/a
A4: EnergyConvTech | B4: ModelGeography | C4: CapacityUnit | D4: InputEC | E4: OutputDEC | F4: AnnualOutputPerUnitCapacity | G4: SubGeography1 | H4: ConvEff | I4: Lifetime | J4: SelfCons | K4: MaxRampUpRate | L4: MaxRampDownRate | M4: MaxAnnualUF | N4: MW 2023 | O4: MW 2024 | P4: Legacy Fixed Cost (million Rs/MW) | Q4: New Fixed Cost (anualized per MW) | R4: VarCost (million Rs / Mt) | S4: VarCost million Rs/MWh-elec | T4: electrticity consumption | U4: PhysicalUnit | V4: EnergyUnit | W4: DomEnergyDensity | X4: DomEmissionFactor | Y4: Fuel Use per MWh | Z4: tCO2/MT | AA4: MWh/MT | AB4: tCO2/MWh input | AC4: emission_rate Macro | AG4: Fixed O&M (PIER or assumed) | AH4: adj | AI4: AIC(no fO&M) | AJ4: CRP | AK4: wacc | AL4: CRF | AM4: CAPEX
A5: Unit | H5: % | I5: years | J5: %
A6: EG_COAL | B6: INDIA | C6: GW | D6: THERMAL_COAL | E6: ELECTRICITY | F6: 8760 | G6: NR | H6: 0.3809682 | I6: 40 | J6: 0.066 | K6: 0.3 | L6: 0.3 | M6: 0.85 | P6: =11751.5992748699 -> 11751.599 | Q6: =13721031.29/1000 -> 13721.031 | R6: 133.52302 | S6: =R6/Carriers!$G$3/Conversions!$D$2*Y6 -> 7.850786e-05 | T6: =J6/Y6 -> 0.023484404 | U6: MT | V6: PJ | W6: 17.207188 | X6: 1871.8737 | Y6: =1/H6/(1-J6) -> 2.8103758 | Z6: =Carriers!H$28*1000 -> 1942097.6 | AA6: =Carriers!G$3*277800 -> 4780156.7 | AB6: =Z6/AA6 -> 0.40628325 | AC6: =AB6*Y6 -> 1.1418086 | AD6: COAL | AE6: NR | AF6: =11751.5992748699 -> 11751.599 | AG6: 3 | AH6: =AG6*Conversions!$D$5*1000 -> 3716.7527 | AI6: =AF6-AH6 -> 8034.8465 | AJ6: 10 | AK6: 0.105 | AL6: =AK6/(1-(1+AK6)^-AJ6) -> 0.16625732 | AM6: =AI6/AL6 -> 48327.776
A7: EG_COAL | B7: INDIA | C7: GW | D7: THERMAL_COAL | E7: ELECTRICITY | F7: 8760 | G7: NER | H7: 0.3809682 | I7: 40 | J7: 0.066 | K7: 0.3 | L7: 0.3 | M7: 0.85 | P7: =26148.8463751508 -> 26148.846 | Q7: =13721031.29/1000 -> 13721.031 | R7: 133.52302 | S7: =R7/Carriers!$G$3/Conversions!$D$2*Y7 -> 7.850786e-05 | T7: =J7/Y7 -> 0.023484404 | U7: MT | V7: PJ | W7: 17.207188 | X7: 1871.8737 | Y7: =1/H7/(1-J7) -> 2.8103758 | Z7: =Carriers!H$28*1000 -> 1942097.6 | AA7: =Carriers!G$3*277800 -> 4780156.7 | AB7: =Z7/AA7 -> 0.40628325 | AC7: =AB7 -> 0.40628325 | AD7: COAL | AE7: NER | AF7: =26148.8463751508 -> 26148.846 | AG7: 3 | AH7: =AG7*Conversions!$D$5*1000 -> 3716.7527 | AI7: =AF7-AH7 -> 22432.094 | AJ7: 10 | AK7: 0.105 | AL7: =AK7/(1-(1+AK7)^-AJ7) -> 0.16625732 | AM7: =AI7/AL7 -> 134923.95
A8: EG_COAL | B8: INDIA | C8: GW | D8: THERMAL_COAL | E8: ELECTRICITY | F8: 8760 | G8: ER | H8: 0.3809682 | I8: 40 | J8: 0.066 | K8: 0.3 | L8: 0.3 | M8: 0.85 | P8: =6514.90571684157 -> 6514.9057 | Q8: =13721031.29/1000 -> 13721.031 | R8: 133.52302 | S8: =R8/Carriers!$G$3/Conversions!$D$2*Y8 -> 7.850786e-05 | T8: =J8/Y8 -> 0.023484404 | W8: 17.207188 | X8: 1871.8737 | Y8: =1/H8/(1-J8) -> 2.8103758 | Z8: =Carriers!H$28*1000 -> 1942097.6 | AA8: =Carriers!G$3*277800 -> 4780156.7 | AB8: =Z8/AA8 -> 0.40628325 | AC8: =AB8 -> 0.40628325 | AD8: COAL | AE8: ER | AF8: =6514.90571684157 -> 6514.9057 | AG8: 3 | AH8: =AG8*Conversions!$D$5*1000 -> 3716.7527 | AI8: =AF8-AH8 -> 2798.153 | AJ8: 10 | AK8: 0.105 | AL8: =AK8/(1-(1+AK8)^-AJ8) -> 0.16625732 | AM8: =AI8/AL8 -> 16830.254
A9: EG_COAL | B9: INDIA | C9: GW | D9: THERMAL_COAL | E9: ELECTRICITY | F9: 8760 | G9: WR | H9: 0.3809682 | I9: 40 | J9: 0.066 | K9: 0.3 | L9: 0.3 | M9: 0.85 | P9: =5794.65159561365 -> 5794.6516 | Q9: =13721031.29/1000 -> 13721.031 | R9: 133.52302 | S9: =R9/Carriers!$G$3/Conversions!$D$2*Y9 -> 7.850786e-05 | T9: =J9/Y9 -> 0.023484404 | W9: 17.207188 | X9: 1871.8737 | Y9: =1/H9/(1-J9) -> 2.8103758 | Z9: =Carriers!H$28*1000 -> 1942097.6 | AA9: =Carriers!G$3*277800 -> 4780156.7 | AB9: =Z9/AA9 -> 0.40628325 | AC9: =AB9 -> 0.40628325 | AD9: COAL | AE9: WR | AF9: =5794.65159561365 -> 5794.6516 | AG9: 3 | AH9: =AG9*Conversions!$D$5*1000 -> 3716.7527 | AI9: =AF9-AH9 -> 2077.8989 | AJ9: 10 | AK9: 0.105 | AL9: =AK9/(1-(1+AK9)^-AJ9) -> 0.16625732 | AM9: =AI9/AL9 -> 12498.089
A10: EG_COAL | B10: INDIA | C10: GW | D10: THERMAL_COAL | E10: ELECTRICITY | F10: 8760 | G10: SR | H10: 0.3809682 | I10: 40 | J10: 0.066 | K10: 0.3 | L10: 0.3 | M10: 0.85 | P10: =5822.44460147077 -> 5822.4446 | Q10: =13721031.29/1000 -> 13721.031 | R10: 133.52302 | S10: =R10/Carriers!$G$3/Conversions!$D$2*Y10 -> 7.850786e-05 | T10: =J10/Y10 -> 0.023484404 | W10: 17.207188 | X10: 1871.8737 | Y10: =1/H10/(1-J10) -> 2.8103758 | Z10: =Carriers!H$28*1000 -> 1942097.6 | AA10: =Carriers!G$3*277800 -> 4780156.7 | AB10: =Z10/AA10 -> 0.40628325 | AC10: =AB10 -> 0.40628325 | AD10: COAL | AE10: SR | AF10: =5822.44460147077 -> 5822.4446 | AG10: 3 | AH10: =AG10*Conversions!$D$5*1000 -> 3716.7527 | AI10: =AF10-AH10 -> 2105.6919 | AJ10: 10 | AK10: 0.105 | AL10: =AK10/(1-(1+AK10)^-AJ10) -> 0.16625732 | AM10: =AI10/AL10 -> 12665.258
AD11: COAL | AF11: =13721031.29/1000 -> 13721.031 | AG11: 3 | AH11: =AG11*Conversions!$D$5*1000 -> 3716.7527 | AI11: =AF11-AH11 -> 10004.279 | AJ11: 40 | AK11: 0.105 | AL11: =AK11/(1-(1+AK11)^-AJ11) -> 0.10697141 | AM11: =AI11/AL11 -> 93522.921
A12: EG_CCGT | B12: INDIA | C12: GW | D12: NATGAS | E12: ELECTRICITY | F12: 8760 | G12: ALL | H12: 0.40444272 | I12: 25 | J12: 0.02 | K12: 0.9 | L12: 0.9 | M12: 0.85 | P12: =8512.22780274884 -> 8512.2278 | Q12: =8512227.803/1000 -> 8512.2278 | R12: 0 | S12: 0 | T12: =J12/Y12 -> 0.0079270774 | Y12: =1/H12/(1-J12) -> 2.522998 | Z12: =Carriers!H4*1000 -> 3025024.5 | AA12: =Carriers!G4*277800/0.829 -> 12627066 | AB12: =Z12/AA12 -> 0.23956671 | AC12: =AB12 -> 0.23956671 | AD12: =ECT_EfficiencyCostMaxAnnualUF!A12 -> EG_CCGT | AF12: =ECT_EfficiencyCostMaxAnnualUF!Q12 -> 8512.2278 | AG12: 2.9 | AH12: =AG12*Conversions!$D$5*1000 -> 3592.861 | AI12: =AF12-AH12 -> 4919.3668 | AJ12: 25 | AK12: 0.105 | AL12: =AK12/(1-(1+AK12)^-AJ12) -> 0.11442932 | AM12: =AI12/AL12 -> 42990.44
A13: EG_OCGT | B13: INDIA | C13: GW | D13: NATGAS | E13: ELECTRICITY | F13: 8760 | G13: ALL | H13: 0.28070163 | I13: 25 | J13: 0.01 | K13: 1 | L13: 1 | M13: 0.85 | P13: =6679.75064927145 -> 6679.7506 | Q13: =6679750.649/1000 -> 6679.7506 | R13: 0 | S13: 0 | T13: =J13/Y13 -> 0.0027789461 | Y13: =1/H13/(1-J13) -> 3.5984865 | Z13: =Carriers!H4*1000 -> 3025024.5 | AA13: =Carriers!G4*277800/0.829 -> 12627066 | AB13: =Z13/AA13 -> 0.23956671 | AC13: =AB13 -> 0.23956671 | AD13: =ECT_EfficiencyCostMaxAnnualUF!A13 -> EG_OCGT | AF13: =ECT_EfficiencyCostMaxAnnualUF!Q13 -> 6679.7506 | AG13: 0.7 | AH13: =AG13*Conversions!$D$5*1000 -> 867.24231 | AI13: =AF13-AH13 -> 5812.5083 | AJ13: 25 | AK13: 0.105 | AL13: =AK13/(1-(1+AK13)^-AJ13) -> 0.11442932 | AM13: =AI13/AL13 -> 50795.621
A14: EG_PHWR | B14: INDIA | C14: GW | D14: ATOMIC | E14: ELECTRICITY | F14: 8760 | G14: ALL | H14: 1 | I14: 40 | J14: 0.1078 | K14: 0.01 | L14: 0.01 | M14: 0.70916667 | P14: =20833.2103478327 -> 20833.21 | Q14: =20833210.35/1000 -> 20833.21 | R14: 0 | S14: 0 | T14: =J14/Y14 -> 0.09617916 | Y14: =1/H14/(1-J14) -> 1.1208249 | AD14: =ECT_EfficiencyCostMaxAnnualUF!A14 -> EG_PHWR | AF14: =ECT_EfficiencyCostMaxAnnualUF!Q14 -> 20833.21 | AG14: 4.3 | AH14: =AG14*Conversions!$D$5*1000 -> 5327.3456 | AI14: =AF14-AH14 -> 15505.865 | AJ14: 40 | AK14: 0.105 | AL14: =AK14/(1-(1+AK14)^-AJ14) -> 0.10697141 | AM14: =AI14/AL14 -> 144953.36
A15: EG_SMR | B15: INDIA | C15: GW | D15: ATOMIC | E15: ELECTRICITY | F15: 8760 | G15: ALL | H15: 1 | I15: 30 | J15: 0.05 | K15: 0.01 | L15: 0.01 | M15: 0.70916667 | Q15: =35289429.39/1000 -> 35289.429 | R15: 0 | S15: 0 | T15: =J15/Y15 -> 0.0475 | Y15: =1/H15/(1-J15) -> 1.0526316 | AD15: =ECT_EfficiencyCostMaxAnnualUF!A15 -> EG_SMR | AF15: =ECT_EfficiencyCostMaxAnnualUF!Q15 -> 35289.429 | AG15: 5 | AH15: =AG15*Conversions!$D$5*1000 -> 6194.5879 | AI15: =AF15-AH15 -> 29094.841 | AJ15: 30 | AK15: 0.105 | AL15: =AK15/(1-(1+AK15)^-AJ15) -> 0.11052848 | AM15: =AI15/AL15 -> 263233.88
A16: EG_LH | B16: INDIA | C16: GW | D16: HYDEL | E16: ELECTRICITY | F16: 8760 | G16: ALL | H16: 1 | I16: 40 | J16: 0.006 | K16: 1 | L16: 1 | M16: 1 | P16: =19631.8145207228 -> 19631.815 | Q16: =19631814.52/1000 -> 19631.815 | R16: 0 | S16: 0 | T16: =J16/Y16 -> 0.0060362173 | Y16: =H16-J16 -> 0.994 | AD16: =ECT_EfficiencyCostMaxAnnualUF!A16 -> EG_LH | AF16: =ECT_EfficiencyCostMaxAnnualUF!Q16 -> 19631.815 | AG16: 4.4 | AH16: =AG16*Conversions!$D$5*1000 -> 5451.2374 | AI16: =AF16-AH16 -> 14180.577 | AJ16: 40 | AK16: 0.105 | AL16: =AK16/(1-(1+AK16)^-AJ16) -> 0.10697141 | AM16: =AI16/AL16 -> 132564.18
A17: EG_SH | B17: INDIA | C17: GW | D17: HYDEL | E17: ELECTRICITY | F17: 8760 | G17: ALL | H17: 1 | I17: 35 | J17: 0.01 | K17: 1 | L17: 1 | M17: 1 | P17: =11825.3487554956 -> 11825.349 | Q17: =11825348.76/1000 -> 11825.349 | R17: 0 | S17: 0 | T17: =J17/Y17 -> 0.01010101 | Y17: =H17-J17 -> 0.99 | AD17: =ECT_EfficiencyCostMaxAnnualUF!A17 -> EG_SH | AF17: =ECT_EfficiencyCostMaxAnnualUF!Q17 -> 11825.349 | AG17: =2.4 -> 2.4 | AH17: =AG17*Conversions!$D$5*1000 -> 2973.4022 | AI17: =AF17-AH17 -> 8851.9466 | AJ17: 35 | AK17: 0.0835 | AL17: =AK17/(1-(1+AK17)^-AJ17) -> 0.088866959 | AM17: =AI17/AL17 -> 99608.974
A18: EG_BIOMASS | B18: INDIA | C18: GW | D18: BIOMASS_WASTE | E18: ELECTRICITY | F18: 8760 | G18: ALL | H18: 0.2388459 | I18: 20 | J18: 0.1 | K18: 0.06 | L18: 0.06 | M18: 1 | P18: =7713.45723965334 -> 7713.4572 | Q18: =7713457.24/1000 -> 7713.4572 | R18: 0 | S18: 0 | T18: =J18/Y18 -> 0.021496131 | Y18: =1/H18/(1-J18) -> 4.652 | Z18: =Carriers!H6*1000 -> 1656436.7 | AA18: =Carriers!G8*277800 -> 3791683.3 | AB18: =Z18/AA18 -> 0.43686051 | AC18: =AB18 -> 0.43686051 | AD18: =ECT_EfficiencyCostMaxAnnualUF!A18 -> EG_BIOMASS | AF18: =ECT_EfficiencyCostMaxAnnualUF!Q18 -> 7713.4572 | AG18: 1 | AH18: =AG18*Conversions!$D$5*1000 -> 1238.9176 | AI18: =AF18-AH18 -> 6474.5397 | AJ18: 20 | AK18: 0.0835 | AL18: =AK18/(1-(1+AK18)^-AJ18) -> 0.1045193 | AM18: =AI18/AL18 -> 61945.879
A19: EG_SOLARGM | B19: INDIA | C19: GW | D19: SUNLIGHT | E19: ELECTRICITY | F19: 8760 | G19: ALL | H19: 1 | I19: 25 | J19: 0.01 | K19: 1 | L19: 1 | M19: 1 | P19: =5630.98419436319 -> 5630.9842 | Q19: =5439705.856/1000 -> 5439.7059 | R19: 0 | S19: 0 | T19: =J19/Y19 -> 0.01 | Y19: 1 | AD19: =ECT_EfficiencyCostMaxAnnualUF!A19 -> EG_SOLARGM | AF19: =ECT_EfficiencyCostMaxAnnualUF!Q19 -> 5439.7059 | AG19: 0.35 | AH19: =AG19*Conversions!$D$5*1000 -> 433.62115 | AI19: =AF19-AH19 -> 5006.0847 | AJ19: 25 | AK19: 0.105 | AL19: =AK19/(1-(1+AK19)^-AJ19) -> 0.11442932 | AM19: =AI19/AL19 -> 43748.269
A20: EG_SOLARRF | B20: INDIA | C20: GW | D20: SUNLIGHT | E20: ELECTRICITY | F20: 8760 | G20: ALL | H20: 1 | I20: 25 | J20: 0.006 | K20: 1 | L20: 1 | M20: 1 | P20: =5542.18769541597 -> 5542.1877 | Q20: =5362133.837/1000 -> 5362.1338 | R20: 0 | S20: 0 | T20: =J20/Y20 -> 0.006 | Y20: 1 | AD20: =ECT_EfficiencyCostMaxAnnualUF!A20 -> EG_SOLARRF | AF20: =ECT_EfficiencyCostMaxAnnualUF!Q20 -> 5362.1338 | AG20: 0.51 | AH20: =AG20*Conversions!$D$5*1000 -> 631.84797 | AI20: =AF20-AH20 -> 4730.2859 | AJ20: 25 | AK20: 0.104 | AL20: =AK20/(1-(1+AK20)^-AJ20) -> 0.113573 | AM20: =AI20/AL20 -> 41649.738
A21: EG_WINDON | B21: INDIA | C21: GW | D21: WIND | E21: ELECTRICITY | F21: 8760 | G21: ALL | H21: 1 | I21: 25 | J21: 0.005 | K21: 1 | L21: 1 | M21: 1 | P21: =10659.4302732183 -> 10659.43 | Q21: =10586964.46/1000 -> 10586.964 | R21: 0 | S21: 0 | T21: =J21/Y21 -> 0.005 | Y21: 1 | AD21: =ECT_EfficiencyCostMaxAnnualUF!A21 -> EG_WINDON | AF21: =ECT_EfficiencyCostMaxAnnualUF!Q21 -> 10586.964 | AG21: 0.68 | AH21: =AG21*Conversions!$D$5*1000 -> 842.46396 | AI21: =AF21-AH21 -> 9744.5005 | AJ21: 25 | AK21: 0.105 | AL21: =AK21/(1-(1+AK21)^-AJ21) -> 0.11442932 | AM21: =AI21/AL21 -> 85157.375
A22: EG_WINDOFF | B22: INDIA | C22: GW | D22: WIND | E22: ELECTRICITY | F22: 8760 | G22: ALL | H22: 1 | I22: 25 | J22: 0.005 | K22: 1 | L22: 1 | M22: 1 | Q22: =34540361.67/1000 -> 34540.362 | R22: 0 | S22: 0 | T22: =J22/Y22 -> 0.005 | Y22: 1 | AD22: =ECT_EfficiencyCostMaxAnnualUF!A22 -> EG_WINDOFF | AF22: =ECT_EfficiencyCostMaxAnnualUF!Q22 -> 34540.362 | AG22: 6.7 | AH22: =AG22*Conversions!$D$5*1000 -> 8300.7478 | AI22: =AF22-AH22 -> 26239.614 | AJ22: 25 | AK22: 0.112 | AL22: =AK22/(1-(1+AK22)^-AJ22) -> 0.12047789 | AM22: =AI22/AL22 -> 217796.1
M25: for coal
M26: 0.95 | O26: =AVERAGE(M26:M38) -> 0.85 | Y26: adj in availability
M27: =$M$26 -> 0.95 | Y27: adj in discharge efficiency
M28: =$M$26 -> 0.95
M29: 0.75
M30: 0.5
M31: 0.5
M32: 0.75
M33: =$M$26 -> 0.95
M34: =$M$26 -> 0.95
M35: =$M$26 -> 0.95
M36: =$M$26 -> 0.95
M37: =$M$26 -> 0.95
M38: =$M$26 -> 0.95

Sheet Storage
A1: Source | B1: PIER2.0 | C1: PIER2.0 | D1: PIER2.0 | E1: PIER2.0 | F1: PIER2.0 | G1: PIER2.0 | H1: PIER2.0 | I1: PIER2.0 | J1: PIER2.0 | K1: PIER2.0 | L1: PIER2.0 | M1: PIER2.0 | N1: PIER2.0
A2: File | B2: EnergyStorTechnologies.csv | C2: EnergyStorTechnologies.csv | D2: EnergyStorTechnologies.csv | E2: EnergyStorTechnologies.csv | F2: EnergyStorTechnologies.csv | G2: EnergyStorTechnologies.csv | H2: EST_DeratingDepthOfDischarge.csv | I2: EST_DeratingDepthOfDischarge.csv | J2: EST_DeratingDepthOfDischarge.csv | K2: EST_EfficiencyCost.csv | L2: EST_EfficiencyCost.csv | M2: EST_Lifetime.csv | N2: EST_Lifetime.csv
A6: EnergyStorTech | B6: StoredEC | C6: DomOrImp | D6: MaxChargeRate | E6: MaxDischargeRate | F6: StorPeriodicity | G6: Comment | H6: InstYear | I6: CapacityDerating | J6: DepthOfDischarge | K6: FixedCost ( | L6: Efficiency | M6: LifetimeYears | N6: LifetimeCycles | P6: ChargeEfficiency | Q6: DischargeEfficiency | S6: MaxFlowFrac
A7: TWOHR_BATTERY | B7: ELECTRICITY | C7: EC_DOM | D7: 0.5 | E7: 0.5 | F7: DAILY | G7: For now making all storages daily cycling - given computational constraints | H7: 2024 | I7: 0 | J7: 0.9 | K7: =2247.515108*1000 -> 2247515.1 | L7: 0.8 | M7: 10 | N7: 3873.4092 | P7: =SQRT(L7) -> 0.89442719 | Q7: =SQRT(L7) -> 0.89442719
A8: FOURHR_BATTERY | B8: ELECTRICITY | C8: EC_DOM | D8: 0.25 | E8: 0.25 | F8: DAILY | H8: 2024 | I8: 0 | J8: 0.9 | K8: =1912.359346*1000 -> 1912359.3 | L8: 0.8 | M8: 10 | N8: 3873.4092 | P8: =SQRT(L8) -> 0.89442719 | Q8: =SQRT(L8) -> 0.89442719
A9: SIXHR_BATTERY | B9: ELECTRICITY | C9: EC_DOM | D9: 0.166667 | E9: 0.166667 | F9: DAILY | H9: 2024 | I9: 0 | J9: 0.9 | K9: =1800.640759*1000 -> 1800640.8 | L9: 0.8 | M9: 10 | N9: 3873.4092 | P9: =SQRT(L9) -> 0.89442719 | Q9: =SQRT(L9) -> 0.89442719
A10: PUMPED_STOR | B10: ELECTRICITY | C10: EC_DOM | D10: 0.16666667 | E10: 0.16666667 | F10: DAILY | G10: Pumped storage discharges over 6 hours (Ensure latest info taken from EST Parameters workbook) | H10: 2024 | I10: 0 | J10: 0.9 | K10: =1900.130322*1000 -> 1900130.3 | L10: 0.75 | M10: 40 | N10: 50000 | P10: =SQRT(L10) -> 0.8660254 | Q10: =SQRT(L10) -> 0.8660254
A14: EST_LegacyDetails.csv
A15: EnergyStorTech | B15: ModelGeography | C15: SubGeography1 | D15: LegacyCapacity | E15: BalLifetime | F15: BalCycles | G15: Cap2024
A16: PUMPED_STOR | B16: INDIA | C16: ER | D16: 5.4 | E16: 20 | F16: 50000 | G16: 0
A17: PUMPED_STOR | B17: INDIA | C17: WR | D17: 11.04 | E17: 20 | F17: 50000 | G17: 0
A18: PUMPED_STOR | B18: INDIA | C18: NER | D18: 0 | E18: 20 | F18: 50000 | G18: 0
A19: PUMPED_STOR | B19: INDIA | C19: SR | D19: 12.0336 | E19: 20 | F19: 50000 | G19: 0
A20: PUMPED_STOR | B20: INDIA | C20: NR | D20: 0 | E20: 20 | F20: 50000 | G20: 0
A21: MaxAddCap2024 | D21: 2Hr2024 | E21: 4Hr2024 | F21: 6Hr2024
A22: Min Add Cap=0 | B22: INDIA | C22: NR | D22: =SUM(G29:G35)*1000 -> 89.334403 | E22: =SUM(G54:G61)*1000 -> 179.76477 | F22: =SUM(G79:G86)*1000 -> 269.64715
B23: INDIA | C23: NER | D23: =SUM(G36:G37)*1000 -> 15.332799 | E23: =SUM(G62:G63)*1000 -> 30.665597 | F23: =SUM(G87:G88)*1000 -> 45.998396
B24: INDIA | C24: ER | D24: =SUM(G39:G43)*1000 -> 17.738573 | E24: =SUM(G64:G68)*1000 -> 35.477145 | F24: =SUM(G89:G93)*1000 -> 53.215718
B25: INDIA | C25: WR | D25: =SUM(G44:G48)*1000 -> 48.356055 | E25: =SUM(G69:G73)*1000 -> 96.712109 | F25: =SUM(G94:G98)*1000 -> 145.06816
B26: INDIA | C26: SR | D26: =SUM(G49:G53)*1000 -> 28.69019 | E26: =SUM(G74:G78)*1000 -> 57.38038 | F26: =SUM(G99:G103)*1000 -> 86.070569
A28: EnergyStorTech | B28: ModelGeography | C28: SubGeography1 | D28: SubGeography2 | E28: Year | F28: MinCap | G28: MaxCap
A29: TWOHR_BATTERY | B29: INDIA | C29: NR | D29: HR | E29: 2024 | F29: 0 | G29: 0.0012189254
A30: TWOHR_BATTERY | B30: INDIA | C30: NR | D30: HP | E30: 2024 | F30: 0 | G30: 0.0090457097
A31: TWOHR_BATTERY | B31: INDIA | C31: NR | D31: JK | E31: 2024 | F31: 0 | G31: 0.029684576
A32: TWOHR_BATTERY | B32: INDIA | C32: NR | D32: PB | E32: 2024 | F32: 0 | G32: 0.00075113606
A33: TWOHR_BATTERY | B33: INDIA | C33: NR | D33: RJ | E33: 2024 | F33: 0 | G33: 0.038040631
A34: TWOHR_BATTERY | B34: INDIA | C34: NR | D34: UP | E34: 2024 | F34: 0 | G34: 0.0061026464
A35: TWOHR_BATTERY | B35: INDIA | C35: NR | D35: UK | E35: 2024 | F35: 0 | G35: 0.0044907779
A36: TWOHR_BATTERY | B36: INDIA | C36: NER | D36: AS | E36: 2024 | F36: 0 | G36: 0.0036781609
A37: TWOHR_BATTERY | B37: INDIA | C37: NER | D37: NE | E37: 2024 | F37: 0 | G37: 0.011654638
A38: TWOHR_BATTERY | B38: INDIA | C38: NR | D38: DL | E38: 2024 | F38: 0 | G38: 0.00054798182
A39: TWOHR_BATTERY | B39: INDIA | C39: ER | D39: BR | E39: 2024 | F39: 0 | G39: 0.0029938519
A40: TWOHR_BATTERY | B40: INDIA | C40: ER | D40: JH | E40: 2024 | F40: 0 | G40: 0.0048596632
... A103: SIXHR_BATTERY | B103: INDIA | C103: SR | D103: TS | E103: 2024 | F103: 0 | G103: 0.016367281

Sheet Carriers
A1: Year | B1: EnergyCarrier | C1: BalancingArea | D1: BalancingTime | E1: PhysicalUnit | F1: EnergyUnit | G1: DomEnergyDensity | H1: DomEmissionFactor | I1: EmissionType | J1: ImpEnergyDensity | K1: ImpEmissionFactor | L1: Remarks
A2: 2024 | B2: COKING_COAL | C2: SUBGEOGRAPHY1 | D2: YEAR | E2: MT | F2: PJ | G2: 20.555669 | H2: 2257.6805 | I2: GHG | J2: 24.179251 | K2: 2760.9
A3: 2024 | B3: THERMAL_COAL | C3: SUBGEOGRAPHY1 | D3: YEAR | E3: MT | F3: PJ | G3: 17.207188 | H3: 1871.8737 | I3: GHG | J3: 22.60872 | K3: 1982.186
A4: 2024 | B4: NATGAS | C4: MODELGEOGRAPHY | D4: YEAR | E4: BCM | F4: PJ | G4: 37.6812 | H4: 3025.0245 | I4: GHG | J4: 37.6812 | K4: 2048.5162
A5: 2024 | B5: BIOGAS | C5: MODELGEOGRAPHY | D5: YEAR | E5: BCM | F5: PJ | G5: 22.8 | H5: 2001.5626 | I5: GHG | J5: 22.8 | K5: 1246.1226 | L5: Density of biogas is assumed to be same as natural gas
A6: 2024 | B6: BIOMASS | C6: MODELGEOGRAPHY | D6: YEAR | E6: MT | F6: PJ | G6: 15.56 | H6: 1656.4367 | I6: GHG | J6: 15.56 | K6: 1656.4367
A7: 2024 | B7: CRUDE | C7: MODELGEOGRAPHY | D7: YEAR | E7: MT | F7: PJ | G7: 43.12404 | H7: 54.232192 | I7: GHG | J7: 43.12404 | K7: 0 | L7: As only fugitive emissions are applicable to crude, emissions for imported crude is assumed as 0 for the ModelGeography
A8: 2024 | B8: BIOMASS_WASTE | C8: MODELGEOGRAPHY | D8: YEAR | E8: MT | F8: PJ | G8: 13.648968 | H8: 1292.3067 | I8: GHG | J8: 13.648968 | K8: 1292.3067
A9: 2024 | B9: PETCOKE | H9: 3176.6475 | I9: GHG | K9: 3176.6475
A10: 2024 | B10: PP_OTHER | H10: 3141.2838 | I10: GHG | K10: 3141.2838
A11: 2024 | B11: MS | H11: 3080.7549 | I11: GHG | K11: 3080.7549
A12: 2025 | B12: MS | H12: 2464.6039 | I12: GHG | K12: 2464.6039 | L12: 20% reduction due to ethanol blending, assuming E20 is fully deployed beginning FY25
A13: 2024 | B13: HSD | H13: 3196.749 | I13: GHG | K13: 3196.749
A14: 2024 | B14: ATF | H14: 3080.7549 | I14: GHG | K14: 3080.7549
A15: 2035 | B15: ATF | H15: 3058.2628 | I15: GHG | K15: 3058.2628
A16: 2036 | B16: ATF | H16: 3035.935 | I16: GHG | K16: 3035.935
A17: 2037 | B17: ATF | H17: 3013.7701 | I17: GHG | K17: 3013.7701
A18: 2038 | B18: ATF | H18: 2991.7671 | I18: GHG | K18: 2991.7671
A19: 2039 | B19: ATF | H19: 2969.9247 | I19: GHG | K19: 2969.9247
A20: 2040 | B20: ATF | H20: 2948.2418 | I20: GHG | K20: 2948.2418
A21: 2041 | B21: ATF | H21: 2926.7172 | I21: GHG | K21: 2926.7172 | L21: 5% reduction by FY41 from FY24-34 levels
A22: 2024 | B22: LPG | H22: 2987.2078 | I22: GHG | K22: 2987.2078
A27: EnergyConvTech | C27: InstYear | H27: DomEmissionFactor | I27: EmissionType | K27: ImpEmissionFactor
A28: EG_COAL | C28: 2023 | H28: 1942.0976 | I28: GHG | K28: 2057.8978

Sheet Conversions
A2: 1 | B2: PJ | C2: = | D2: 277777.78 | E2: MWh
A5: Inflator for 2020 to 2024 | D5: 1.2389176

Sheet Transmission
A1: EnergyCarrier | B1: ModelGeographySrc | C1: SubGeography1Src | D1: ModelGeographyDest | E1: SubGeography1Dest | F1: Year | G1: TransitCost | H1: TransitLoss | I1: MaxTransit | K1: used in Macro
A2: ELECTRICITY | B2: INDIA | C2: NR | D2: INDIA | E2: NR | F2: 2024 | G2: 2.6248298 | H2: 0.14930632 | I2: -1 | K2: =H2/2 -> 0.074653161
A3: ELECTRICITY | B3: INDIA | C3: WR | D3: INDIA | E3: WR | F3: 2024 | G3: 1.8783628 | H3: 0.12258156 | I3: -1 | K3: =H3/2 -> 0.061290778
A4: ELECTRICITY | B4: INDIA | C4: SR | D4: INDIA | E4: SR | F4: 2024 | G4: 2.8361183 | H4: 0.10645771 | I4: -1 | K4: =H4/2 -> 0.053228855
A5: ELECTRICITY | B5: INDIA | C5: ER | D5: INDIA | E5: ER | F5: 2024 | G5: 1.8272949 | H5: 0.17367141 | I5: -1 | K5: =H5/2 -> 0.086835705
A6: ELECTRICITY | B6: INDIA | C6: NER | D6: INDIA | E6: NER | F6: 2024 | G6: 4.6461251 | H6: 0.15154467 | I6: -1 | K6: =H6/2 -> 0.075772337
A7: ELECTRICITY | B7: INDIA | C7: NR | D7: INDIA | E7: WR | F7: 2024 | G7: 0.50994571 | H7: 0.035 | I7: 36.72
A8: ELECTRICITY | B8: INDIA | C8: WR | D8: INDIA | E8: SR | F8: 2024 | G8: 0.50994571 | H8: 0.035 | I8: 22.32
A9: ELECTRICITY | B9: INDIA | C9: SR | D9: INDIA | E9: ER | F9: 2024 | G9: 0.50994571 | H9: 0.035 | I9: 5.83
A10: ELECTRICITY | B10: INDIA | C10: ER | D10: INDIA | E10: NER | F10: 2024 | G10: 0.50994571 | H10: 0.035 | I10: 2.95
A11: ELECTRICITY | B11: INDIA | C11: NER | D11: INDIA | E11: NR | F11: 2024 | G11: 0.50994571 | H11: 0.035 | I11: 3
A12: ELECTRICITY | B12: INDIA | C12: NR | D12: INDIA | E12: SR | F12: 2024 | G12: 0.50994571 | H12: 0.035 | I12: 0
A13: ELECTRICITY | B13: INDIA | C13: WR | D13: INDIA | E13: ER | F13: 2024 | G13: 0.50994571 | H13: 0.035 | I13: 21.19
A14: ELECTRICITY | B14: INDIA | C14: SR | D14: INDIA | E14: NER | F14: 2024 | G14: 0.50994571 | H14: 0.035 | I14: 0
A15: ELECTRICITY | B15: INDIA | C15: ER | D15: INDIA | E15: NR | F15: 2024 | G15: 0.50994571 | H15: 0.035 | I15: 22.53
A16: ELECTRICITY | B16: INDIA | C16: NER | D16: INDIA | E16: WR | F16: 2024 | G16: 0.50994571 | H16: 0.035 | I16: 0
A17: ELECTRICITY | B17: INDIA | C17: NR | D17: INDIA | E17: ER | F17: 2024 | G17: 0.50994571 | H17: 0.035 | I17: 19.53
A18: ELECTRICITY | B18: INDIA | C18: WR | D18: INDIA | E18: NER | F18: 2024 | G18: 0.50994571 | H18: 0.035 | I18: 0
... A26: ELECTRICITY | B26: INDIA | C26: NER | D26: INDIA | E26: ER | F26: 2024 | G26: 0.50994571 | H26: 0.035 | I26: 2.95

Sheet Tx-CTU-rollingplans
A1: Notes:
A2: 1. In this sheet data on capacity is taken from CTU Transmission Rolling plans, divided into bi-directional capacities in inter-regional corridors
A3: 2. The same is used to project for future years post FY31
A6: Central Transmission Utility (CTU): Rolling Plans | H6: FY22 data also in NEP-2024 Table 6.4
A7: https://www.ctuil.in/annual-rolling-plan/reports/ | H7: Annex 2.11 (ISTS ROLLING PLAN 2026-27) | J7: Annex-11.11 (ISTS ROLLING PLAN 2027-28 (INTERIM REPORT)) | L7: Annex 2.10 (ISTS ROLLING PLAN 2027-28) | N7: Annex 2.8 (ISTS ROLLING PLAN 2028-29 (INTERIM REPORT)) | P7: Annex 3.10 (ISTS ROLLING PLAN 2028-29 (FINAL REPORT)) | R7: Annex 3.10 (ISTS ROLLING PLAN 2029-30)) | T7: Annex 3.3 (ISTS ROLLING PLAN 2030-31 (INTERIM REPORT))
G8: FY | H8: 2022 | I8: 2027 | J8: 2023 | K8: 2028 | L8: 2023 | M8: 2028 | N8: 2024 | O8: 2029 | P8: 2024 | Q8: 2029 | R8: 2025 | S8: 2030 | T8: 2026 | U8: 2031
B9: Direction1 | C9: Direction2 | E9: From | F9: To | H9: 44621 | I9: Capacity by 2026-27 | J9: 44805 | K9: Capacity by 2027-28 | L9: 44986 | M9: Capacity by 2027-28 | N9: 45170 | O9: Capacity at the end of 2029 | P9: 45352 | Q9: Capacity at the end of 2029 | R9: 45717 | S9: Capacity at the End of 2030 | T9: 45901 | U9: Capacity at the End of 2031
B10: =F10&"-"&E10 -> NR-ER | C10: =E10&"-"&F10 -> ER-NR | E10: ER | F10: NR | G10: EAST - NORTH | H10: 22530 | I10: 22530 | J10: 22530 | K10: 22530 | L10: 22530 | M10: 22530 | N10: 22530 | O10: 22530 | P10: 22530 | Q10: 22530 | R10: 22530 | S10: 22530 | T10: 22530 | U10: 22530
B11: =F11&"-"&E11 -> NR-WR | C11: =E11&"-"&F11 -> WR-NR | E11: WR | F11: NR | G11: WEST - NORTH | H11: 36720 | I11: 36720 | J11: 36720 | K11: 42520 | L11: 36720 | M11: 50920 | N11: 36720 | O11: 46720 | P11: 36720 | Q11: 46720 | R11: 38320 | S11: 50920 | T11: 38320 | U11: 61120
B12: =F12&"-"&E12 -> NER-ER | C12: =E12&"-"&F12 -> ER-NER | E12: ER | F12: NER | G12: EAST - NORTH EAST | H12: 2860 | I12: 3550 | J12: 2860 | K12: 3550 | L12: 2860 | M12: 3550 | N12: 2950 | O12: 2950 | P12: 2950 | Q12: 3550 | R12: 3550 | S12: 3550 | T12: 3550 | U12: 3550
B13: =F13&"-"&E13 -> WR-ER | C13: =E13&"-"&F13 -> ER-WR | E13: ER | F13: WR | G13: EAST - WEST | H13: 21190 | I13: 21190 | J13: 21190 | K13: 22790 | L13: 21190 | M13: 22790 | N13: 21190 | O13: 22790 | P13: 21190 | Q13: 22790 | R13: 21190 | S13: 22790 | T13: 22790 | U13: 26990
B14: =F14&"-"&E14 -> SR-WR | C14: =E14&"-"&F14 -> WR-SR | E14: WR | F14: SR | G14: WEST - SOUTH | H14: 18120 | I14: 23920 | J14: 18120 | K14: 28120 | L14: 18120 | M14: 28120 | N14: 18120 | O14: 28120 | P14: 22320 | Q14: 28120 | R14: 22320 | S14: 28120 | T14: 22320 | U14: 32320
B15: =F15&"-"&E15 -> SR-ER | C15: =E15&"-"&F15 -> ER-SR | E15: ER | F15: SR | G15: EAST - SOUTH | H15: 7830 | I15: 7830 | J15: 7830 | K15: 7830 | L15: 7830 | M15: 7830 | N15: 7830 | O15: 7830 | P15: 7830 | Q15: 7830 | R15: 7830 | S15: 7830 | T15: 7830 | U15: 12030
B16: =F16&"-"&E16 -> NER-NR | C16: =E16&"-"&F16 -> NR-NER | E16: NR | F16: NER | G16: NORTH EAST - NORTH | H16: 3000 | I16: 3000 | J16: 3000 | K16: 3000 | L16: 3000 | M16: 3000 | N16: 3000 | O16: 3000 | P16: 3000 | Q16: 3000 | R16: 3000 | S16: 3000 | T16: 3000 | U16: 3000
G17: TOTAL | H17: =SUM(H10:H16) -> 112250 | I17: =SUM(I10:I16) -> 118740 | J17: =SUM(J10:J16) -> 112250 | K17: =SUM(K10:K16) -> 130340 | L17: =SUM(L10:L16) -> 112250 | M17: =SUM(M10:M16) -> 138740 | N17: =SUM(N10:N16) -> 112340 | O17: =SUM(O10:O16) -> 133940 | ... U17: =SUM(U10:U16) -> 161540
E19: From | F19: To | I19: Figure 3-34: Inter-Regional Transmission Capacity in 2026-27 | K19: Figure 3-28: Inter-Regional Transmission Capacity in 2027-28 | M19: Figure 3-28: Inter-Regional Transmission Capacity by 2027-28 | O19: Figure 3-25: Inter-Regional Transmission Capacity by 2028-29 | Q19: Figure 3-26: Inter-Regional Transmission Capacity by 2028-29 | S19: Figure 3-28: Inter-Regional Transmission Capacity by 2029-30 | U19: Figure 3-11: Inter-Regional Transmission Capacity by 2030-31 | W19: =E19 -> From | X19: =F19 -> To
C20: =E20&"-"&F20 -> SR-WR | D20: 1 | E20: SR | F20: WR | I20: 23920 | K20: 28120 | M20: 25120 | N20: =M20/MAX(M20:M21) -> 0.89331437 | O20: 25120 | P20: =O20/MAX(O20:O21) -> 0.89331437 | Q20: 25120 | R20: =Q20/MAX(Q20:Q21) -> 0.89331437 | S20: 25120 | T20: =S20/MAX(S20:S21) -> 0.89331437 | U20: 29320 | V20: =U20/MAX(U20:U21) -> 0.90717822 | W20: =E20 -> SR | X20: =F20 -> WR
C21: =E21&"-"&F21 -> WR-SR | D21: 2 | E21: WR | F21: SR | I21: 23920 | K21: 28120 | M21: 28120 | N21: =M21/MAX(M21:M22) -> 1 | O21: 28120 | P21: =O21/MAX(O21:O22) -> 1 | Q21: 28120 | R21: =Q21/MAX(Q21:Q22) -> 1 | S21: 28120 | T21: =S21/MAX(S21:S22) -> 1 | U21: 32320 | V21: =U21/MAX(U21:U22) -> 1 | W21: =E21 -> WR | X21: =F21 -> SR
C22: =E22&"-"&F22 -> SR-ER | D22: 3 | E22: SR | F22: ER | I22: 7830 | K22: 7830 | M22: 5830 | N22: =M22/MAX(M22:M23) -> 0.74457216 | O22: 5830 | P22: =O22/MAX(O22:O23) -> 0.74457216 | Q22: 5830 | R22: =Q22/MAX(Q22:Q23) -> 0.74457216 | S22: 5830 | T22: =S22/MAX(S22:S23) -> 0.74457216 | U22: 9530 | V22: =U22/MAX(U22:U23) -> 0.7921862 | W22: =E22 -> SR | X22: =F22 -> ER
C23: =E23&"-"&F23 -> ER-SR | D23: 4 | E23: ER | F23: SR | I23: 7830 | K23: 7830 | M23: 7830 | N23: =M23/MAX(M22:M23) -> 1 | O23: 7830 | P23: =O23/MAX(O22:O23) -> 1 | Q23: 7830 | R23: =Q23/MAX(Q22:Q23) -> 1 | S23: 7830 | T23: =S23/MAX(S22:S23) -> 1 | U23: 12030 | V23: =U23/MAX(U22:U23) -> 1 | W23: =E23 -> ER | X23: =F23 -> SR
C24: =E24&"-"&F24 -> WR-NR | D24: 5 | E24: WR | F24: NR | I24: 36720 | K24: 45520 | M24: 45170 | N24: =M24/MAX(M24:M25) -> 0.88707777 | O24: 45170 | P24: =O24/MAX(O24:O25) -> 0.88707777 | Q24: 46720 | R24: =Q24/MAX(Q24:Q25) -> 1 | S24: 50720 | T24: =S24/MAX(S24:S25) -> 1 | U24: 61120 | V24: =U24/MAX(U24:U25) -> 1 | W24: =E24 -> WR | X24: =F24 -> NR
C25: =E25&"-"&F25 -> NR-WR | D25: 6 | E25: NR | F25: WR | I25: 36720 | K25: 45520 | M25: 50920 | N25: =M25/MAX(M24:M25) -> 1 | O25: 50920 | P25: =O25/MAX(O24:O25) -> 1 | Q25: 40720 | R25: =Q25/MAX(Q24:Q25) -> 0.87157534 | S25: 44720 | T25: =S25/MAX(S24:S25) -> 0.88170347 | U25: 55120 | V25: =U25/MAX(U24:U25) -> 0.90183246 | W25: =E25 -> NR | X25: =F25 -> WR
C26: =E26&"-"&F26 -> WR-ER | D26: 7 | E26: WR | F26: ER | I26: 21190 | K26: 22790 | M26: 22790 | N26: =M26/MAX(M26:M27) -> 1 | O26: 22790 | P26: =O26/MAX(O26:O27) -> 1 | Q26: 22790 | R26: =Q26/MAX(Q26:Q27) -> 1 | S26: 22790 | T26: =S26/MAX(S26:S27) -> 1 | U26: 26990 | V26: =U26/MAX(U26:U27) -> 1 | W26: =E26 -> WR | X26: =F26 -> ER
C27: =E27&"-"&F27 -> ER-WR | D27: 8 | E27: ER | F27: WR | I27: 21190 | K27: 22790 | M27: 22790 | N27: =M27/MAX(M26:M27) -> 1 | O27: 22790 | P27: =O27/MAX(O26:O27) -> 1 | Q27: 22790 | R27: =Q27/MAX(Q26:Q27) -> 1 | S27: 22790 | T27: =S27/MAX(S26:S27) -> 1 | U27: 26990 | V27: =U27/MAX(U26:U27) -> 1 | W27: =E27 -> ER | X27: =F27 -> WR
C28: =E28&"-"&F28 -> ER-NER | D28: 9 | E28: ER | F28: NER | I28: 3550 | K28: 3550 | M28: 3550 | N28: =M28/MAX(M28:M29) -> 1 | O28: 3550 | P28: =O28/MAX(O28:O29) -> 1 | Q28: 3550 | R28: =Q28/MAX(Q28:Q29) -> 1 | S28: 3550 | T28: =S28/MAX(S28:S29) -> 1 | U28: 3550 | V28: =U28/MAX(U28:U29) -> 1 | W28: =E28 -> ER | X28: =F28 -> NER
C29: =E29&"-"&F29 -> NER-ER | D29: 10 | E29: NER | F29: ER | I29: 3550 | K29: 3550 | M29: 3550 | N29: =M29/MAX(M28:M29) -> 1 | O29: 3550 | P29: =O29/MAX(O28:O29) -> 1 | Q29: 3550 | R29: =Q29/MAX(Q28:Q29) -> 1 | S29: 3550 | T29: =S29/MAX(S28:S29) -> 1 | U29: 3550 | V29: =U29/MAX(U28:U29) -> 1 | W29: =E29 -> NER | X29: =F29 -> ER
C30: =E30&"-"&F30 -> ER-NR | D30: 11 | E30: ER | F30: NR | I30: 22530 | K30: 22530 | M30: 22530 | N30: =M30/MAX(M30:M31) -> 1 | O30: 22530 | P30: =O30/MAX(O30:O31) -> 1 | Q30: 22530 | R30: =Q30/MAX(Q30:Q31) -> 1 | S30: 22630 | T30: =S30/MAX(S30:S31) -> 1 | U30: 22530 | V30: =U30/MAX(U30:U31) -> 1 | W30: =E30 -> ER | X30: =F30 -> NR
C31: =E31&"-"&F31 -> NR-ER | D31: 12 | E31: NR | F31: ER | I31: 22530 | K31: 22530 | M31: 19530 | N31: =M31/MAX(M30:M31) -> 0.86684421 | O31: 19530 | P31: =O31/MAX(O30:O31) -> 0.86684421 | Q31: 19530 | R31: =Q31/MAX(Q30:Q31) -> 0.86684421 | S31: 19530 | T31: =S31/MAX(S30:S31) -> 0.8630137 | U31: 19530 | V31: =U31/MAX(U30:U31) -> 0.86684421 | W31: =E31 -> NR | X31: =F31 -> ER
C32: =E32&"-"&F32 -> NR-NER | D32: 13 | E32: NR | F32: NER | I32: 3000 | K32: 3000 | M32: 1500 | N32: =M32/MAX(M32:M33) -> 0.5 | O32: 1500 | P32: =O32/MAX(O32:O33) -> 0.5 | Q32: 1500 | R32: =Q32/MAX(Q32:Q33) -> 0.5 | S32: 1500 | T32: =S32/MAX(S32:S33) -> 0.5 | U32: 1500 | V32: =U32/MAX(U32:U33) -> 0.5 | W32: =E32 -> NR | X32: =F32 -> NER
C33: =E33&"-"&F33 -> NER-NR | D33: 14 | E33: NER | F33: NR | I33: 3000 | K33: 3000 | M33: 3000 | N33: =M33/MAX(M32:M33) -> 1 | O33: 3000 | P33: =O33/MAX(O32:O33) -> 1 | Q33: 3000 | R33: =Q33/MAX(Q32:Q33) -> 1 | S33: 3000 | T33: =S33/MAX(S32:S33) -> 1 | U33: 3000 | V33: =U33/MAX(U32:U33) -> 1 | W33: =E33 -> NER | X33: =F33 -> NR
I36: All directions have same values | K36: All directions have same values | O36: WR-NR-WR is higher than projected total? | Q36: WR-NR-WR is higher than projected total? | S36: WR-NR is a typo? | U36: ER-NR is reduced
G40: Notes on treatment of birectional capacity
H41: 1. Relative Capacity shares within an inter-regional corridor is first mentioned in 'Rolling plan 2027-28', and is applied for years FY22-FY28 due to lack of available data for these years
H42: 2. As on Sept 2025 (i.e 2 QTRs of FY26), the Capacity was already ~120GW which is greater than FY2026-27 plan; therefore for FY26-27 the rolling plan is dirsregarded and FY26 data is considered as constant
H43: 3. The WR-NR capacity in FY27-28 Rolling plan gets downgraded from 50.9GW to 46.7GW until FY29-30 plan. Since it is not reasonable to expect a higher capacity in an earlier year and lower in the subsequent years, for FY28 assumption FY29 plan is considered.
H44: 4. Considering the relative shares from FY28-29 Final report leads to a situation where
H45: 5. Decide on projections
F48: Inter-regional corridor transmission capacity
F50: MW | H50: Actuals | M50: CTU Rolling plans | R50: Projected by PIER
G51: FY | H51: 2022 | I51: =H51+1 -> 2023 | J51: =I51+1 -> 2024 | K51: =J51+1 -> 2025 | L51: =K51+1 -> 2026 | M51: =L51+1 -> 2027 | N51: =M51+1 -> 2028 | O51: =N51+1 -> 2029 | P51: =O51+1 -> 2030 | ... AA51: =Z51+1 -> 2041 | AE51: CAGR FY22 to FY26 | AF51: CAGR FY26-FY30 | AG51: Actual assumed | AI51: CAGR FY24-FY41
...

Sheet ECT_MaxAdd2024
A3: Year | B3: 2024 | C3: 2023 | D3: Total in 2024
A5: Row Labels | B5: Sum of MaxCapacity
A6: NR | B6: 5.7302851
A7: EG_BIOMASS | B7: 0.143 | C7: 3355.17 | D7: =B7*1000+C7 -> 3498.17
A8: EG_CCGT | B8: 0 | C8: 7330.5 | D8: =B8*1000+C8 -> 7330.5
A9: EG_COAL | B9: 0 | C9: 67226.28 | D9: =B9*1000+C9 -> 67226.28
A10: EG_LH | B10: 0 | C10: 20500 | D10: =B10*1000+C10 -> 20500
A11: EG_OCGT | B11: 0 | C11: 0 | D11: =B11*1000+C11 -> 0
A12: EG_PHWR | B12: 0 | C12: 1603.5 | D12: =B12*1000+C12 -> 1603.5
A13: EG_SH | B13: 0.028 | C13: 1700 | D13: =B13*1000+C13 -> 1728
A14: EG_SMR | B14: 0 | C14: 0 | D14: =B14*1000+C14 -> 0
A15: EG_SOLARGM | B15: 4.791 | C15: 19996.72 | D15: =B15*1000+C15 -> 24787.72
A16: EG_SOLARRF | B16: 0.766 | C16: 2666.3 | D16: =B16*1000+C16 -> 3432.3
A17: EG_WINDOFF | B17: 0 | C17: 0 | D17: =B17*1000+C17 -> 0
A18: EG_WINDON | B18: 0.002 | C18: 5301.4 | D18: =B18*1000+C18 -> 5303.4
A19: GH_ELECTROLYSIS | B19: 0.0002850662 | C19: 0 | D19: =B19*1000+C19 -> 0.2850662
A20: NER | B20: 0.026021154
A21: EG_BIOMASS | B21: 0.001 | C21: 15.8 | D21: =B21*1000+C21 -> 16.8
A22: EG_CCGT | B22: 0 | C22: 2002.4 | D22: =B22*1000+C22 -> 2002.4
A23: EG_COAL | B23: 0 | C23: 1011 | D23: =B23*1000+C23 -> 1011
A24: EG_LH | B24: 0 | C24: 1850 | D24: =B24*1000+C24 -> 1850
A25: EG_OCGT | B25: 0 | C25: 0 | D25: =B25*1000+C25 -> 0
A26: EG_PHWR | B26: 0 | C26: 0 | D26: =B26*1000+C26 -> 0
A27: EG_SH | B27: 0.01 | C27: 300 | D27: =B27*1000+C27 -> 310
A28: EG_SMR | B28: 0 | C28: 0 | D28: =B28*1000+C28 -> 0
A29: EG_SOLARGM | B29: 0.007 | C29: 171.48 | D29: =B29*1000+C29 -> 178.48
A30: EG_SOLARRF | B30: 0.008 | C30: 67.6 | D30: =B30*1000+C30 -> 75.6
A31: EG_WINDOFF | B31: 0 | C31: 0 | D31: =B31*1000+C31 -> 0
A32: EG_WINDON | B32: 0 | C32: 0 | D32: =B32*1000+C32 -> 0
A33: GH_ELECTROLYSIS | B33: 2.1154e-05 | C33: 0 | D33: =B33*1000+C33 -> 0.021154
A34: ER | B34: 0.2071059
A35: EG_BIOMASS | B35: 0.023 | C35: 560.64 | D35: =B35*1000+C35 -> 583.64
A36: EG_CCGT | B36: 0 | C36: 770.8 | D36: =B36*1000+C36 -> 770.8
A37: EG_COAL | B37: 0 | C37: 41730 | D37: =B37*1000+C37 -> 41730
A38: EG_LH | B38: 0 | C38: 4200 | D38: =B38*1000+C38 -> 4200
A39: EG_OCGT | B39: 0 | C39: 0 | D39: =B39*1000+C39 -> 0
A40: EG_PHWR | B40: 0 | C40: 0 | D40: =B40*1000+C40 -> 0
A41: EG_SH | B41: 0.006 | C41: 350 | D41: =B41*1000+C41 -> 356
A42: EG_SMR | B42: 0 | C42: 0 | D42: =B42*1000+C42 -> 0
A43: EG_SOLARGM | B43: 0.04 | C43: 847.72 | D43: =B43*1000+C43 -> 887.72
...

Sheet NODES
A1: PEC_ProdImpConstraints.csv | E1: MT or BCF | F1: MT or BCF | G1: PEC_Info.csv | H1: need unit | K1: need unit | Q1: Dom | R1: Imp | T1: MWh | V1: NatSum
A2: EnergyCarrier | B2: ModelGeography | C2: SubGeography1 | D2: Year | E2: MaxDomesticProd | F2: MaxImport | G2: NonEnergyShare | H2: DomesticPrice (mRs/ktonne) | I2: AVTaxOHDom | J2: FixedTaxOHDom | K2: ImportPrice | L2: AVTaxOHImp | M2: FixedTaxOHImp | O2: Price (mRs/mT) | P2: Price (mRs/BCM) | Q2: Fuel Price (mRs/mWh) | R2: Fuel Price (mRs/mWh) | T2: MaxDomesticProd | U2: MaxImport
A3: BIOMASS | B3: INDIA | D3: 2023 | E3: 270 | F3: 0 | G3: 0 | H3: 5449.5727 | I3: 0 | J3: 0 | K3: 5449.5727 | L3: 0 | M3: 0 | O3: =H3*1000 -> 5449572.7 | Q3: =O3/Carriers!$G$6/Conversions!$D$2 -> 1.2608266 | R3: =Q3 -> 1.2608266 | T3: =E3*Carriers!$G$6*1000000000 -> 4201200000000 | U3: =F3*Carriers!$G$6*1000000000 -> 0
A4: BIOMASS | B4: INDIA | D4: 2024 | E4: 270 | F4: 0 | G4: 0 | H4: 5683.2536 | I4: 0 | J4: 0 | K4: 5683.2536 | L4: 0 | M4: 0 | O4: =H4*1000 -> 5683253.6 | Q4: =O4/Carriers!$G$6/Conversions!$D$2 -> 1.3148916 | R4: =Q4 -> 1.3148916 | T4: =E4*Carriers!$G$6*1000000000 -> 4201200000000 | U4: =F4*Carriers!$G$6*1000000000 -> 0
A5: BIOMASS_WASTE | B5: INDIA | D5: 2023 | E5: 175 | F5: 0 | G5: 0 | H5: 9000 | I5: 0.05 | J5: 0 | K5: 9000 | L5: 0.05 | M5: 0 | O5: =H5*1000 -> 9000000 | Q5: =O5/Carriers!$G$8/Conversions!$D$2 -> 2.3738058 | R5: =Q5 -> 2.3738058 | T5: =E5*Carriers!$G$6*1000000000 -> 2723000000000 | U5: =F5*Carriers!$G$6*1000000000 -> 0
A6: BIOMASS_WASTE | B6: INDIA | D6: 2024 | E6: 175 | F6: 0 | G6: 0 | H6: 9000 | I6: 0.05 | J6: 0 | K6: 9000 | L6: 0.05 | M6: 0 | O6: =H6*1000 -> 9000000 | Q6: =O6/Carriers!$G$8/Conversions!$D$2 -> 2.3738058 | R6: =Q6 -> 2.3738058 | T6: =E6*Carriers!$G$6*1000000000 -> 2723000000000 | U6: =F6*Carriers!$G$6*1000000000 -> 0
A7: NATGAS | B7: INDIA | D7: 2023 | E7: 33.648 | F7: 200 | G7: 0.36749121 | H7: 23859.031 | I7: 0.24 | J7: 0 | K7: 54880.306 | L7: 0.349 | M7: 0 | P7: =H7*1000 -> 23859031 | Q7: =P7/Carriers!$G$4/Conversions!$D$2 -> 2.2794526 | R7: =K7*1000/Carriers!$G$4/Conversions!$D$2 -> 5.2431743 | T7: =E7*Carriers!$G$4*1000000000 -> 1267897017600 | U7: =F7*Carriers!$G$4*1000000000 -> 7536240000000
A8: NATGAS | B8: INDIA | D8: 2024 | E8: 34.32096 | F8: 200 | G8: 0.36749121 | H8: 24102 | I8: 0.24 | J8: 0 | K8: 35195.967 | L8: 0.349 | M8: 0 | P8: =H8*1000 -> 24102000 | Q8: =P8/Carriers!$G$4/Conversions!$D$2 -> 2.3026655 | R8: =K8*1000/Carriers!$G$4/Conversions!$D$2 -> 3.3625648 | T8: =E8*Carriers!$G$4*1000000000 -> 1.293255e+12 | U8: =F8*Carriers!$G$4*1000000000 -> 7536240000000
A9: THERMAL_COAL | B9: INDIA | C9: ER | D9: 2023 | E9: 395.289 | F9: 150 | G9: 0 | H9: 1156.3734 | I9: 0.3508 | J9: 0 | K9: 13197.141 | L9: 0.205 | M9: 0 | O9: =H9*1000 -> 1156373.4 | Q9: =O9/Carriers!$G$3/Conversions!$D$2 -> 0.24193055 | R9: =K9*1000/Carriers!$J$3/Conversions!$D$2 -> 2.1013886 | T9: =E9*Carriers!$G$3*1000000000 -> 6.801812e+12 | U9: =F9*Carriers!$J$3*1000000000 -> 3.391308e+12
A10: THERMAL_COAL | B10: INDIA | C10: WR | D10: 2023 | E10: 406.857 | F10: 150 | G10: 0 | H10: 1156.3734 | I10: 0.3508 | J10: 0 | K10: 13197.141 | L10: 0.205 | M10: 0 | O10: =H10*1000 -> 1156373.4 | Q10: =O10/Carriers!$G$3/Conversions!$D$2 -> 0.24193055 | R10: =K10*1000/Carriers!$J$3/Conversions!$D$2 -> 2.1013886 | T10: =E10*Carriers!$G$3*1000000000 -> 7.0008647e+12 | U10: =F10*Carriers!$J$3*1000000000 -> 3.391308e+12
A11: THERMAL_COAL | B11: INDIA | C11: NR | D11: 2023 | E11: 30.747 | F11: 0 | G11: 0 | H11: 1156.3734 | I11: 0.3508 | J11: 0 | K11: 13197.141 | L11: 0.205 | M11: 0 | O11: =H11*1000 -> 1156373.4 | Q11: =O11/Carriers!$G$3/Conversions!$D$2 -> 0.24193055 | R11: =K11*1000/Carriers!$J$3/Conversions!$D$2 -> 2.1013886 | T11: =E11*Carriers!$G$3*1000000000 -> 5.290694e+11 | U11: =F11*Carriers!$J$3*1000000000 -> 0
A12: THERMAL_COAL | B12: INDIA | C12: SR | D12: 2023 | E12: 91.156 | F12: 150 | G12: 0 | H12: 1156.3734 | I12: 0.3508 | J12: 0 | K12: 13197.141 | L12: 0.205 | M12: 0 | O12: =H12*1000 -> 1156373.4 | Q12: =O12/Carriers!$G$3/Conversions!$D$2 -> 0.24193055 | R12: =K12*1000/Carriers!$J$3/Conversions!$D$2 -> 2.1013886 | T12: =E12*Carriers!$G$3*1000000000 -> 1.5685384e+12 | U12: =F12*Carriers!$J$3*1000000000 -> 3.391308e+12
A13: THERMAL_COAL | B13: INDIA | C13: NER | D13: 2023 | E13: 0 | F13: 0 | G13: 0 | H13: 1156.3734 | I13: 0.3508 | J13: 0 | K13: 13197.141 | L13: 0.205 | M13: 0 | O13: =H13*1000 -> 1156373.4 | Q13: =O13/Carriers!$G$3/Conversions!$D$2 -> 0.24193055 | R13: =K13*1000/Carriers!$J$3/Conversions!$D$2 -> 2.1013886 | T13: =E13*Carriers!$G$3*1000000000 -> 0 | U13: =F13*Carriers!$J$3*1000000000 -> 0 | V13: =SUM(T9:T13) -> 1.5900285e+13 | W13: =SUM(U9:U13) -> 1.0173924e+13
A14: THERMAL_COAL | B14: INDIA | C14: ER | D14: 2024 | E14: 417.84809 | F14: 150 | G14: 0 | H14: 1156.3734 | I14: 0.3508 | J14: 0 | K14: 10095.813 | L14: 0.205 | M14: 0 | O14: =H14*1000 -> 1156373.4 | Q14: =O14/Carriers!$G$3/Conversions!$D$2 -> 0.24193055 | R14: =K14*1000/Carriers!$J$3/Conversions!$D$2 -> 1.6075623 | T14: =E14*Carriers!$G$3*1000000000 -> 7.1899905e+12 | U14: =F14*Carriers!$J$3*1000000000 -> 3.391308e+12
A15: THERMAL_COAL | B15: INDIA | C15: WR | D15: 2024 | E15: 429.33807 | F15: 150 | G15: 0 | H15: 1156.3734 | I15: 0.3508 | J15: 0 | K15: 10095.813 | L15: 0.205 | M15: 0 | O15: =H15*1000 -> 1156373.4 | Q15: =O15/Carriers!$G$3/Conversions!$D$2 -> 0.24193055 | R15: =K15*1000/Carriers!$J$3/Conversions!$D$2 -> 1.6075623 | T15: =E15*Carriers!$G$3*1000000000 -> 7.3877008e+12 | U15: =F15*Carriers!$J$3*1000000000 -> 3.391308e+12
A16: THERMAL_COAL | B16: INDIA | C16: NR | D16: 2024 | E16: 31.9232 | F16: 0 | G16: 0 | H16: 1156.3734 | I16: 0.3508 | J16: 0 | K16: 10095.813 | L16: 0.205 | M16: 0 | O16: =H16*1000 -> 1156373.4 | Q16: =O16/Carriers!$G$3/Conversions!$D$2 -> 0.24193055 | R16: =K16*1000/Carriers!$J$3/Conversions!$D$2 -> 1.6075623 | T16: =E16*Carriers!$G$3*1000000000 -> 5.4930849e+11 | U16: =F16*Carriers!$J$3*1000000000 -> 0
A17: THERMAL_COAL | B17: INDIA | C17: SR | D17: 2024 | E17: 91.773025 | F17: 150 | G17: 0 | H17: 1156.3734 | I17: 0.3508 | J17: 0 | K17: 10095.813 | L17: 0.205 | M17: 0 | O17: =H17*1000 -> 1156373.4 | Q17: =O17/Carriers!$G$3/Conversions!$D$2 -> 0.24193055 | R17: =K17*1000/Carriers!$J$3/Conversions!$D$2 -> 1.6075623 | T17: =E17*Carriers!$G$3*1000000000 -> 1.5791557e+12 | U17: =F17*Carriers!$J$3*1000000000 -> 3.391308e+12
A18: THERMAL_COAL | B18: INDIA | C18: NER | D18: 2024 | E18: 0 | F18: 0 | G18: 0 | H18: 1156.3734 | I18: 0.3508 | J18: 0 | K18: 10095.813 | L18: 0.205 | M18: 0 | O18: =H18*1000 -> 1156373.4 | Q18: =O18/Carriers!$G$3/Conversions!$D$2 -> 0.24193055 | R18: =K18*1000/Carriers!$J$3/Conversions!$D$2 -> 1.6075623 | T18: =E18*Carriers!$G$3*1000000000 -> 0 | U18: =F18*Carriers!$J$3*1000000000 -> 0 | V18: =SUM(T14:T18) -> 1.6706155e+13 | W18: =SUM(U14:U18) -> 1.0173924e+13
G27: TWH | H27: MWh
G28: =1374 -> 1374 | H28: =G28*1000000 -> 1374000000 | I28: =H28*Q10 -> 3.3241257e+08

Sheet CAPEX_example
G7: Source- | H7: Section 4.1 ITC 2022
F8: ITC cost calculation | G8: 2020 | H8: 2030 | I8: 2040 | J8: 2050 | K8: https://cercind.gov.in/2022/orders/14-SM-2022.pdf
F9: Capital cost (cr. ₹/MW) | G9: 5 | H9: 5 | I9: 4.9 | J9: 4.83 | K9: Discount rate | N9: 10.5
F10: Fixed O&M (cr. ₹/MW/year) | G10: 0 | H10: 0 | I10: 0 | J10: 0
F11: Variable cost | G11: -
F12: lifetime | G12: 20 | H12: 20 | I12: 20 | J12: 20
F13: Discount rate/interest rate | G13: =N9/100 -> 0.105 | H13: =G13 -> 0.105 | I13: =G13 -> 0.105 | J13: =G13 -> 0.105
F14: Capital recovery Factor (CRF) | G14: =(G13*(1+G13)^G12)/(((1+G13)^G12)-1) -> 0.12149327 | H14: =(H13*(1+H13)^H12)/(((1+H13)^H12)-1) -> 0.12149327 | I14: =(I13*(1+I13)^I12)/(((1+I13)^I12)-1) -> 0.12149327 | J14: =(J13*(1+J13)^J12)/(((1+J13)^J12)-1) -> 0.12149327
F15: Annualized capital cost (cr. ₹/MW) | G15: =G14*G9 -> 0.60746633 | H15: =H14*H9 -> 0.60746633 | I15: =I14*I9 -> 0.595317 | J15: =J14*J9 -> 0.58681247
F16: Total annualized cost | G16: =(G15+G10)*10^7/1000 -> 6074.6633 | H16: =(H15+H10)*10^7/1000 -> 6074.6633 | I16: =(I15+I10)*10^7/1000 -> 5953.17 | J16: =(J15+J10)*10^7/1000 -> 5868.1247
F17: Tottal AIC in Rs2024 millionRs/MW | G17: =G16*Conversions!$D$5*10 -> 75260.071 | H17: =H16*Conversions!$D$5*10 -> 75260.071 | I17: =I16*Conversions!$D$5*10 -> 73754.87 | J17: =J16*Conversions!$D$5*10 -> 72701.229
D19: All in million rupees
