Workbook
Name Escalation_rate: [1]!COAL_TransitCost_Esc[#All]

Sheet Model_expectations_worksheet
N3: Reported Macro investments = Annual annuity * years in total model length
C4: legacy | D4: 2024 | E4: 2025 | T4: Not applying in the first year, as it should be
C5: P1 | D5: P2 | E5: P3 | G5: All | H5: All | I5: P1 | J5: P2 | K5: P3 | N5: Invest_multiplier | Q5: Total annualized investment (trillion) - coming from Macro / 2 | T5: Fixed | W5: PIER
B6: Tech | D6: MW | E6: MW | G6: FixedO&M | H6: CRP | J6: Investment | K6: Investment | L6: CRF | N6: P2 | O6: P3 | Q6: P2 | R6: P3 | T6: P2 | U6: P3 | W6: P2 | X6: P3
B7: EG_COAL | C7: 264152.47 | D7: 0 | E7: 1980 | G7: 3.7167527 | H7: 40 | J7: 93.522921 | K7: 93.522921 | L7: 0.10697141 | N7: 2 | O7: 1 | Q7: =J7*D7*L7*N7/1000000 -> 0 | R7: =E7*K7*L7*O7/1000000 -> 0.019808472 | T7: =C7*G7/1000000 -> 0.98178942 | U7: =(C7+D7)*G7/1000000 -> 0.98178942
B8: EG_CCGT | C8: 31397.2 | D8: 370 | E8: 370 | G8: 3.592861 | H8: 25 | J8: 42.99044 | K8: 42.99044 | L8: 0.11442932 | N8: 2 | O8: 1 | Q8: =J8*D8*L8*N8/1000000 -> 0.0036403314 | R8: =E8*K8*L8*O8/1000000 -> 0.0018201657 | T8: =C8*G8/1000000 -> 0.11280577 | U8: =(C8+D8)*G8/1000000 -> 0.11413513
B9: EG_OCGT | C9: 0 | D9: 0 | E9: 0 | G9: 0.86724231 | H9: 25 | J9: 50.795621 | K9: 50.795621 | L9: 0.11442932 | N9: 2 | O9: 1 | Q9: =J9*D9*L9*N9/1000000 -> 0 | R9: =E9*K9*L9*O9/1000000 -> 0 | T9: =C9*G9/1000000 -> 0 | U9: =(C9+D9)*G9/1000000 -> 0
B10: EG_PHWR | C10: 8180.01 | D10: 1400 | E10: 2100 | G10: 5.3273456 | H10: 40 | J10: 144.95336 | K10: 144.95336 | L10: 0.10697141 | N10: 2 | O10: 1 | Q10: =J10*D10*L10*N10/1000000 -> 0.043416421 | R10: =E10*K10*L10*O10/1000000 -> 0.032562316 | T10: =C10*G10/1000000 -> 0.04357774 | U10: =(C10+D10)*G10/1000000 -> 0.051036024
B11: EG_SMR | C11: 0 | D11: 0 | E11: 0 | G11: 6.1945879 | H11: 30 | J11: 263.23388 | K11: 263.23388 | L11: 0.11052848 | N11: 2 | O11: 1 | Q11: =J11*D11*L11*N11/1000000 -> 0 | R11: =E11*K11*L11*O11/1000000 -> 0 | T11: =C11*G11/1000000 -> 0 | U11: =(C11+D11)*G11/1000000 -> 0
B12: EG_LH | C12: 46491.18 | D12: 0 | E12: 1160 | G12: 5.4512374 | H12: 40 | J12: 132.56418 | K12: 132.56418 | L12: 0.10697141 | N12: 2 | O12: 1 | Q12: =J12*D12*L12*N12/1000000 -> 0 | R12: =E12*K12*L12*O12/1000000 -> 0.01644947 | T12: =C12*G12/1000000 -> 0.25343446 | U12: =(C12+D12)*G12/1000000 -> 0.25343446
B13: EG_SH | C13: 4939.05 | D13: 72 | E13: 144 | G13: 2.9734022 | H13: 35 | J13: 99.608974 | K13: 99.608974 | L13: 0.088866959 | N13: 2 | O13: 1 | Q13: =J13*D13*L13*N13/1000000 -> 0.0012746803 | R13: =E13*K13*L13*O13/1000000 -> 0.0012746803 | T13: =C13*G13/1000000 -> 0.014685782 | U13: =(C13+D13)*G13/1000000 -> 0.014899867
B14: EG_BIOMASS | C14: 10830.04 | D14: 463 | E14: 926 | G14: 1.2389176 | H14: 20 | J14: 61.945879 | K14: 61.945879 | L14: 0.1045193 | N14: 2 | O14: 1 | Q14: =J14*D14*L14*N14/1000000 -> 0.0059954237 | R14: =E14*K14*L14*O14/1000000 -> 0.0059954237 | T14: =C14*G14/1000000 -> 0.013417527 | U14: =(C14+D14)*G14/1000000 -> 0.013991146
B15: EG_SOLARGM | C15: 58366.793 | D15: 12020 | E15: 25411 | G15: 0.43362115 | H15: 25 | J15: 43.748269 | K15: 42.133466 | L15: 0.11442932 | N15: 2 | O15: 1 | Q15: =J15*D15*L15*N15/1000000 -> 0.12034628 | R15: =E15*K15*L15*O15/1000000 -> 0.12251415 | T15: =C15*G15/1000000 -> 0.025309076 | U15: =(C15+D15)*G15/1000000 -> 0.030521202
B16: EG_SOLARRF | C16: 9468.2674 | D16: 3234 | E16: 25392 | G16: 0.63184797 | H16: 25 | J16: 41.649738 | K16: 40.115885 | L16: 0.113573 | N16: 2 | O16: 1 | Q16: =J16*D16*L16*N16/1000000 -> 0.030595489 | R16: =E16*K16*L16*O16/1000000 -> 0.11568802 | T16: =C16*G16/1000000 -> 0.0059825055 | U16: =(C16+D16)*G16/1000000 -> 0.0080259018
B17: EG_WINDON | C17: 46169.83 | D17: 3253 | E17: 8758 | G17: 0.84246396 | H17: 25 | J17: 85.157375 | K17: 84.5284 | L17: 0.11442932 | N17: 2 | O17: 1 | Q17: =J17*D17*L17*N17/1000000 -> 0.06339772 | R17: =E17*K17*L17*O17/1000000 -> 0.084711994 | T17: =C17*G17/1000000 -> 0.038896418 | U17: =(C17+D17)*G17/1000000 -> 0.041636953
B18: EG_WINDOFF | C18: 0 | D18: 0 | E18: 0 | G18: 8.3007478 | H18: 25 | J18: 217.7961 | K18: 202.86445 | L18: 0.12047789 | N18: 2 | O18: 1 | Q18: =J18*D18*L18*N18/1000000 -> 0 | R18: =E18*K18*L18*O18/1000000 -> 0 | T18: =C18*G18/1000000 -> 0 | U18: =(C18+D18)*G18/1000000 -> 0
Q19: =SUM(Q7:Q18) -> 0.26866634 | R19: =SUM(R7:R18) -> 0.4008247 | T19: =SUM(T7:T18) -> 1.4898987 | U19: =SUM(U7:U18) -> 1.5094701
Q20: =Q19/2 -> 0.13433317

Sheet PeriodMap
A1: Period | B1: Year (FY) | C1: Constraint (s) | D1: Notes
A2: 1 | B2: 2023 | C2: Capacity forced , no retirements, no new-builds | D2: This period is inserted only so that all existing capacity can be built. Using demand from 2024, as PIER2.0 does not provide a demand for 2023
A3: 2 | B3: 2024 | C3: Pipeline capacity forced, no retirements, no new-builds | D3: Demand = PIER2.0 2024, Calibration year for constrained model operation and comparison between Rumi+PIER2.0 & Macro case build on PIER2.0
A4: 3 | B4: 2025 | D4: Demand = PIER2.0 2025, Calibration year for less constraned model operaration
A5: 4 | B5: 2029 | D5: Using demand from 2029, as selected year for period , which spans 2026 to 2031, using constraints from PIER2.0 "8_REF_Unconstr" scenario
A6: 5 | B6: 2034 | D6: Using demand from 2034, as selected year for period, which spans 2032 to 2036, using constraints from PIER2.0 "8_REF_Unconstr" scenario
A7: 6 | B7: 2039 | D7: Using demand from 2039, as selected year for period, which spans 2037 to 2041, using constraints from PIER2.0 "8_REF_Unconstr" scenario
A8: 7 | B8: 2045
A9: 8 | B9: 2055
A10: 9 | B10: 2065
A11: 10 | B11: 2071

Sheet nodes
A1: Source::File | B1: PIER2.0::PEC_ProdImpConstraints.csv | C1: PIER2.0::PEC_ProdImpConstraints.csv | D1: PIER2.0::PEC_ProdImpConstraints.csv | E1: PIER2.0::PEC_ProdImpConstraints.csv | F1: PIER2.0::PEC_ProdImpConstraints.csv | G1: PIER2.0::PEC_ProdImpConstraints.csv | H1: PIER2.0::PEC_Info.csv | I1: PIER2.0::PEC_Info.csv | J1: PIER2.0::PEC_Info.csv | K1: PIER2.0::PEC_Info.csv | L1: PIER2.0::PEC_Info.csv | M1: PIER2.0::PEC_Info.csv | N1: PIER2.0::PEC_Info.csv
A2: PIER2.0 var name | B2: EnergyCarrier | C2: ModelGeography | D2: SubGeography1 | E2: Year | F2: MaxDomesticProd | G2: MaxImport | H2: NonEnergyShare | I2: DomesticPrice (mRs/ktonne) | J2: AVTaxOHDom | K2: FixedTaxOHDom | L2: ImportPrice | M2: AVTaxOHImp | N2: FixedTaxOHImp
A3: Variable | F3: a | G3: b | H3: c | I3: d | J3: e | K3: f | L3: g | M3: h | N3: i | P3: aa | Q3: bb | R3: cc | S3: dd
A4: description | P4: Seg1 - domestic price with taxes applied | Q4: Seg 1 - domestic resource | R4: Seg 2 - import price with taxes applied | S4: Seg 2 - import resource
A5: Equation to Macro var | P5: = ( d * 1e3 * (1 + e) + f * 1e3 ) / conversion_if_not _MT / conversion from MT to PJ / conversion from PJ to MWh | Q5: = a * conversion_if_not _MT * conversion from MT to PJ * conversion from PJ to MWh | R5: = ( g * 1e3 * (1 + h) + i * 1e3 ) / conversion_if_not _MT / conversion from MT to PJ / conversion from PJ to MWh | S5: = b * conversion_if_not _MT * conversion from MT to PJ * conversion from PJ to MWh
A6: Macro variable | D6: location | P6: price | Q6: max | R6: price | S6: max
A7: period | F7: MT or BCM | G7: MT or BCF | H7: % | I7: mRs/mT or kRs/BCM | J7: % | K7: mRs/mT ork Rs/BCM | L7: mRs/mT or kRs/BCM | M7: % | N7: mRs/mT or kRs/BCM | P7: mRs/MWh | Q7: MWh | R7: mRs/mWh
A8: 1 | B8: BIOMASS | C8: INDIA | E8: =_xlfn.XLOOKUP(A8,PeriodMap!$A$2:$A$45,PeriodMap!$B$2:$B$45) -> 2023 | F8: =_xlfn.XLOOKUP(_xlfn.CONCAT($B8,$D8,$E8),PEC_ProdImpConstraints!$G$2:$G$286,PEC_ProdImpConstraints!$E$2:$E$286) -> 270 | G8: =_xlfn.XLOOKUP(_xlfn.CONCAT($B8,$D8,$E8),PEC_ProdImpConstraints!$G$2:$G$286,PEC_ProdImpConstraints!$F$2:$F$286) -> 0 | H8: =_xlfn.XLOOKUP(_xlfn.CONCAT($B8,$D8,$E8),PEC_Info!$L$2:$L$301,PEC_Info!$E$2:$E$301) -> 0 | I8: =_xlfn.XLOOKUP(_xlfn.CONCAT($B8,$D8,$E8),PEC_Info!$L$2:$L$301,PEC_Info!$F$2:$F$301) -> 5449.5727 | J8: =_xlfn.XLOOKUP(_xlfn.CONCAT($B8,$D8,$E8),PEC_Info!$L$2:$L$301,PEC_Info!$G$2:$G$301) -> 0 | K8: =_xlfn.XLOOKUP(_xlfn.CONCAT($B8,$D8,$E8),PEC_Info!$L$2:$L$301,PEC_Info!$H$2:$H$301) -> 0 | L8: =_xlfn.XLOOKUP(_xlfn.CONCAT($B8,$D8,$E8),PEC_Info!$L$2:$L$301,PEC_Info!$I$2:$I$301) -> 5449.5727 | M8: =_xlfn.XLOOKUP(_xlfn.CONCAT($B8,$D8,$E8),PEC_Info!$L$2:$L$301,PEC_Info!$J$2:$J$301) -> 0 | N8: =_xlfn.XLOOKUP(_xlfn.CONCAT($B8,$D8,$E8),PEC_Info!$L$2:$L$301,PEC_Info!$K$2:$K$301) -> 0 | P8: =(I8*(1+J8)+K8*1000)/_xlfn.XLOOKUP(B8,CarriersTech_characteristics!$B$2:$B$8,CarriersTech_characteristics!$G$2:$G$8)/Conversions!$D$2 -> 0.0012608266 | Q8: =F8*_xlfn.XLOOKUP(B8,CarriersTech_characteristics!$B$2:$B$8,CarriersTech_characteristics!$G$2:$G$8)*Conversions!$D$2*(1-H8) -> 1.167e+09 | R8: =(L8*(1+M8)+N8*1000)/_xlfn.XLOOKUP(B8,CarriersTech_characteristics!$B$2:$B$8,CarriersTech_characteristics!$J$2:$J$8)/Conversions!$D$2 -> 0.0012608266 | S8: =G8*_xlfn.XLOOKUP(B8,CarriersTech_characteristics!$B$2:$B$8,CarriersTech_characteristics!$J$2:$J$8)*Conversions!$D$2 -> 0
A9: 1 | B9: BIOMASS_WASTE | C9: INDIA | E9: =_xlfn.XLOOKUP(A9,PeriodMap!$A$2:$A$45,PeriodMap!$B$2:$B$45) -> 2023 | F9: =_xlfn.XLOOKUP(_xlfn.CONCAT($B9,$D9,$E9),PEC_ProdImpConstraints!$G$2:$G$286,PEC_ProdImpConstraints!$E$2:$E$286) -> 175 | G9: =_xlfn.XLOOKUP(_xlfn.CONCAT($B9,$D9,$E9),PEC_ProdImpConstraints!$G$2:$G$286,PEC_ProdImpConstraints!$F$2:$F$286) -> 0 | H9: =_xlfn.XLOOKUP(_xlfn.CONCAT($B9,$D9,$E9),PEC_Info!$L$2:$L$301,PEC_Info!$E$2:$E$301) -> 0 | I9: =_xlfn.XLOOKUP(_xlfn.CONCAT($B9,$D9,$E9),PEC_Info!$L$2:$L$301,PEC_Info!$F$2:$F$301) -> 9000 | J9: =_xlfn.XLOOKUP(_xlfn.CONCAT($B9,$D9,$E9),PEC_Info!$L$2:$L$301,PEC_Info!$G$2:$G$301) -> 0.05 | K9: =_xlfn.XLOOKUP(_xlfn.CONCAT($B9,$D9,$E9),PEC_Info!$L$2:$L$301,PEC_Info!$H$2:$H$301) -> 0 | L9: =_xlfn.XLOOKUP(_xlfn.CONCAT($B9,$D9,$E9),PEC_Info!$L$2:$L$301,PEC_Info!$I$2:$I$301) -> 9000 | M9: =_xlfn.XLOOKUP(_xlfn.CONCAT($B9,$D9,$E9),PEC_Info!$L$2:$L$301,PEC_Info!$J$2:$J$301) -> 0.05 | N9: =_xlfn.XLOOKUP(_xlfn.CONCAT($B9,$D9,$E9),PEC_Info!$L$2:$L$301,PEC_Info!$K$2:$K$301) -> 0 | P9: =(I9*(1+J9)+K9*1000)/_xlfn.XLOOKUP(B9,CarriersTech_characteristics!$B$2:$B$8,CarriersTech_characteristics!$G$2:$G$8)/Conversions!$D$2 -> 0.0024924961 | Q9: =F9*_xlfn.XLOOKUP(B9,CarriersTech_characteristics!$B$2:$B$8,CarriersTech_characteristics!$G$2:$G$8)*Conversions!$D$2*(1-H9) -> 6.6349151e+08 | R9: =(L9*(1+M9)+N9*1000)/_xlfn.XLOOKUP(B9,CarriersTech_characteristics!$B$2:$B$8,CarriersTech_characteristics!$J$2:$J$8)/Conversions!$D$2 -> 0.0024924961 | S9: =G9*_xlfn.XLOOKUP(B9,CarriersTech_characteristics!$B$2:$B$8,CarriersTech_characteristics!$J$2:$J$8)*Conversions!$D$2 -> 0
A10: 1 | B10: NATGAS | C10: INDIA | E10: =_xlfn.XLOOKUP(A10,PeriodMap!$A$2:$A$45,PeriodMap!$B$2:$B$45) -> 2023 | F10: =_xlfn.XLOOKUP(_xlfn.CONCAT($B10,$D10,$E10),PEC_ProdImpConstraints!$G$2:$G$286,PEC_ProdImpConstraints!$E$2:$E$286) -> 33.648 | G10: =_xlfn.XLOOKUP(_xlfn.CONCAT($B10,$D10,$E10),PEC_ProdImpConstraints!$G$2:$G$286,PEC_ProdImpConstraints!$F$2:$F$286) -> 200 | H10: =_xlfn.XLOOKUP(_xlfn.CONCAT($B10,$D10,$E10),PEC_Info!$L$2:$L$301,PEC_Info!$E$2:$E$301) -> 0.36749121 | I10: =_xlfn.XLOOKUP(_xlfn.CONCAT($B10,$D10,$E10),PEC_Info!$L$2:$L$301,PEC_Info!$F$2:$F$301) -> 23859.031 | J10: =_xlfn.XLOOKUP(_xlfn.CONCAT($B10,$D10,$E10),PEC_Info!$L$2:$L$301,PEC_Info!$G$2:$G$301) -> 0.24 | K10: =_xlfn.XLOOKUP(_xlfn.CONCAT($B10,$D10,$E10),PEC_Info!$L$2:$L$301,PEC_Info!$H$2:$H$301) -> 0 | L10: =_xlfn.XLOOKUP(_xlfn.CONCAT($B10,$D10,$E10),PEC_Info!$L$2:$L$301,PEC_Info!$I$2:$I$301) -> 54880.306 | M10: =_xlfn.XLOOKUP(_xlfn.CONCAT($B10,$D10,$E10),PEC_Info!$L$2:$L$301,PEC_Info!$J$2:$J$301) -> 0.349 | N10: =_xlfn.XLOOKUP(_xlfn.CONCAT($B10,$D10,$E10),PEC_Info!$L$2:$L$301,PEC_Info!$K$2:$K$301) -> 0 | P10: =(I10*(1+J10)+K10*1000)/Conversions!$D$3/_xlfn.XLOOKUP(B10,CarriersTech_characteristics!$B$2:$B$8,CarriersTech_characteristics!$G$2:$G$8)/Conversions!$D$2 -> 0.0034095552 | Q10: =F10*_xlfn.XLOOKUP(B10,CarriersTech_characteristics!$B$2:$B$8,CarriersTech_characteristics!$G$2:$G$8)*Conversions!$D$2*(1-H10) -> 2.2276556e+08 | R10: =(L10*(1+M10)+N10*1000)/Conversions!$D$3/_xlfn.XLOOKUP(B10,CarriersTech_characteristics!$B$2:$B$8,CarriersTech_characteristics!$J$2:$J$8)/Conversions!$D$2 -> 0.008532017 | S10: =G10*_xlfn.XLOOKUP(B10,CarriersTech_characteristics!$B$2:$B$8,CarriersTech_characteristics!$J$2:$J$8)*Conversions!$D$2 -> 2.0934e+09
A11: 1 | B11: THERMAL_COAL | C11: INDIA | D11: NR | E11: =_xlfn.XLOOKUP(A11,PeriodMap!$A$2:$A$45,PeriodMap!$B$2:$B$45) -> 2023 | F11: =_xlfn.XLOOKUP(_xlfn.CONCAT($B11,$D11,$E11),PEC_ProdImpConstraints!$G$2:$G$286,PEC_ProdImpConstraints!$E$2:$E$286) -> 30.747 | G11: =_xlfn.XLOOKUP(_xlfn.CONCAT($B11,$D11,$E11),PEC_ProdImpConstraints!$G$2:$G$286,PEC_ProdImpConstraints!$F$2:$F$286) -> 0 | H11: =_xlfn.XLOOKUP(_xlfn.CONCAT($B11,$D11,$E11),PEC_Info!$L$2:$L$301,PEC_Info!$E$2:$E$301) -> 0 | I11: =_xlfn.XLOOKUP(_xlfn.CONCAT($B11,$D11,$E11),PEC_Info!$L$2:$L$301,PEC_Info!$F$2:$F$301) -> 1156.3734 | J11: =_xlfn.XLOOKUP(_xlfn.CONCAT($B11,$D11,$E11),PEC_Info!$L$2:$L$301,PEC_Info!$G$2:$G$301) -> 0.3508 | K11: =_xlfn.XLOOKUP(_xlfn.CONCAT($B11,$D11,$E11),PEC_Info!$L$2:$L$301,PEC_Info!$H$2:$H$301) -> 0 | L11: =_xlfn.XLOOKUP(_xlfn.CONCAT($B11,$D11,$E11),PEC_Info!$L$2:$L$301,PEC_Info!$I$2:$I$301) -> 13197.141 | M11: =_xlfn.XLOOKUP(_xlfn.CONCAT($B11,$D11,$E11),PEC_Info!$L$2:$L$301,PEC_Info!$J$2:$J$301) -> 0.205 | N11: =_xlfn.XLOOKUP(_xlfn.CONCAT($B11,$D11,$E11),PEC_Info!$L$2:$L$301,PEC_Info!$K$2:$K$301) -> 0 | P11: =(I11*(1+J11)+K11*1000)/_xlfn.XLOOKUP(B11,CarriersTech_characteristics!$B$2:$B$8,CarriersTech_characteristics!$G$2:$G$8)/Conversions!$D$2 -> 0.00032679978 | Q11: =F11*_xlfn.XLOOKUP(B11,CarriersTech_characteristics!$B$2:$B$8,CarriersTech_characteristics!$G$2:$G$8)*Conversions!$D$2*(1-H11) -> 1.4696372e+08 | R11: =(L11*(1+M11)+N11*1000)/_xlfn.XLOOKUP(B11,CarriersTech_characteristics!$B$2:$B$8,CarriersTech_characteristics!$J$2:$J$8)/Conversions!$D$2 -> 0.0025321733 | S11: =G11*_xlfn.XLOOKUP(B11,CarriersTech_characteristics!$B$2:$B$8,CarriersTech_characteristics!$J$2:$J$8)*Conversions!$D$2 -> 0
A12: 1 | B12: THERMAL_COAL | C12: INDIA | D12: NER | E12: =_xlfn.XLOOKUP(A12,PeriodMap!$A$2:$A$45,PeriodMap!$B$2:$B$45) -> 2023 | F12: =_xlfn.XLOOKUP(_xlfn.CONCAT($B12,$D12,$E12),PEC_ProdImpConstraints!$G$2:$G$286,PEC_ProdImpConstraints!$E$2:$E$286) -> 0 | G12: =_xlfn.XLOOKUP(_xlfn.CONCAT($B12,$D12,$E12),PEC_ProdImpConstraints!$G$2:$G$286,PEC_ProdImpConstraints!$F$2:$F$286) -> 0 | H12: =_xlfn.XLOOKUP(_xlfn.CONCAT($B12,$D12,$E12),PEC_Info!$L$2:$L$301,PEC_Info!$E$2:$E$301) -> 0 | I12: =_xlfn.XLOOKUP(_xlfn.CONCAT($B12,$D12,$E12),PEC_Info!$L$2:$L$301,PEC_Info!$F$2:$F$301) -> 1156.3734 | J12: =_xlfn.XLOOKUP(_xlfn.CONCAT($B12,$D12,$E12),PEC_Info!$L$2:$L$301,PEC_Info!$G$2:$G$301) -> 0.3508 | K12: =_xlfn.XLOOKUP(_xlfn.CONCAT($B12,$D12,$E12),PEC_Info!$L$2:$L$301,PEC_Info!$H$2:$H$301) -> 0 | L12: =_xlfn.XLOOKUP(_xlfn.CONCAT($B12,$D12,$E12),PEC_Info!$L$2:$L$301,PEC_Info!$I$2:$I$301) -> 13197.141 | M12: =_xlfn.XLOOKUP(_xlfn.CONCAT($B12,$D12,$E12),PEC_Info!$L$2:$L$301,PEC_Info!$J$2:$J$301) -> 0.205 | N12: =_xlfn.XLOOKUP(_xlfn.CONCAT($B12,$D12,$E12),PEC_Info!$L$2:$L$301,PEC_Info!$K$2:$K$301) -> 0 | P12: =(I12*(1+J12)+K12*1000)/_xlfn.XLOOKUP(B12,CarriersTech_characteristics!$B$2:$B$8,CarriersTech_characteristics!$G$2:$G$8)/Conversions!$D$2 -> 0.00032679978 | Q12: =F12*_xlfn.XLOOKUP(B12,CarriersTech_characteristics!$B$2:$B$8,CarriersTech_characteristics!$G$2:$G$8)*Conversions!$D$2*(1-H12) -> 0 | R12: =(L12*(1+M12)+N12*1000)/_xlfn.XLOOKUP(B12,CarriersTech_characteristics!$B$2:$B$8,CarriersTech_characteristics!$J$2:$J$8)/Conversions!$D$2 -> 0.0025321733 | S12: =G12*_xlfn.XLOOKUP(B12,CarriersTech_characteristics!$B$2:$B$8,CarriersTech_characteristics!$J$2:$J$8)*Conversions!$D$2 -> 0
A13: 1 | B13: THERMAL_COAL | C13: INDIA | D13: ER | E13: =_xlfn.XLOOKUP(A13,PeriodMap!$A$2:$A$45,PeriodMap!$B$2:$B$45) -> 2023 | F13: =_xlfn.XLOOKUP(_xlfn.CONCAT($B13,$D13,$E13),PEC_ProdImpConstraints!$G$2:$G$286,PEC_ProdImpConstraints!$E$2:$E$286) -> 395.289 | G13: =_xlfn.XLOOKUP(_xlfn.CONCAT($B13,$D13,$E13),PEC_ProdImpConstraints!$G$2:$G$286,PEC_ProdImpConstraints!$F$2:$F$286) -> 150 | H13: =_xlfn.XLOOKUP(_xlfn.CONCAT($B13,$D13,$E13),PEC_Info!$L$2:$L$301,PEC_Info!$E$2:$E$301) -> 0 | I13: =_xlfn.XLOOKUP(_xlfn.CONCAT($B13,$D13,$E13),PEC_Info!$L$2:$L$301,PEC_Info!$F$2:$F$301) -> 1156.3734 | J13: =_xlfn.XLOOKUP(_xlfn.CONCAT($B13,$D13,$E13),PEC_Info!$L$2:$L$301,PEC_Info!$G$2:$G$301) -> 0.3508 | K13: =_xlfn.XLOOKUP(_xlfn.CONCAT($B13,$D13,$E13),PEC_Info!$L$2:$L$301,PEC_Info!$H$2:$H$301) -> 0 | L13: =_xlfn.XLOOKUP(_xlfn.CONCAT($B13,$D13,$E13),PEC_Info!$L$2:$L$301,PEC_Info!$I$2:$I$301) -> 13197.141 | M13: =_xlfn.XLOOKUP(_xlfn.CONCAT($B13,$D13,$E13),PEC_Info!$L$2:$L$301,PEC_Info!$J$2:$J$301) -> 0.205 | N13: =_xlfn.XLOOKUP(_xlfn.CONCAT($B13,$D13,$E13),PEC_Info!$L$2:$L$301,PEC_Info!$K$2:$K$301) -> 0 | P13: =(I13*(1+J13)+K13*1000)/_xlfn.XLOOKUP(B13,CarriersTech_characteristics!$B$2:$B$8,CarriersTech_characteristics!$G$2:$G$8)/Conversions!$D$2 -> 0.00032679978 | Q13: =F13*_xlfn.XLOOKUP(B13,CarriersTech_characteristics!$B$2:$B$8,CarriersTech_characteristics!$G$2:$G$8)*Conversions!$D$2*(1-H13) -> 1.8893922e+09 | R13: =(L13*(1+M13)+N13*1000)/_xlfn.XLOOKUP(B13,CarriersTech_characteristics!$B$2:$B$8,CarriersTech_characteristics!$J$2:$J$8)/Conversions!$D$2 -> 0.0025321733 | S13: =G13*_xlfn.XLOOKUP(B13,CarriersTech_characteristics!$B$2:$B$8,CarriersTech_characteristics!$J$2:$J$8)*Conversions!$D$2 -> 9.4203001e+08
A14: 1 | B14: THERMAL_COAL | C14: INDIA | D14: WR | E14: =_xlfn.XLOOKUP(A14,PeriodMap!$A$2:$A$45,PeriodMap!$B$2:$B$45) -> 2023 | F14: =_xlfn.XLOOKUP(_xlfn.CONCAT($B14,$D14,$E14),PEC_ProdImpConstraints!$G$2:$G$286,PEC_ProdImpConstraints!$E$2:$E$286) -> 406.857 | G14: =_xlfn.XLOOKUP(_xlfn.CONCAT($B14,$D14,$E14),PEC_ProdImpConstraints!$G$2:$G$286,PEC_ProdImpConstraints!$F$2:$F$286) -> 150 | H14: =_xlfn.XLOOKUP(_xlfn.CONCAT($B14,$D14,$E14),PEC_Info!$L$2:$L$301,PEC_Info!$E$2:$E$301) -> 0 | I14: =_xlfn.XLOOKUP(_xlfn.CONCAT($B14,$D14,$E14),PEC_Info!$L$2:$L$301,PEC_Info!$F$2:$F$301) -> 1156.3734 | J14: =_xlfn.XLOOKUP(_xlfn.CONCAT($B14,$D14,$E14),PEC_Info!$L$2:$L$301,PEC_Info!$G$2:$G$301) -> 0.3508 | K14: =_xlfn.XLOOKUP(_xlfn.CONCAT($B14,$D14,$E14),PEC_Info!$L$2:$L$301,PEC_Info!$H$2:$H$301) -> 0 | L14: =_xlfn.XLOOKUP(_xlfn.CONCAT($B14,$D14,$E14),PEC_Info!$L$2:$L$301,PEC_Info!$I$2:$I$301) -> 13197.141 | M14: =_xlfn.XLOOKUP(_xlfn.CONCAT($B14,$D14,$E14),PEC_Info!$L$2:$L$301,PEC_Info!$J$2:$J$301) -> 0.205 | N14: =_xlfn.XLOOKUP(_xlfn.CONCAT($B14,$D14,$E14),PEC_Info!$L$2:$L$301,PEC_Info!$K$2:$K$301) -> 0 | P14: =(I14*(1+J14)+K14*1000)/_xlfn.XLOOKUP(B14,CarriersTech_characteristics!$B$2:$B$8,CarriersTech_characteristics!$G$2:$G$8)/Conversions!$D$2 -> 0.00032679978 | Q14: =F14*_xlfn.XLOOKUP(B14,CarriersTech_characteristics!$B$2:$B$8,CarriersTech_characteristics!$G$2:$G$8)*Conversions!$D$2*(1-H14) -> 1.9446847e+09 | R14: =(L14*(1+M14)+N14*1000)/_xlfn.XLOOKUP(B14,CarriersTech_characteristics!$B$2:$B$8,CarriersTech_characteristics!$J$2:$J$8)/Conversions!$D$2 -> 0.0025321733 | S14: =G14*_xlfn.XLOOKUP(B14,CarriersTech_characteristics!$B$2:$B$8,CarriersTech_characteristics!$J$2:$J$8)*Conversions!$D$2 -> 9.4203001e+08
A15: 1 | B15: THERMAL_COAL | C15: INDIA | D15: SR | E15: =_xlfn.XLOOKUP(A15,PeriodMap!$A$2:$A$45,PeriodMap!$B$2:$B$45) -> 2023 | F15: =_xlfn.XLOOKUP(_xlfn.CONCAT($B15,$D15,$E15),PEC_ProdImpConstraints!$G$2:$G$286,PEC_ProdImpConstraints!$E$2:$E$286) -> 91.156 | G15: =_xlfn.XLOOKUP(_xlfn.CONCAT($B15,$D15,$E15),PEC_ProdImpConstraints!$G$2:$G$286,PEC_ProdImpConstraints!$F$2:$F$286) -> 150 | H15: =_xlfn.XLOOKUP(_xlfn.CONCAT($B15,$D15,$E15),PEC_Info!$L$2:$L$301,PEC_Info!$E$2:$E$301) -> 0 | I15: =_xlfn.XLOOKUP(_xlfn.CONCAT($B15,$D15,$E15),PEC_Info!$L$2:$L$301,PEC_Info!$F$2:$F$301) -> 1156.3734 | J15: =_xlfn.XLOOKUP(_xlfn.CONCAT($B15,$D15,$E15),PEC_Info!$L$2:$L$301,PEC_Info!$G$2:$G$301) -> 0.3508 | K15: =_xlfn.XLOOKUP(_xlfn.CONCAT($B15,$D15,$E15),PEC_Info!$L$2:$L$301,PEC_Info!$H$2:$H$301) -> 0 | L15: =_xlfn.XLOOKUP(_xlfn.CONCAT($B15,$D15,$E15),PEC_Info!$L$2:$L$301,PEC_Info!$I$2:$I$301) -> 13197.141 | M15: =_xlfn.XLOOKUP(_xlfn.CONCAT($B15,$D15,$E15),PEC_Info!$L$2:$L$301,PEC_Info!$J$2:$J$301) -> 0.205 | N15: =_xlfn.XLOOKUP(_xlfn.CONCAT($B15,$D15,$E15),PEC_Info!$L$2:$L$301,PEC_Info!$K$2:$K$301) -> 0 | P15: =(I15*(1+J15)+K15*1000)/_xlfn.XLOOKUP(B15,CarriersTech_characteristics!$B$2:$B$8,CarriersTech_characteristics!$G$2:$G$8)/Conversions!$D$2 -> 0.00032679978 | Q15: =F15*_xlfn.XLOOKUP(B15,CarriersTech_characteristics!$B$2:$B$8,CarriersTech_characteristics!$G$2:$G$8)*Conversions!$D$2*(1-H15) -> 4.3570511e+08 | R15: =(L15*(1+M15)+N15*1000)/_xlfn.XLOOKUP(B15,CarriersTech_characteristics!$B$2:$B$8,CarriersTech_characteristics!$J$2:$J$8)/Conversions!$D$2 -> 0.0025321733 | S15: =G15*_xlfn.XLOOKUP(B15,CarriersTech_characteristics!$B$2:$B$8,CarriersTech_characteristics!$J$2:$J$8)*Conversions!$D$2 -> 9.4203001e+08
A16: 1 | B16: THERMAL_COAL | C16: INDIA | D16: ALL | E16: =_xlfn.XLOOKUP(A16,PeriodMap!$A$2:$A$45,PeriodMap!$B$2:$B$45) -> 2023 | F16: =SUM(F11:F15) -> 924.049 | G16: =SUM(G11:G15) -> 450 | H16: =AVERAGE(H11:H15) -> 0 | I16: =AVERAGE(I11:I15) -> 1156.3734 | J16: =AVERAGE(J11:J15) -> 0.3508 | K16: =AVERAGE(K11:K15) -> 0 | L16: =AVERAGE(L11:L15) -> 13197.141 | M16: =AVERAGE(M11:M15) -> 0.205 | N16: =AVERAGE(N11:N15) -> 0 | P16: =AVERAGE(P11:P15) -> 0.00032679978 | Q16: =SUM(Q11:Q15) -> 4.4167457e+09 | R16: =AVERAGE(R11:R15) -> 0.0025321733 | S16: =SUM(S11:S15) -> 2.82609e+09
A17: 1 | B17: CRUDE | C17: INDIA | E17: =_xlfn.XLOOKUP(A17,PeriodMap!$A$2:$A$45,PeriodMap!$B$2:$B$45) -> 2023 | F17: =_xlfn.XLOOKUP(_xlfn.CONCAT($B17,$D17,$E17),PEC_ProdImpConstraints!$G$2:$G$286,PEC_ProdImpConstraints!$E$2:$E$286) -> 31.9035 | G17: =_xlfn.XLOOKUP(_xlfn.CONCAT($B17,$D17,$E17),PEC_ProdImpConstraints!$G$2:$G$286,PEC_ProdImpConstraints!$F$2:$F$286) -> 330 | H17: 0 | I17: =_xlfn.XLOOKUP(_xlfn.CONCAT($B17,$D17,$E17),PEC_Info!$L$2:$L$301,PEC_Info!$F$2:$F$301) -> 57833.373 | J17: =_xlfn.XLOOKUP(_xlfn.CONCAT($B17,$D17,$E17),PEC_Info!$L$2:$L$301,PEC_Info!$G$2:$G$301) -> 0 | K17: =_xlfn.XLOOKUP(_xlfn.CONCAT($B17,$D17,$E17),PEC_Info!$L$2:$L$301,PEC_Info!$H$2:$H$301) -> 51.2 | L17: =_xlfn.XLOOKUP(_xlfn.CONCAT($B17,$D17,$E17),PEC_Info!$L$2:$L$301,PEC_Info!$I$2:$I$301) -> 56505.275 | M17: =_xlfn.XLOOKUP(_xlfn.CONCAT($B17,$D17,$E17),PEC_Info!$L$2:$L$301,PEC_Info!$J$2:$J$301) -> 0 | N17: =_xlfn.XLOOKUP(_xlfn.CONCAT($B17,$D17,$E17),PEC_Info!$L$2:$L$301,PEC_Info!$K$2:$K$301) -> 57.2 | P17: =(I17*(1+J17)+K17*1000)/_xlfn.XLOOKUP(B17,CarriersTech_characteristics!$B$2:$B$8,CarriersTech_characteristics!$G$2:$G$8)/Conversions!$D$2 -> 0.0091021189 | Q17: =F17*_xlfn.XLOOKUP(B17,CarriersTech_characteristics!$B$2:$B$8,CarriersTech_characteristics!$G$2:$G$8)*Conversions!$D$2*(1-H17) -> 3.8216884e+08 | R17: =(L17*(1+M17)+N17*1000)/_xlfn.XLOOKUP(B17,CarriersTech_characteristics!$B$2:$B$8,CarriersTech_characteristics!$J$2:$J$8)/Conversions!$D$2 -> 0.0094921299 | S17: =G17*_xlfn.XLOOKUP(B17,CarriersTech_characteristics!$B$2:$B$8,CarriersTech_characteristics!$J$2:$J$8)*Conversions!$D$2 -> 3.953037e+09
A18: 1 | B18: BIOGAS | C18: INDIA | E18: =_xlfn.XLOOKUP(A18,PeriodMap!$A$2:$A$45,PeriodMap!$B$2:$B$45) -> 2023 | F18: =_xlfn.XLOOKUP(_xlfn.CONCAT($B18,$D18,$E18),PEC_ProdImpConstraints!$G$2:$G$286,PEC_ProdImpConstraints!$E$2:$E$286) -> 87 | G18: =_xlfn.XLOOKUP(_xlfn.CONCAT($B18,$D18,$E18),PEC_ProdImpConstraints!$G$2:$G$286,PEC_ProdImpConstraints!$F$2:$F$286) -> 0 | H18: 0 | I18: =_xlfn.XLOOKUP(_xlfn.CONCAT($B18,$D18,$E18),PEC_Info!$L$2:$L$301,PEC_Info!$F$2:$F$301) -> 49802.018 | J18: =_xlfn.XLOOKUP(_xlfn.CONCAT($B18,$D18,$E18),PEC_Info!$L$2:$L$301,PEC_Info!$G$2:$G$301) -> 0.05 | K18: =_xlfn.XLOOKUP(_xlfn.CONCAT($B18,$D18,$E18),PEC_Info!$L$2:$L$301,PEC_Info!$H$2:$H$301) -> 0 | L18: =_xlfn.XLOOKUP(_xlfn.CONCAT($B18,$D18,$E18),PEC_Info!$L$2:$L$301,PEC_Info!$I$2:$I$301) -> 49802.018 | M18: =_xlfn.XLOOKUP(_xlfn.CONCAT($B18,$D18,$E18),PEC_Info!$L$2:$L$301,PEC_Info!$J$2:$J$301) -> 0.05 | N18: =_xlfn.XLOOKUP(_xlfn.CONCAT($B18,$D18,$E18),PEC_Info!$L$2:$L$301,PEC_Info!$K$2:$K$301) -> 0 | P18: =(I18*(1+J18)+K18*1000)/Conversions!$D$3/_xlfn.XLOOKUP(B18,CarriersTech_characteristics!$B$2:$B$8,CarriersTech_characteristics!$G$2:$G$8)/Conversions!$D$2 -> 0.0099597712 | Q18: =F18*_xlfn.XLOOKUP(B18,CarriersTech_characteristics!$B$2:$B$8,CarriersTech_characteristics!$G$2:$G$8)*Conversions!$D$2*(1-H18) -> 5.51e+08 | R18: =(L18*(1+M18)+N18*1000)/Conversions!$D$3/_xlfn.XLOOKUP(B18,CarriersTech_characteristics!$B$2:$B$8,CarriersTech_characteristics!$J$2:$J$8)/Conversions!$D$2 -> 0.0099597712 | S18: =G18*_xlfn.XLOOKUP(B18,CarriersTech_characteristics!$B$2:$B$8,CarriersTech_characteristics!$J$2:$J$8)*Conversions!$D$2 -> 0
A19: 1 | B19: COKING_COAL | C19: INDIA | D19: ER | E19: =_xlfn.XLOOKUP(A19,PeriodMap!$A$2:$A$45,PeriodMap!$B$2:$B$45) -> 2023 | F19: =_xlfn.XLOOKUP(_xlfn.CONCAT($B19,$D19,$E19),PEC_ProdImpConstraints!$G$2:$G$286,PEC_ProdImpConstraints!$E$2:$E$286) -> 12.971 | G19: =_xlfn.XLOOKUP(_xlfn.CONCAT($B19,$D19,$E19),PEC_ProdImpConstraints!$G$2:$G$286,PEC_ProdImpConstraints!$F$2:$F$286) -> 100 | H19: 0 | I19: =_xlfn.XLOOKUP(_xlfn.CONCAT($B19,$D19,$E19),PEC_Info!$L$2:$L$301,PEC_Info!$F$2:$F$301) -> 2789.0369 | J19: =_xlfn.XLOOKUP(_xlfn.CONCAT($B19,$D19,$E19),PEC_Info!$L$2:$L$301,PEC_Info!$G$2:$G$301) -> 0.3508 | K19: =_xlfn.XLOOKUP(_xlfn.CONCAT($B19,$D19,$E19),PEC_Info!$L$2:$L$301,PEC_Info!$H$2:$H$301) -> 0 | L19: =_xlfn.XLOOKUP(_xlfn.CONCAT($B19,$D19,$E19),PEC_Info!$L$2:$L$301,PEC_Info!$I$2:$I$301) -> 28632.348 | M19: =_xlfn.XLOOKUP(_xlfn.CONCAT($B19,$D19,$E19),PEC_Info!$L$2:$L$301,PEC_Info!$J$2:$J$301) -> 0.205 | N19: =_xlfn.XLOOKUP(_xlfn.CONCAT($B19,$D19,$E19),PEC_Info!$L$2:$L$301,PEC_Info!$K$2:$K$301) -> 0 | P19: =(I19*(1+J19)+K19*1000)/_xlfn.XLOOKUP(B19,CarriersTech_characteristics!$B$2:$B$8,CarriersTech_characteristics!$G$2:$G$8)/Conversions!$D$2 -> 0.00065980588 | Q19: =F19*_xlfn.XLOOKUP(B19,CarriersTech_characteristics!$B$2:$B$8,CarriersTech_characteristics!$G$2:$G$8)*Conversions!$D$2*(1-H19) -> 74063219 | R19: =(L19*(1+M19)+N19*1000)/_xlfn.XLOOKUP(B19,CarriersTech_characteristics!$B$2:$B$8,CarriersTech_characteristics!$J$2:$J$8)/Conversions!$D$2 -> 0.0051369302 | S19: =G19*_xlfn.XLOOKUP(B19,CarriersTech_characteristics!$B$2:$B$8,CarriersTech_characteristics!$J$2:$J$8)*Conversions!$D$2 -> 6.7164587e+08
A20: 1 | B20: COKING_COAL | C20: INDIA | D20: WR | E20: =_xlfn.XLOOKUP(A20,PeriodMap!$A$2:$A$45,PeriodMap!$B$2:$B$45) -> 2023 | F20: =_xlfn.XLOOKUP(_xlfn.CONCAT($B20,$D20,$E20),PEC_ProdImpConstraints!$G$2:$G$286,PEC_ProdImpConstraints!$E$2:$E$286) -> 0 | G20: =_xlfn.XLOOKUP(_xlfn.CONCAT($B20,$D20,$E20),PEC_ProdImpConstraints!$G$2:$G$286,PEC_ProdImpConstraints!$F$2:$F$286) -> 100 | H20: 0 | I20: =_xlfn.XLOOKUP(_xlfn.CONCAT($B20,$D20,$E20),PEC_Info!$L$2:$L$301,PEC_Info!$F$2:$F$301) -> 2789.0369 | J20: =_xlfn.XLOOKUP(_xlfn.CONCAT($B20,$D20,$E20),PEC_Info!$L$2:$L$301,PEC_Info!$G$2:$G$301) -> 0.3508 | K20: =_xlfn.XLOOKUP(_xlfn.CONCAT($B20,$D20,$E20),PEC_Info!$L$2:$L$301,PEC_Info!$H$2:$H$301) -> 0 | L20: =_xlfn.XLOOKUP(_xlfn.CONCAT($B20,$D20,$E20),PEC_Info!$L$2:$L$301,PEC_Info!$I$2:$I$301) -> 28632.348 | M20: =_xlfn.XLOOKUP(_xlfn.CONCAT($B20,$D20,$E20),PEC_Info!$L$2:$L$301,PEC_Info!$J$2:$J$301) -> 0.205 | N20: =_xlfn.XLOOKUP(_xlfn.CONCAT($B20,$D20,$E20),PEC_Info!$L$2:$L$301,PEC_Info!$K$2:$K$301) -> 0 | P20: =(I20*(1+J20)+K20*1000)/_xlfn.XLOOKUP(B20,CarriersTech_characteristics!$B$2:$B$8,CarriersTech_characteristics!$G$2:$G$8)/Conversions!$D$2 -> 0.00065980588 | Q20: =F20*_xlfn.XLOOKUP(B20,CarriersTech_characteristics!$B$2:$B$8,CarriersTech_characteristics!$G$2:$G$8)*Conversions!$D$2*(1-H20) -> 0 | R20: =(L20*(1+M20)+N20*1000)/_xlfn.XLOOKUP(B20,CarriersTech_characteristics!$B$2:$B$8,CarriersTech_characteristics!$J$2:$J$8)/Conversions!$D$2 -> 0.0051369302 | S20: =G20*_xlfn.XLOOKUP(B20,CarriersTech_characteristics!$B$2:$B$8,CarriersTech_characteristics!$J$2:$J$8)*Conversions!$D$2 -> 6.7164587e+08
A21: 1 | B21: COKING_COAL | C21: INDIA | D21: NR | E21: =_xlfn.XLOOKUP(A21,PeriodMap!$A$2:$A$45,PeriodMap!$B$2:$B$45) -> 2023 | F21: =_xlfn.XLOOKUP(_xlfn.CONCAT($B21,$D21,$E21),PEC_ProdImpConstraints!$G$2:$G$286,PEC_ProdImpConstraints!$E$2:$E$286) -> 0 | G21: =_xlfn.XLOOKUP(_xlfn.CONCAT($B21,$D21,$E21),PEC_ProdImpConstraints!$G$2:$G$286,PEC_ProdImpConstraints!$F$2:$F$286) -> 0 | H21: 0 | I21: =_xlfn.XLOOKUP(_xlfn.CONCAT($B21,$D21,$E21),PEC_Info!$L$2:$L$301,PEC_Info!$F$2:$F$301) -> 2789.0369 | J21: =_xlfn.XLOOKUP(_xlfn.CONCAT($B21,$D21,$E21),PEC_Info!$L$2:$L$301,PEC_Info!$G$2:$G$301) -> 0.3508 | K21: =_xlfn.XLOOKUP(_xlfn.CONCAT($B21,$D21,$E21),PEC_Info!$L$2:$L$301,PEC_Info!$H$2:$H$301) -> 0 | L21: =_xlfn.XLOOKUP(_xlfn.CONCAT($B21,$D21,$E21),PEC_Info!$L$2:$L$301,PEC_Info!$I$2:$I$301) -> 28632.348 | M21: =_xlfn.XLOOKUP(_xlfn.CONCAT($B21,$D21,$E21),PEC_Info!$L$2:$L$301,PEC_Info!$J$2:$J$301) -> 0.205 | N21: =_xlfn.XLOOKUP(_xlfn.CONCAT($B21,$D21,$E21),PEC_Info!$L$2:$L$301,PEC_Info!$K$2:$K$301) -> 0 | P21: =(I21*(1+J21)+K21*1000)/_xlfn.XLOOKUP(B21,CarriersTech_characteristics!$B$2:$B$8,CarriersTech_characteristics!$G$2:$G$8)/Conversions!$D$2 -> 0.00065980588 | Q21: =F21*_xlfn.XLOOKUP(B21,CarriersTech_characteristics!$B$2:$B$8,CarriersTech_characteristics!$G$2:$G$8)*Conversions!$D$2*(1-H21) -> 0 | R21: =(L21*(1+M21)+N21*1000)/_xlfn.XLOOKUP(B21,CarriersTech_characteristics!$B$2:$B$8,CarriersTech_characteristics!$J$2:$J$8)/Conversions!$D$2 -> 0.0051369302 | S21: =G21*_xlfn.XLOOKUP(B21,CarriersTech_characteristics!$B$2:$B$8,CarriersTech_characteristics!$J$2:$J$8)*Conversions!$D$2 -> 0
A22: 1 | B22: COKING_COAL | C22: INDIA | D22: SR | E22: =_xlfn.XLOOKUP(A22,PeriodMap!$A$2:$A$45,PeriodMap!$B$2:$B$45) -> 2023 | F22: =_xlfn.XLOOKUP(_xlfn.CONCAT($B22,$D22,$E22),PEC_ProdImpConstraints!$G$2:$G$286,PEC_ProdImpConstraints!$E$2:$E$286) -> 0 | G22: =_xlfn.XLOOKUP(_xlfn.CONCAT($B22,$D22,$E22),PEC_ProdImpConstraints!$G$2:$G$286,PEC_ProdImpConstraints!$F$2:$F$286) -> 100 | H22: 0 | I22: =_xlfn.XLOOKUP(_xlfn.CONCAT($B22,$D22,$E22),PEC_Info!$L$2:$L$301,PEC_Info!$F$2:$F$301) -> 2789.0369 | J22: =_xlfn.XLOOKUP(_xlfn.CONCAT($B22,$D22,$E22),PEC_Info!$L$2:$L$301,PEC_Info!$G$2:$G$301) -> 0.3508 | K22: =_xlfn.XLOOKUP(_xlfn.CONCAT($B22,$D22,$E22),PEC_Info!$L$2:$L$301,PEC_Info!$H$2:$H$301) -> 0 | L22: =_xlfn.XLOOKUP(_xlfn.CONCAT($B22,$D22,$E22),PEC_Info!$L$2:$L$301,PEC_Info!$I$2:$I$301) -> 28632.348 | M22: =_xlfn.XLOOKUP(_xlfn.CONCAT($B22,$D22,$E22),PEC_Info!$L$2:$L$301,PEC_Info!$J$2:$J$301) -> 0.205 | N22: =_xlfn.XLOOKUP(_xlfn.CONCAT($B22,$D22,$E22),PEC_Info!$L$2:$L$301,PEC_Info!$K$2:$K$301) -> 0 | P22: =(I22*(1+J22)+K22*1000)/_xlfn.XLOOKUP(B22,CarriersTech_characteristics!$B$2:$B$8,CarriersTech_characteristics!$G$2:$G$8)/Conversions!$D$2 -> 0.00065980588 | Q22: =F22*_xlfn.XLOOKUP(B22,CarriersTech_characteristics!$B$2:$B$8,CarriersTech_characteristics!$G$2:$G$8)*Conversions!$D$2*(1-H22) -> 0 | R22: =(L22*(1+M22)+N22*1000)/_xlfn.XLOOKUP(B22,CarriersTech_characteristics!$B$2:$B$8,CarriersTech_characteristics!$J$2:$J$8)/Conversions!$D$2 -> 0.0051369302 | S22: =G22*_xlfn.XLOOKUP(B22,CarriersTech_characteristics!$B$2:$B$8,CarriersTech_characteristics!$J$2:$J$8)*Conversions!$D$2 -> 6.7164587e+08
A23: 1 | B23: COKING_COAL | C23: INDIA | D23: NER | E23: =_xlfn.XLOOKUP(A23,PeriodMap!$A$2:$A$45,PeriodMap!$B$2:$B$45) -> 2023 | F23: =_xlfn.XLOOKUP(_xlfn.CONCAT($B23,$D23,$E23),PEC_ProdImpConstraints!$G$2:$G$286,PEC_ProdImpConstraints!$E$2:$E$286) -> 0 | G23: =_xlfn.XLOOKUP(_xlfn.CONCAT($B23,$D23,$E23),PEC_ProdImpConstraints!$G$2:$G$286,PEC_ProdImpConstraints!$F$2:$F$286) -> 0 | H23: 0 | I23: =_xlfn.XLOOKUP(_xlfn.CONCAT($B23,$D23,$E23),PEC_Info!$L$2:$L$301,PEC_Info!$F$2:$F$301) -> 2789.0369 | J23: =_xlfn.XLOOKUP(_xlfn.CONCAT($B23,$D23,$E23),PEC_Info!$L$2:$L$301,PEC_Info!$G$2:$G$301) -> 0.3508 | K23: =_xlfn.XLOOKUP(_xlfn.CONCAT($B23,$D23,$E23),PEC_Info!$L$2:$L$301,PEC_Info!$H$2:$H$301) -> 0 | L23: =_xlfn.XLOOKUP(_xlfn.CONCAT($B23,$D23,$E23),PEC_Info!$L$2:$L$301,PEC_Info!$I$2:$I$301) -> 28632.348 | M23: =_xlfn.XLOOKUP(_xlfn.CONCAT($B23,$D23,$E23),PEC_Info!$L$2:$L$301,PEC_Info!$J$2:$J$301) -> 0.205 | N23: =_xlfn.XLOOKUP(_xlfn.CONCAT($B23,$D23,$E23),PEC_Info!$L$2:$L$301,PEC_Info!$K$2:$K$301) -> 0 | P23: =(I23*(1+J23)+K23*1000)/_xlfn.XLOOKUP(B23,CarriersTech_characteristics!$B$2:$B$8,CarriersTech_characteristics!$G$2:$G$8)/Conversions!$D$2 -> 0.00065980588 | Q23: =F23*_xlfn.XLOOKUP(B23,CarriersTech_characteristics!$B$2:$B$8,CarriersTech_characteristics!$G$2:$G$8)*Conversions!$D$2*(1-H23) -> 0 | R23: =(L23*(1+M23)+N23*1000)/_xlfn.XLOOKUP(B23,CarriersTech_characteristics!$B$2:$B$8,CarriersTech_characteristics!$J$2:$J$8)/Conversions!$D$2 -> 0.0051369302 | S23: =G23*_xlfn.XLOOKUP(B23,CarriersTech_characteristics!$B$2:$B$8,CarriersTech_characteristics!$J$2:$J$8)*Conversions!$D$2 -> 0
A24: 1 | B24: COKING_COAL | C24: INDIA | D24: ALL | E24: =_xlfn.XLOOKUP(A24,PeriodMap!$A$2:$A$45,PeriodMap!$B$2:$B$45) -> 2023 | F24: =SUM(F19:F23) -> 12.971 | G24: =SUM(G19:G23) -> 300 | H24: =AVERAGE(H19:H23) -> 0 | I24: =AVERAGE(I19:I23) -> 2789.0369 | J24: =AVERAGE(J19:J23) -> 0.3508 | K24: =AVERAGE(K19:K23) -> 0 | L24: =AVERAGE(L19:L23) -> 28632.348 | M24: =AVERAGE(M19:M23) -> 0.205 | N24: =AVERAGE(N19:N23) -> 0 | P24: =AVERAGE(P19:P23) -> 0.00065980588 | Q24: =SUM(Q19:Q23) -> 74063219 | R24: =AVERAGE(R19:R23) -> 0.0051369302 | S24: =SUM(S19:S23) -> 2.0149376e+09
A25: 2 | B25: BIOMASS | C25: INDIA | E25: =_xlfn.XLOOKUP(A25,PeriodMap!$A$2:$A$45,PeriodMap!$B$2:$B$45) -> 2024 | F25: =_xlfn.XLOOKUP(_xlfn.CONCAT($B25,$D25,$E25),PEC_ProdImpConstraints!$G$2:$G$286,PEC_ProdImpConstraints!$E$2:$E$286) -> 270 | G25: =_xlfn.XLOOKUP(_xlfn.CONCAT($B25,$D25,$E25),PEC_ProdImpConstraints!$G$2:$G$286,PEC_ProdImpConstraints!$F$2:$F$286) -> 0 | H25: =_xlfn.XLOOKUP(_xlfn.CONCAT($B25,$D25,$E25),PEC_Info!$L$2:$L$301,PEC_Info!$E$2:$E$301) -> 0 | I25: =_xlfn.XLOOKUP(_xlfn.CONCAT($B25,$D25,$E25),PEC_Info!$L$2:$L$301,PEC_Info!$F$2:$F$301) -> 5683.2536 | J25: =_xlfn.XLOOKUP(_xlfn.CONCAT($B25,$D25,$E25),PEC_Info!$L$2:$L$301,PEC_Info!$G$2:$G$301) -> 0 | K25: =_xlfn.XLOOKUP(_xlfn.CONCAT($B25,$D25,$E25),PEC_Info!$L$2:$L$301,PEC_Info!$H$2:$H$301) -> 0 | L25: =_xlfn.XLOOKUP(_xlfn.CONCAT($B25,$D25,$E25),PEC_Info!$L$2:$L$301,PEC_Info!$I$2:$I$301) -> 5683.2536 | M25: =_xlfn.XLOOKUP(_xlfn.CONCAT($B25,$D25,$E25),PEC_Info!$L$2:$L$301,PEC_Info!$J$2:$J$301) -> 0 | N25: =_xlfn.XLOOKUP(_xlfn.CONCAT($B25,$D25,$E25),PEC_Info!$L$2:$L$301,PEC_Info!$K$2:$K$301) -> 0 | P25: =(I25*(1+J25)+K25*1000)/_xlfn.XLOOKUP(B25,CarriersTech_characteristics!$B$2:$B$8,CarriersTech_characteristics!$G$2:$G$8)/Conversions!$D$2 -> 0.0013148916 | Q25: =F25*_xlfn.XLOOKUP(B25,CarriersTech_characteristics!$B$2:$B$8,CarriersTech_characteristics!$G$2:$G$8)*Conversions!$D$2*(1-H25) -> 1.167e+09 | R25: =(L25*(1+M25)+N25*1000)/_xlfn.XLOOKUP(B25,CarriersTech_characteristics!$B$2:$B$8,CarriersTech_characteristics!$J$2:$J$8)/Conversions!$D$2 -> 0.0013148916 | S25: =G25*_xlfn.XLOOKUP(B25,CarriersTech_characteristics!$B$2:$B$8,CarriersTech_characteristics!$J$2:$J$8)*Conversions!$D$2 -> 0
A26: 2 | B26: BIOMASS_WASTE | C26: INDIA | E26: =_xlfn.XLOOKUP(A26,PeriodMap!$A$2:$A$45,PeriodMap!$B$2:$B$45) -> 2024 | F26: =_xlfn.XLOOKUP(_xlfn.CONCAT($B26,$D26,$E26),PEC_ProdImpConstraints!$G$2:$G$286,PEC_ProdImpConstraints!$E$2:$E$286) -> 175 | G26: =_xlfn.XLOOKUP(_xlfn.CONCAT($B26,$D26,$E26),PEC_ProdImpConstraints!$G$2:$G$286,PEC_ProdImpConstraints!$F$2:$F$286) -> 0 | H26: =_xlfn.XLOOKUP(_xlfn.CONCAT($B26,$D26,$E26),PEC_Info!$L$2:$L$301,PEC_Info!$E$2:$E$301) -> 0 | I26: =_xlfn.XLOOKUP(_xlfn.CONCAT($B26,$D26,$E26),PEC_Info!$L$2:$L$301,PEC_Info!$F$2:$F$301) -> 9000 | J26: =_xlfn.XLOOKUP(_xlfn.CONCAT($B26,$D26,$E26),PEC_Info!$L$2:$L$301,PEC_Info!$G$2:$G$301) -> 0.05 | K26: =_xlfn.XLOOKUP(_xlfn.CONCAT($B26,$D26,$E26),PEC_Info!$L$2:$L$301,PEC_Info!$H$2:$H$301) -> 0 | L26: =_xlfn.XLOOKUP(_xlfn.CONCAT($B26,$D26,$E26),PEC_Info!$L$2:$L$301,PEC_Info!$I$2:$I$301) -> 9000 | M26: =_xlfn.XLOOKUP(_xlfn.CONCAT($B26,$D26,$E26),PEC_Info!$L$2:$L$301,PEC_Info!$J$2:$J$301) -> 0.05 | N26: =_xlfn.XLOOKUP(_xlfn.CONCAT($B26,$D26,$E26),PEC_Info!$L$2:$L$301,PEC_Info!$K$2:$K$301) -> 0 | P26: =(I26*(1+J26)+K26*1000)/_xlfn.XLOOKUP(B26,CarriersTech_characteristics!$B$2:$B$8,CarriersTech_characteristics!$G$2:$G$8)/Conversions!$D$2 -> 0.0024924961 | Q26: =F26*_xlfn.XLOOKUP(B26,CarriersTech_characteristics!$B$2:$B$8,CarriersTech_characteristics!$G$2:$G$8)*Conversions!$D$2*(1-H26) -> 6.6349151e+08 | R26: =(L26*(1+M26)+N26*1000)/_xlfn.XLOOKUP(B26,CarriersTech_characteristics!$B$2:$B$8,CarriersTech_characteristics!$J$2:$J$8)/Conversions!$D$2 -> 0.0024924961 | S26: =G26*_xlfn.XLOOKUP(B26,CarriersTech_characteristics!$B$2:$B$8,CarriersTech_characteristics!$J$2:$J$8)*Conversions!$D$2 -> 0
A27: 2 | B27: NATGAS | C27: INDIA | E27: =_xlfn.XLOOKUP(A27,PeriodMap!$A$2:$A$45,PeriodMap!$B$2:$B$45) -> 2024 | F27: =_xlfn.XLOOKUP(_xlfn.CONCAT($B27,$D27,$E27),PEC_ProdImpConstraints!$G$2:$G$286,PEC_ProdImpConstraints!$E$2:$E$286) -> 34.32096 | G27: =_xlfn.XLOOKUP(_xlfn.CONCAT($B27,$D27,$E27),PEC_ProdImpConstraints!$G$2:$G$286,PEC_ProdImpConstraints!$F$2:$F$286) -> 200 | H27: =_xlfn.XLOOKUP(_xlfn.CONCAT($B27,$D27,$E27),PEC_Info!$L$2:$L$301,PEC_Info!$E$2:$E$301) -> 0.36749121 | I27: =_xlfn.XLOOKUP(_xlfn.CONCAT($B27,$D27,$E27),PEC_Info!$L$2:$L$301,PEC_Info!$F$2:$F$301) -> 24102 | J27: =_xlfn.XLOOKUP(_xlfn.CONCAT($B27,$D27,$E27),PEC_Info!$L$2:$L$301,PEC_Info!$G$2:$G$301) -> 0.24 | K27: =_xlfn.XLOOKUP(_xlfn.CONCAT($B27,$D27,$E27),PEC_Info!$L$2:$L$301,PEC_Info!$H$2:$H$301) -> 0 | L27: =_xlfn.XLOOKUP(_xlfn.CONCAT($B27,$D27,$E27),PEC_Info!$L$2:$L$301,PEC_Info!$I$2:$I$301) -> 35195.967 | M27: =_xlfn.XLOOKUP(_xlfn.CONCAT($B27,$D27,$E27),PEC_Info!$L$2:$L$301,PEC_Info!$J$2:$J$301) -> 0.349 | N27: =_xlfn.XLOOKUP(_xlfn.CONCAT($B27,$D27,$E27),PEC_Info!$L$2:$L$301,PEC_Info!$K$2:$K$301) -> 0 | P27: =(I27*(1+J27)+K27*1000)/Conversions!$D$3/_xlfn.XLOOKUP(B27,CarriersTech_characteristics!$B$2:$B$8,CarriersTech_characteristics!$G$2:$G$8)/Conversions!$D$2 -> 0.0034442765 | Q27: =F27*_xlfn.XLOOKUP(B27,CarriersTech_characteristics!$B$2:$B$8,CarriersTech_characteristics!$G$2:$G$8)*Conversions!$D$2*(1-H27) -> 2.2722087e+08 | R27: =(L27*(1+M27)+N27*1000)/Conversions!$D$3/_xlfn.XLOOKUP(B27,CarriersTech_characteristics!$B$2:$B$8,CarriersTech_characteristics!$J$2:$J$8)/Conversions!$D$2 -> 0.0054717732 | S27: =G27*_xlfn.XLOOKUP(B27,CarriersTech_characteristics!$B$2:$B$8,CarriersTech_characteristics!$J$2:$J$8)*Conversions!$D$2 -> 2.0934e+09
A28: 2 | B28: THERMAL_COAL | C28: INDIA | D28: NR | E28: =_xlfn.XLOOKUP(A28,PeriodMap!$A$2:$A$45,PeriodMap!$B$2:$B$45) -> 2024 | F28: =_xlfn.XLOOKUP(_xlfn.CONCAT($B28,$D28,$E28),PEC_ProdImpConstraints!$G$2:$G$286,PEC_ProdImpConstraints!$E$2:$E$286) -> 31.9232 | G28: =_xlfn.XLOOKUP(_xlfn.CONCAT($B28,$D28,$E28),PEC_ProdImpConstraints!$G$2:$G$286,PEC_ProdImpConstraints!$F$2:$F$286) -> 0 | H28: =_xlfn.XLOOKUP(_xlfn.CONCAT($B28,$D28,$E28),PEC_Info!$L$2:$L$301,PEC_Info!$E$2:$E$301) -> 0 | I28: =_xlfn.XLOOKUP(_xlfn.CONCAT($B28,$D28,$E28),PEC_Info!$L$2:$L$301,PEC_Info!$F$2:$F$301) -> 1156.3734 | J28: =_xlfn.XLOOKUP(_xlfn.CONCAT($B28,$D28,$E28),PEC_Info!$L$2:$L$301,PEC_Info!$G$2:$G$301) -> 0.3508 | K28: =_xlfn.XLOOKUP(_xlfn.CONCAT($B28,$D28,$E28),PEC_Info!$L$2:$L$301,PEC_Info!$H$2:$H$301) -> 0 | L28: =_xlfn.XLOOKUP(_xlfn.CONCAT($B28,$D28,$E28),PEC_Info!$L$2:$L$301,PEC_Info!$I$2:$I$301) -> 10095.813 | M28: =_xlfn.XLOOKUP(_xlfn.CONCAT($B28,$D28,$E28),PEC_Info!$L$2:$L$301,PEC_Info!$J$2:$J$301) -> 0.205 | N28: =_xlfn.XLOOKUP(_xlfn.CONCAT($B28,$D28,$E28),PEC_Info!$L$2:$L$301,PEC_Info!$K$2:$K$301) -> 0 | P28: =(I28*(1+J28)+K28*1000)/_xlfn.XLOOKUP(B28,CarriersTech_characteristics!$B$2:$B$8,CarriersTech_characteristics!$G$2:$G$8)/Conversions!$D$2 -> 0.00032679978 | Q28: =F28*_xlfn.XLOOKUP(B28,CarriersTech_characteristics!$B$2:$B$8,CarriersTech_characteristics!$G$2:$G$8)*Conversions!$D$2*(1-H28) -> 1.5258569e+08 | R28: =(L28*(1+M28)+N28*1000)/_xlfn.XLOOKUP(B28,CarriersTech_characteristics!$B$2:$B$8,CarriersTech_characteristics!$J$2:$J$8)/Conversions!$D$2 -> 0.0019371126 | S28: =G28*_xlfn.XLOOKUP(B28,CarriersTech_characteristics!$B$2:$B$8,CarriersTech_characteristics!$J$2:$J$8)*Conversions!$D$2 -> 0
A29: 2 | B29: THERMAL_COAL | C29: INDIA | D29: NER | E29: =_xlfn.XLOOKUP(A29,PeriodMap!$A$2:$A$45,PeriodMap!$B$2:$B$45) -> 2024 | F29: =_xlfn.XLOOKUP(_xlfn.CONCAT($B29,$D29,$E29),PEC_ProdImpConstraints!$G$2:$G$286,PEC_ProdImpConstraints!$E$2:$E$286) -> 0 | G29: =_xlfn.XLOOKUP(_xlfn.CONCAT($B29,$D29,$E29),PEC_ProdImpConstraints!$G$2:$G$286,PEC_ProdImpConstraints!$F$2:$F$286) -> 0 | H29: =_xlfn.XLOOKUP(_xlfn.CONCAT($B29,$D29,$E29),PEC_Info!$L$2:$L$301,PEC_Info!$E$2:$E$301) -> 0 | I29: =_xlfn.XLOOKUP(_xlfn.CONCAT($B29,$D29,$E29),PEC_Info!$L$2:$L$301,PEC_Info!$F$2:$F$301) -> 1156.3734 | J29: =_xlfn.XLOOKUP(_xlfn.CONCAT($B29,$D29,$E29),PEC_Info!$L$2:$L$301,PEC_Info!$G$2:$G$301) -> 0.3508 | K29: =_xlfn.XLOOKUP(_xlfn.CONCAT($B29,$D29,$E29),PEC_Info!$L$2:$L$301,PEC_Info!$H$2:$H$301) -> 0 | L29: =_xlfn.XLOOKUP(_xlfn.CONCAT($B29,$D29,$E29),PEC_Info!$L$2:$L$301,PEC_Info!$I$2:$I$301) -> 10095.813 | M29: =_xlfn.XLOOKUP(_xlfn.CONCAT($B29,$D29,$E29),PEC_Info!$L$2:$L$301,PEC_Info!$J$2:$J$301) -> 0.205 | N29: =_xlfn.XLOOKUP(_xlfn.CONCAT($B29,$D29,$E29),PEC_Info!$L$2:$L$301,PEC_Info!$K$2:$K$301) -> 0 | P29: =(I29*(1+J29)+K29*1000)/_xlfn.XLOOKUP(B29,CarriersTech_characteristics!$B$2:$B$8,CarriersTech_characteristics!$G$2:$G$8)/Conversions!$D$2 -> 0.00032679978 | Q29: =F29*_xlfn.XLOOKUP(B29,CarriersTech_characteristics!$B$2:$B$8,CarriersTech_characteristics!$G$2:$G$8)*Conversions!$D$2*(1-H29) -> 0 | R29: =(L29*(1+M29)+N29*1000)/_xlfn.XLOOKUP(B29,CarriersTech_characteristics!$B$2:$B$8,CarriersTech_characteristics!$J$2:$J$8)/Conversions!$D$2 -> 0.0019371126 | S29: =G29*_xlfn.XLOOKUP(B29,CarriersTech_characteristics!$B$2:$B$8,CarriersTech_characteristics!$J$2:$J$8)*Conversions!$D$2 -> 0
A30: 2 | B30: THERMAL_COAL | C30: INDIA | D30: ER | E30: =_xlfn.XLOOKUP(A30,PeriodMap!$A$2:$A$45,PeriodMap!$B$2:$B$45) -> 2024 | F30: =_xlfn.XLOOKUP(_xlfn.CONCAT($B30,$D30,$E30),PEC_ProdImpConstraints!$G$2:$G$286,PEC_ProdImpConstraints!$E$2:$E$286) -> 417.84809 | G30: =_xlfn.XLOOKUP(_xlfn.CONCAT($B30,$D30,$E30),PEC_ProdImpConstraints!$G$2:$G$286,PEC_ProdImpConstraints!$F$2:$F$286) -> 150 | H30: =_xlfn.XLOOKUP(_xlfn.CONCAT($B30,$D30,$E30),PEC_Info!$L$2:$L$301,PEC_Info!$E$2:$E$301) -> 0 | I30: =_xlfn.XLOOKUP(_xlfn.CONCAT($B30,$D30,$E30),PEC_Info!$L$2:$L$301,PEC_Info!$F$2:$F$301) -> 1156.3734 | J30: =_xlfn.XLOOKUP(_xlfn.CONCAT($B30,$D30,$E30),PEC_Info!$L$2:$L$301,PEC_Info!$G$2:$G$301) -> 0.3508 | K30: =_xlfn.XLOOKUP(_xlfn.CONCAT($B30,$D30,$E30),PEC_Info!$L$2:$L$301,PEC_Info!$H$2:$H$301) -> 0 | L30: =_xlfn.XLOOKUP(_xlfn.CONCAT($B30,$D30,$E30),PEC_Info!$L$2:$L$301,PEC_Info!$I$2:$I$301) -> 10095.813 | M30: =_xlfn.XLOOKUP(_xlfn.CONCAT($B30,$D30,$E30),PEC_Info!$L$2:$L$301,PEC_Info!$J$2:$J$301) -> 0.205 | N30: =_xlfn.XLOOKUP(_xlfn.CONCAT($B30,$D30,$E30),PEC_Info!$L$2:$L$301,PEC_Info!$K$2:$K$301) -> 0 | P30: =(I30*(1+J30)+K30*1000)/_xlfn.XLOOKUP(B30,CarriersTech_characteristics!$B$2:$B$8,CarriersTech_characteristics!$G$2:$G$8)/Conversions!$D$2 -> 0.00032679978 | Q30: =F30*_xlfn.XLOOKUP(B30,CarriersTech_characteristics!$B$2:$B$8,CarriersTech_characteristics!$G$2:$G$8)*Conversions!$D$2*(1-H30) -> 1.9972196e+09 | R30: =(L30*(1+M30)+N30*1000)/_xlfn.XLOOKUP(B30,CarriersTech_characteristics!$B$2:$B$8,CarriersTech_characteristics!$J$2:$J$8)/Conversions!$D$2 -> 0.0019371126 | S30: =G30*_xlfn.XLOOKUP(B30,CarriersTech_characteristics!$B$2:$B$8,CarriersTech_characteristics!$J$2:$J$8)*Conversions!$D$2 -> 9.4203001e+08
A31: 2 | B31: THERMAL_COAL | C31: INDIA | D31: WR | E31: =_xlfn.XLOOKUP(A31,PeriodMap!$A$2:$A$45,PeriodMap!$B$2:$B$45) -> 2024 | F31: =_xlfn.XLOOKUP(_xlfn.CONCAT($B31,$D31,$E31),PEC_ProdImpConstraints!$G$2:$G$286,PEC_ProdImpConstraints!$E$2:$E$286) -> 429.33807 | G31: =_xlfn.XLOOKUP(_xlfn.CONCAT($B31,$D31,$E31),PEC_ProdImpConstraints!$G$2:$G$286,PEC_ProdImpConstraints!$F$2:$F$286) -> 150 | H31: =_xlfn.XLOOKUP(_xlfn.CONCAT($B31,$D31,$E31),PEC_Info!$L$2:$L$301,PEC_Info!$E$2:$E$301) -> 0 | I31: =_xlfn.XLOOKUP(_xlfn.CONCAT($B31,$D31,$E31),PEC_Info!$L$2:$L$301,PEC_Info!$F$2:$F$301) -> 1156.3734 | J31: =_xlfn.XLOOKUP(_xlfn.CONCAT($B31,$D31,$E31),PEC_Info!$L$2:$L$301,PEC_Info!$G$2:$G$301) -> 0.3508 | K31: =_xlfn.XLOOKUP(_xlfn.CONCAT($B31,$D31,$E31),PEC_Info!$L$2:$L$301,PEC_Info!$H$2:$H$301) -> 0 | L31: =_xlfn.XLOOKUP(_xlfn.CONCAT($B31,$D31,$E31),PEC_Info!$L$2:$L$301,PEC_Info!$I$2:$I$301) -> 10095.813 | M31: =_xlfn.XLOOKUP(_xlfn.CONCAT($B31,$D31,$E31),PEC_Info!$L$2:$L$301,PEC_Info!$J$2:$J$301) -> 0.205 | N31: =_xlfn.XLOOKUP(_xlfn.CONCAT($B31,$D31,$E31),PEC_Info!$L$2:$L$301,PEC_Info!$K$2:$K$301) -> 0 | P31: =(I31*(1+J31)+K31*1000)/_xlfn.XLOOKUP(B31,CarriersTech_characteristics!$B$2:$B$8,CarriersTech_characteristics!$G$2:$G$8)/Conversions!$D$2 -> 0.00032679978 | Q31: =F31*_xlfn.XLOOKUP(B31,CarriersTech_characteristics!$B$2:$B$8,CarriersTech_characteristics!$G$2:$G$8)*Conversions!$D$2*(1-H31) -> 2.0521391e+09 | R31: =(L31*(1+M31)+N31*1000)/_xlfn.XLOOKUP(B31,CarriersTech_characteristics!$B$2:$B$8,CarriersTech_characteristics!$J$2:$J$8)/Conversions!$D$2 -> 0.0019371126 | S31: =G31*_xlfn.XLOOKUP(B31,CarriersTech_characteristics!$B$2:$B$8,CarriersTech_characteristics!$J$2:$J$8)*Conversions!$D$2 -> 9.4203001e+08
A32: 2 | B32: THERMAL_COAL | C32: INDIA | D32: SR | E32: =_xlfn.XLOOKUP(A32,PeriodMap!$A$2:$A$45,PeriodMap!$B$2:$B$45) -> 2024 | F32: =_xlfn.XLOOKUP(_xlfn.CONCAT($B32,$D32,$E32),PEC_ProdImpConstraints!$G$2:$G$286,PEC_ProdImpConstraints!$E$2:$E$286) -> 91.773025 | G32: =_xlfn.XLOOKUP(_xlfn.CONCAT($B32,$D32,$E32),PEC_ProdImpConstraints!$G$2:$G$286,PEC_ProdImpConstraints!$F$2:$F$286) -> 150 | H32: =_xlfn.XLOOKUP(_xlfn.CONCAT($B32,$D32,$E32),PEC_Info!$L$2:$L$301,PEC_Info!$E$2:$E$301) -> 0 | I32: =_xlfn.XLOOKUP(_xlfn.CONCAT($B32,$D32,$E32),PEC_Info!$L$2:$L$301,PEC_Info!$F$2:$F$301) -> 1156.3734 | J32: =_xlfn.XLOOKUP(_xlfn.CONCAT($B32,$D32,$E32),PEC_Info!$L$2:$L$301,PEC_Info!$G$2:$G$301) -> 0.3508 | K32: =_xlfn.XLOOKUP(_xlfn.CONCAT($B32,$D32,$E32),PEC_Info!$L$2:$L$301,PEC_Info!$H$2:$H$301) -> 0 | L32: =_xlfn.XLOOKUP(_xlfn.CONCAT($B32,$D32,$E32),PEC_Info!$L$2:$L$301,PEC_Info!$I$2:$I$301) -> 10095.813 | M32: =_xlfn.XLOOKUP(_xlfn.CONCAT($B32,$D32,$E32),PEC_Info!$L$2:$L$301,PEC_Info!$J$2:$J$301) -> 0.205 | N32: =_xlfn.XLOOKUP(_xlfn.CONCAT($B32,$D32,$E32),PEC_Info!$L$2:$L$301,PEC_Info!$K$2:$K$301) -> 0 | P32: =(I32*(1+J32)+K32*1000)/_xlfn.XLOOKUP(B32,CarriersTech_characteristics!$B$2:$B$8,CarriersTech_characteristics!$G$2:$G$8)/Conversions!$D$2 -> 0.00032679978 | Q32: =F32*_xlfn.XLOOKUP(B32,CarriersTech_characteristics!$B$2:$B$8,CarriersTech_characteristics!$G$2:$G$8)*Conversions!$D$2*(1-H32) -> 4.3865435e+08 | R32: =(L32*(1+M32)+N32*1000)/_xlfn.XLOOKUP(B32,CarriersTech_characteristics!$B$2:$B$8,CarriersTech_characteristics!$J$2:$J$8)/Conversions!$D$2 -> 0.0019371126 | S32: =G32*_xlfn.XLOOKUP(B32,CarriersTech_characteristics!$B$2:$B$8,CarriersTech_characteristics!$J$2:$J$8)*Conversions!$D$2 -> 9.4203001e+08
A33: 2 | B33: THERMAL_COAL | C33: INDIA | D33: ALL | E33: =_xlfn.XLOOKUP(A33,PeriodMap!$A$2:$A$45,PeriodMap!$B$2:$B$45) -> 2024 | F33: =SUM(F28:F32) -> 970.88239 | G33: =SUM(G28:G32) -> 450 | H33: =AVERAGE(H28:H32) -> 0 | I33: =AVERAGE(I28:I32) -> 1156.3734 | J33: =AVERAGE(J28:J32) -> 0.3508 | K33: =AVERAGE(K28:K32) -> 0 | L33: =AVERAGE(L28:L32) -> 10095.813 | M33: =AVERAGE(M28:M32) -> 0.205 | N33: =AVERAGE(N28:N32) -> 0 | P33: =AVERAGE(P28:P32) -> 0.00032679978 | Q33: =SUM(Q28:Q32) -> 4.6405988e+09 | R33: =AVERAGE(R28:R32) -> 0.0019371126 | S33: =SUM(S28:S32) -> 2.82609e+09
A34: 2 | B34: CRUDE | C34: INDIA | E34: =_xlfn.XLOOKUP(A34,PeriodMap!$A$2:$A$45,PeriodMap!$B$2:$B$45) -> 2024 | F34: =_xlfn.XLOOKUP(_xlfn.CONCAT($B34,$D34,$E34),PEC_ProdImpConstraints!$G$2:$G$286,PEC_ProdImpConstraints!$E$2:$E$286) -> 31.9035 | G34: =_xlfn.XLOOKUP(_xlfn.CONCAT($B34,$D34,$E34),PEC_ProdImpConstraints!$G$2:$G$286,PEC_ProdImpConstraints!$F$2:$F$286) -> 330 | H34: 0 | I34: =_xlfn.XLOOKUP(_xlfn.CONCAT($B34,$D34,$E34),PEC_Info!$L$2:$L$301,PEC_Info!$F$2:$F$301) -> 47177.324 | J34: =_xlfn.XLOOKUP(_xlfn.CONCAT($B34,$D34,$E34),PEC_Info!$L$2:$L$301,PEC_Info!$G$2:$G$301) -> 0 | K34: =_xlfn.XLOOKUP(_xlfn.CONCAT($B34,$D34,$E34),PEC_Info!$L$2:$L$301,PEC_Info!$H$2:$H$301) -> 51.2 | L34: =_xlfn.XLOOKUP(_xlfn.CONCAT($B34,$D34,$E34),PEC_Info!$L$2:$L$301,PEC_Info!$I$2:$I$301) -> 47177.324 | M34: =_xlfn.XLOOKUP(_xlfn.CONCAT($B34,$D34,$E34),PEC_Info!$L$2:$L$301,PEC_Info!$J$2:$J$301) -> 0 | N34: =_xlfn.XLOOKUP(_xlfn.CONCAT($B34,$D34,$E34),PEC_Info!$L$2:$L$301,PEC_Info!$K$2:$K$301) -> 57.2 | P34: =(I34*(1+J34)+K34*1000)/_xlfn.XLOOKUP(B34,CarriersTech_characteristics!$B$2:$B$8,CarriersTech_characteristics!$G$2:$G$8)/Conversions!$D$2 -> 0.0082125507 | Q34: =F34*_xlfn.XLOOKUP(B34,CarriersTech_characteristics!$B$2:$B$8,CarriersTech_characteristics!$G$2:$G$8)*Conversions!$D$2*(1-H34) -> 3.8216884e+08 | R34: =(L34*(1+M34)+N34*1000)/_xlfn.XLOOKUP(B34,CarriersTech_characteristics!$B$2:$B$8,CarriersTech_characteristics!$J$2:$J$8)/Conversions!$D$2 -> 0.0087134314 | S34: =G34*_xlfn.XLOOKUP(B34,CarriersTech_characteristics!$B$2:$B$8,CarriersTech_characteristics!$J$2:$J$8)*Conversions!$D$2 -> 3.953037e+09
A35: 2 | B35: BIOGAS | C35: INDIA | E35: =_xlfn.XLOOKUP(A35,PeriodMap!$A$2:$A$45,PeriodMap!$B$2:$B$45) -> 2024 | F35: =_xlfn.XLOOKUP(_xlfn.CONCAT($B35,$D35,$E35),PEC_ProdImpConstraints!$G$2:$G$286,PEC_ProdImpConstraints!$E$2:$E$286) -> 87 | G35: =_xlfn.XLOOKUP(_xlfn.CONCAT($B35,$D35,$E35),PEC_ProdImpConstraints!$G$2:$G$286,PEC_ProdImpConstraints!$F$2:$F$286) -> 0 | H35: 0 | I35: =_xlfn.XLOOKUP(_xlfn.CONCAT($B35,$D35,$E35),PEC_Info!$L$2:$L$301,PEC_Info!$F$2:$F$301) -> 54962.757 | J35: =_xlfn.XLOOKUP(_xlfn.CONCAT($B35,$D35,$E35),PEC_Info!$L$2:$L$301,PEC_Info!$G$2:$G$301) -> 0.05 | K35: =_xlfn.XLOOKUP(_xlfn.CONCAT($B35,$D35,$E35),PEC_Info!$L$2:$L$301,PEC_Info!$H$2:$H$301) -> 0 | L35: =_xlfn.XLOOKUP(_xlfn.CONCAT($B35,$D35,$E35),PEC_Info!$L$2:$L$301,PEC_Info!$I$2:$I$301) -> 54962.757 | M35: =_xlfn.XLOOKUP(_xlfn.CONCAT($B35,$D35,$E35),PEC_Info!$L$2:$L$301,PEC_Info!$J$2:$J$301) -> 0.05 | N35: =_xlfn.XLOOKUP(_xlfn.CONCAT($B35,$D35,$E35),PEC_Info!$L$2:$L$301,PEC_Info!$K$2:$K$301) -> 0 | P35: =(I35*(1+J35)+K35*1000)/Conversions!$D$3/_xlfn.XLOOKUP(B35,CarriersTech_characteristics!$B$2:$B$8,CarriersTech_characteristics!$G$2:$G$8)/Conversions!$D$2 -> 0.010991853 | Q35: =F35*_xlfn.XLOOKUP(B35,CarriersTech_characteristics!$B$2:$B$8,CarriersTech_characteristics!$G$2:$G$8)*Conversions!$D$2*(1-H35) -> 5.51e+08 | R35: =(L35*(1+M35)+N35*1000)/Conversions!$D$3/_xlfn.XLOOKUP(B35,CarriersTech_characteristics!$B$2:$B$8,CarriersTech_characteristics!$J$2:$J$8)/Conversions!$D$2 -> 0.010991853 | S35: =G35*_xlfn.XLOOKUP(B35,CarriersTech_characteristics!$B$2:$B$8,CarriersTech_characteristics!$J$2:$J$8)*Conversions!$D$2 -> 0
A36: 2 | B36: COKING_COAL | C36: INDIA | D36: ER | E36: =_xlfn.XLOOKUP(A36,PeriodMap!$A$2:$A$45,PeriodMap!$B$2:$B$45) -> 2024 | F36: =_xlfn.XLOOKUP(_xlfn.CONCAT($B36,$D36,$E36),PEC_ProdImpConstraints!$G$2:$G$286,PEC_ProdImpConstraints!$E$2:$E$286) -> 13.516378 | G36: =_xlfn.XLOOKUP(_xlfn.CONCAT($B36,$D36,$E36),PEC_ProdImpConstraints!$G$2:$G$286,PEC_ProdImpConstraints!$F$2:$F$286) -> 100 | H36: 0 | I36: =_xlfn.XLOOKUP(_xlfn.CONCAT($B36,$D36,$E36),PEC_Info!$L$2:$L$301,PEC_Info!$F$2:$F$301) -> 2789.0369 | J36: =_xlfn.XLOOKUP(_xlfn.CONCAT($B36,$D36,$E36),PEC_Info!$L$2:$L$301,PEC_Info!$G$2:$G$301) -> 0.3508 | K36: =_xlfn.XLOOKUP(_xlfn.CONCAT($B36,$D36,$E36),PEC_Info!$L$2:$L$301,PEC_Info!$H$2:$H$301) -> 0 | L36: =_xlfn.XLOOKUP(_xlfn.CONCAT($B36,$D36,$E36),PEC_Info!$L$2:$L$301,PEC_Info!$I$2:$I$301) -> 21903.747 | M36: =_xlfn.XLOOKUP(_xlfn.CONCAT($B36,$D36,$E36),PEC_Info!$L$2:$L$301,PEC_Info!$J$2:$J$301) -> 0.205 | N36: =_xlfn.XLOOKUP(_xlfn.CONCAT($B36,$D36,$E36),PEC_Info!$L$2:$L$301,PEC_Info!$K$2:$K$301) -> 0 | P36: =(I36*(1+J36)+K36*1000)/_xlfn.XLOOKUP(B36,CarriersTech_characteristics!$B$2:$B$8,CarriersTech_characteristics!$G$2:$G$8)/Conversions!$D$2 -> 0.00065980588 | Q36: =F36*_xlfn.XLOOKUP(B36,CarriersTech_characteristics!$B$2:$B$8,CarriersTech_characteristics!$G$2:$G$8)*Conversions!$D$2*(1-H36) -> 77177275 | R36: =(L36*(1+M36)+N36*1000)/_xlfn.XLOOKUP(B36,CarriersTech_characteristics!$B$2:$B$8,CarriersTech_characteristics!$J$2:$J$8)/Conversions!$D$2 -> 0.0039297516 | S36: =G36*_xlfn.XLOOKUP(B36,CarriersTech_characteristics!$B$2:$B$8,CarriersTech_characteristics!$J$2:$J$8)*Conversions!$D$2 -> 6.7164587e+08
A37: 2 | B37: COKING_COAL | C37: INDIA | D37: WR | E37: =_xlfn.XLOOKUP(A37,PeriodMap!$A$2:$A$45,PeriodMap!$B$2:$B$45) -> 2024 | F37: =_xlfn.XLOOKUP(_xlfn.CONCAT($B37,$D37,$E37),PEC_ProdImpConstraints!$G$2:$G$286,PEC_ProdImpConstraints!$E$2:$E$286) -> 0 | G37: =_xlfn.XLOOKUP(_xlfn.CONCAT($B37,$D37,$E37),PEC_ProdImpConstraints!$G$2:$G$286,PEC_ProdImpConstraints!$F$2:$F$286) -> 100 | H37: 0 | I37: =_xlfn.XLOOKUP(_xlfn.CONCAT($B37,$D37,$E37),PEC_Info!$L$2:$L$301,PEC_Info!$F$2:$F$301) -> 2789.0369 | J37: =_xlfn.XLOOKUP(_xlfn.CONCAT($B37,$D37,$E37),PEC_Info!$L$2:$L$301,PEC_Info!$G$2:$G$301) -> 0.3508 | K37: =_xlfn.XLOOKUP(_xlfn.CONCAT($B37,$D37,$E37),PEC_Info!$L$2:$L$301,PEC_Info!$H$2:$H$301) -> 0 | L37: =_xlfn.XLOOKUP(_xlfn.CONCAT($B37,$D37,$E37),PEC_Info!$L$2:$L$301,PEC_Info!$I$2:$I$301) -> 21903.747 | M37: =_xlfn.XLOOKUP(_xlfn.CONCAT($B37,$D37,$E37),PEC_Info!$L$2:$L$301,PEC_Info!$J$2:$J$301) -> 0.205 | N37: =_xlfn.XLOOKUP(_xlfn.CONCAT($B37,$D37,$E37),PEC_Info!$L$2:$L$301,PEC_Info!$K$2:$K$301) -> 0 | P37: =(I37*(1+J37)+K37*1000)/_xlfn.XLOOKUP(B37,CarriersTech_characteristics!$B$2:$B$8,CarriersTech_characteristics!$G$2:$G$8)/Conversions!$D$2 -> 0.00065980588 | Q37: =F37*_xlfn.XLOOKUP(B37,CarriersTech_characteristics!$B$2:$B$8,CarriersTech_characteristics!$G$2:$G$8)*Conversions!$D$2*(1-H37) -> 0 | R37: =(L37*(1+M37)+N37*1000)/_xlfn.XLOOKUP(B37,CarriersTech_characteristics!$B$2:$B$8,CarriersTech_characteristics!$J$2:$J$8)/Conversions!$D$2 -> 0.0039297516 | S37: =G37*_xlfn.XLOOKUP(B37,CarriersTech_characteristics!$B$2:$B$8,CarriersTech_characteristics!$J$2:$J$8)*Conversions!$D$2 -> 6.7164587e+08
A38: 2 | B38: COKING_COAL | C38: INDIA | D38: NR | E38: =_xlfn.XLOOKUP(A38,PeriodMap!$A$2:$A$45,PeriodMap!$B$2:$B$45) -> 2024 | F38: =_xlfn.XLOOKUP(_xlfn.CONCAT($B38,$D38,$E38),PEC_ProdImpConstraints!$G$2:$G$286,PEC_ProdImpConstraints!$E$2:$E$286) -> 0 | G38: =_xlfn.XLOOKUP(_xlfn.CONCAT($B38,$D38,$E38),PEC_ProdImpConstraints!$G$2:$G$286,PEC_ProdImpConstraints!$F$2:$F$286) -> 0 | H38: 0 | I38: =_xlfn.XLOOKUP(_xlfn.CONCAT($B38,$D38,$E38),PEC_Info!$L$2:$L$301,PEC_Info!$F$2:$F$301) -> 2789.0369 | J38: =_xlfn.XLOOKUP(_xlfn.CONCAT($B38,$D38,$E38),PEC_Info!$L$2:$L$301,PEC_Info!$G$2:$G$301) -> 0.3508 | K38: =_xlfn.XLOOKUP(_xlfn.CONCAT($B38,$D38,$E38),PEC_Info!$L$2:$L$301,PEC_Info!$H$2:$H$301) -> 0 | L38: =_xlfn.XLOOKUP(_xlfn.CONCAT($B38,$D38,$E38),PEC_Info!$L$2:$L$301,PEC_Info!$I$2:$I$301) -> 21903.747 | M38: =_xlfn.XLOOKUP(_xlfn.CONCAT($B38,$D38,$E38),PEC_Info!$L$2:$L$301,PEC_Info!$J$2:$J$301) -> 0.205 | N38: =_xlfn.XLOOKUP(_xlfn.CONCAT($B38,$D38,$E38),PEC_Info!$L$2:$L$301,PEC_Info!$K$2:$K$301) -> 0 | P38: =(I38*(1+J38)+K38*1000)/_xlfn.XLOOKUP(B38,CarriersTech_characteristics!$B$2:$B$8,CarriersTech_characteristics!$G$2:$G$8)/Conversions!$D$2 -> 0.00065980588 | Q38: =F38*_xlfn.XLOOKUP(B38,CarriersTech_characteristics!$B$2:$B$8,CarriersTech_characteristics!$G$2:$G$8)*Conversions!$D$2*(1-H38) -> 0 | R38: =(L38*(1+M38)+N38*1000)/_xlfn.XLOOKUP(B38,CarriersTech_characteristics!$B$2:$B$8,CarriersTech_characteristics!$J$2:$J$8)/Conversions!$D$2 -> 0.0039297516 | S38: =G38*_xlfn.XLOOKUP(B38,CarriersTech_characteristics!$B$2:$B$8,CarriersTech_characteristics!$J$2:$J$8)*Conversions!$D$2 -> 0
A39: 2 | B39: COKING_COAL | C39: INDIA | D39: SR | E39: =_xlfn.XLOOKUP(A39,PeriodMap!$A$2:$A$45,PeriodMap!$B$2:$B$45) -> 2024 | F39: =_xlfn.XLOOKUP(_xlfn.CONCAT($B39,$D39,$E39),PEC_ProdImpConstraints!$G$2:$G$286,PEC_ProdImpConstraints!$E$2:$E$286) -> 0 | G39: =_xlfn.XLOOKUP(_xlfn.CONCAT($B39,$D39,$E39),PEC_ProdImpConstraints!$G$2:$G$286,PEC_ProdImpConstraints!$F$2:$F$286) -> 100 | H39: 0 | I39: =_xlfn.XLOOKUP(_xlfn.CONCAT($B39,$D39,$E39),PEC_Info!$L$2:$L$301,PEC_Info!$F$2:$F$301) -> 2789.0369 | J39: =_xlfn.XLOOKUP(_xlfn.CONCAT($B39,$D39,$E39),PEC_Info!$L$2:$L$301,PEC_Info!$G$2:$G$301) -> 0.3508 | K39: =_xlfn.XLOOKUP(_xlfn.CONCAT($B39,$D39,$E39),PEC_Info!$L$2:$L$301,PEC_Info!$H$2:$H$301) -> 0 | L39: =_xlfn.XLOOKUP(_xlfn.CONCAT($B39,$D39,$E39),PEC_Info!$L$2:$L$301,PEC_Info!$I$2:$I$301) -> 21903.747 | M39: =_xlfn.XLOOKUP(_xlfn.CONCAT($B39,$D39,$E39),PEC_Info!$L$2:$L$301,PEC_Info!$J$2:$J$301) -> 0.205 | N39: =_xlfn.XLOOKUP(_xlfn.CONCAT($B39,$D39,$E39),PEC_Info!$L$2:$L$301,PEC_Info!$K$2:$K$301) -> 0 | P39: =(I39*(1+J39)+K39*1000)/_xlfn.XLOOKUP(B39,CarriersTech_characteristics!$B$2:$B$8,CarriersTech_characteristics!$G$2:$G$8)/Conversions!$D$2 -> 0.00065980588 | Q39: =F39*_xlfn.XLOOKUP(B39,CarriersTech_characteristics!$B$2:$B$8,CarriersTech_characteristics!$G$2:$G$8)*Conversions!$D$2*(1-H39) -> 0 | R39: =(L39*(1+M39)+N39*1000)/_xlfn.XLOOKUP(B39,CarriersTech_characteristics!$B$2:$B$8,CarriersTech_characteristics!$J$2:$J$8)/Conversions!$D$2 -> 0.0039297516 | S39: =G39*_xlfn.XLOOKUP(B39,CarriersTech_characteristics!$B$2:$B$8,CarriersTech_characteristics!$J$2:$J$8)*Conversions!$D$2 -> 6.7164587e+08
A40: 2 | B40: COKING_COAL | C40: INDIA | D40: NER | E40: =_xlfn.XLOOKUP(A40,PeriodMap!$A$2:$A$45,PeriodMap!$B$2:$B$45) -> 2024 | F40: =_xlfn.XLOOKUP(_xlfn.CONCAT($B40,$D40,$E40),PEC_ProdImpConstraints!$G$2:$G$286,PEC_ProdImpConstraints!$E$2:$E$286) -> 0 | G40: =_xlfn.XLOOKUP(_xlfn.CONCAT($B40,$D40,$E40),PEC_ProdImpConstraints!$G$2:$G$286,PEC_ProdImpConstraints!$F$2:$F$286) -> 0 | H40: 0 | I40: =_xlfn.XLOOKUP(_xlfn.CONCAT($B40,$D40,$E40),PEC_Info!$L$2:$L$301,PEC_Info!$F$2:$F$301) -> 2789.0369 | J40: =_xlfn.XLOOKUP(_xlfn.CONCAT($B40,$D40,$E40),PEC_Info!$L$2:$L$301,PEC_Info!$G$2:$G$301) -> 0.3508 | K40: =_xlfn.XLOOKUP(_xlfn.CONCAT($B40,$D40,$E40),PEC_Info!$L$2:$L$301,PEC_Info!$H$2:$H$301) -> 0 | L40: =_xlfn.XLOOKUP(_xlfn.CONCAT($B40,$D40,$E40),PEC_Info!$L$2:$L$301,PEC_Info!$I$2:$I$301) -> 21903.747 | M40: =_xlfn.XLOOKUP(_xlfn.CONCAT($B40,$D40,$E40),PEC_Info!$L$2:$L$301,PEC_Info!$J$2:$J$301) -> 0.205 | N40: =_xlfn.XLOOKUP(_xlfn.CONCAT($B40,$D40,$E40),PEC_Info!$L$2:$L$301,PEC_Info!$K$2:$K$301) -> 0 | P40: =(I40*(1+J40)+K40*1000)/_xlfn.XLOOKUP(B40,CarriersTech_characteristics!$B$2:$B$8,CarriersTech_characteristics!$G$2:$G$8)/Conversions!$D$2 -> 0.00065980588 | Q40: =F40*_xlfn.XLOOKUP(B40,CarriersTech_characteristics!$B$2:$B$8,CarriersTech_characteristics!$G$2:$G$8)*Conversions!$D$2*(1-H40) -> 0 | R40: =(L40*(1+M40)+N40*1000)/_xlfn.XLOOKUP(B40,CarriersTech_characteristics!$B$2:$B$8,CarriersTech_characteristics!$J$2:$J$8)/Conversions!$D$2 -> 0.0039297516 | S40: =G40*_xlfn.XLOOKUP(B40,CarriersTech_characteristics!$B$2:$B$8,CarriersTech_characteristics!$J$2:$J$8)*Conversions!$D$2 -> 0
...

Sheet assetsEG
A1: Source::File | H1: PIER::EnergyConvTechnologies.csv | I1: PIER::EnergyConvTechnologies.csv | J1: PIER::EnergyConvTechnologies.csv | K1: PIER::EnergyConvTechnologies.csv | L1: PIER2.0_ECT::EfficiencyCostMaxAnnual.csv | M1: PIER2.0_ECT::EfficiencyCostMaxAnnual.csv | N1: PIER2.0_ECT::EfficiencyCostMaxAnnual.csv | O1: PIER2.0_ECT::EfficiencyCostMaxAnnual.csv | P1: PIER2.0::ECT_Lifetime.csv | Q1: PIER2.0::ECT_OperationalInfo.csv | R1: PIER2.0::ECT_OperationalInfo.csv | S1: PIER2.0::ECT_OperationalInfo.csv | T1: PIER2.0::ECT_LegacyCapacity.csv - PIER2.0::ECT_LegacyRetirement.csv | U1: PIER2.0::ECT_CapAddBounds.csv | V1: PIER2.0::ECT_CapAddBounds.csv | W1: PIER2.0::PhysicalDerivedCarriers.csv | X1: PIER2.0::PhysicalCarrierEmissions.csv or for coal, PIER2.0::ECT_EmissionDetails.csv | Y1: PIER2.0::ECT_EfficiencyCostMaxAnnualUF.xlsx | Z1: PIER2.0::ECT_EfficiencyCostMaxAnnualUF.xlsx
